[2025-03-22 20:28:49,098: INFO/MainProcess] beat: Starting...
[2025-03-22 20:28:49,162: INFO/MainProcess] DatabaseScheduler: Schedule changed.
[2025-03-22 21:00:00,009: INFO/MainProcess] Scheduler: Sending due task fetch-jobs-every-hour (jobs.tasks.fetch_jobs_task)
[2025-03-22 21:15:40,809: INFO/MainProcess] DatabaseScheduler: Schedule changed.
[2025-03-22 21:45:40,814: INFO/MainProcess] Scheduler: Sending due task Fetch jobs from external APIs (jobs.tasks.fetch_jobs_task)
[2025-03-22 22:00:00,002: INFO/MainProcess] Scheduler: Sending due task fetch-jobs-every-hour (jobs.tasks.fetch_jobs_task)
[2025-03-22 22:15:40,815: INFO/MainProcess] Scheduler: Sending due task Fetch jobs from external APIs (jobs.tasks.fetch_jobs_task)
[2025-03-22 22:45:40,815: INFO/MainProcess] Scheduler: Sending due task Fetch jobs from external APIs (jobs.tasks.fetch_jobs_task)
[2025-03-23 13:28:33,664: INFO/MainProcess] beat: Starting...
[2025-03-23 13:28:33,713: INFO/MainProcess] DatabaseScheduler: Schedule changed.
[2025-03-23 13:28:33,725: ERROR/MainProcess] beat: Connection error: Error 111 connecting to localhost:6379. Connection refused.. Trying again in 2.0 seconds...
[2025-03-23 13:28:35,729: ERROR/MainProcess] beat: Connection error: Error 111 connecting to localhost:6379. Connection refused.. Trying again in 4.0 seconds...
[2025-03-23 13:28:39,734: ERROR/MainProcess] beat: Connection error: Error 111 connecting to localhost:6379. Connection refused.. Trying again in 6.0 seconds...
[2025-03-23 13:28:45,739: ERROR/MainProcess] beat: Connection error: Error 111 connecting to localhost:6379. Connection refused.. Trying again in 8.0 seconds...
[2025-03-23 13:28:53,743: ERROR/MainProcess] beat: Connection error: Error 111 connecting to localhost:6379. Connection refused.. Trying again in 10.0 seconds...
[2025-03-23 13:29:03,749: ERROR/MainProcess] beat: Connection error: Error 111 connecting to localhost:6379. Connection refused.. Trying again in 12.0 seconds...
[2025-03-23 13:29:15,756: ERROR/MainProcess] beat: Connection error: Error 111 connecting to localhost:6379. Connection refused.. Trying again in 14.0 seconds...
[2025-03-23 13:29:29,760: ERROR/MainProcess] beat: Connection error: Error 111 connecting to localhost:6379. Connection refused.. Trying again in 16.0 seconds...
[2025-03-23 13:29:45,765: ERROR/MainProcess] beat: Connection error: Error 111 connecting to localhost:6379. Connection refused.. Trying again in 18.0 seconds...
[2025-03-23 13:30:03,771: ERROR/MainProcess] beat: Connection error: Error 111 connecting to localhost:6379. Connection refused.. Trying again in 20.0 seconds...
[2025-03-23 13:30:23,778: ERROR/MainProcess] beat: Connection error: Error 111 connecting to localhost:6379. Connection refused.. Trying again in 22.0 seconds...
[2025-03-23 13:30:45,784: ERROR/MainProcess] beat: Connection error: Error 111 connecting to localhost:6379. Connection refused.. Trying again in 24.0 seconds...
[2025-03-23 13:31:09,789: ERROR/MainProcess] beat: Connection error: Error 111 connecting to localhost:6379. Connection refused.. Trying again in 26.0 seconds...
[2025-03-23 13:31:35,796: ERROR/MainProcess] beat: Connection error: Error 111 connecting to localhost:6379. Connection refused.. Trying again in 28.0 seconds...
[2025-03-23 13:32:03,811: ERROR/MainProcess] beat: Connection error: Error 111 connecting to localhost:6379. Connection refused.. Trying again in 30.0 seconds...
[2025-03-23 13:32:33,816: ERROR/MainProcess] beat: Connection error: Error 111 connecting to localhost:6379. Connection refused.. Trying again in 32.0 seconds...
[2025-03-23 13:33:05,821: ERROR/MainProcess] beat: Connection error: Error 111 connecting to localhost:6379. Connection refused.. Trying again in 32.0 seconds...
[2025-03-23 13:33:37,826: ERROR/MainProcess] beat: Connection error: Error 111 connecting to localhost:6379. Connection refused.. Trying again in 32.0 seconds...
[2025-03-23 13:34:09,836: ERROR/MainProcess] beat: Connection error: Error 111 connecting to localhost:6379. Connection refused.. Trying again in 32.0 seconds...
[2025-03-23 13:34:41,846: ERROR/MainProcess] beat: Connection error: Error 111 connecting to localhost:6379. Connection refused.. Trying again in 32.0 seconds...
[2025-03-23 13:35:13,855: ERROR/MainProcess] beat: Connection error: Error 111 connecting to localhost:6379. Connection refused.. Trying again in 32.0 seconds...
[2025-03-23 13:35:45,865: ERROR/MainProcess] beat: Connection error: Error 111 connecting to localhost:6379. Connection refused.. Trying again in 32.0 seconds...
[2025-03-23 13:36:17,876: ERROR/MainProcess] beat: Connection error: Error 111 connecting to localhost:6379. Connection refused.. Trying again in 32.0 seconds...
[2025-03-23 13:36:49,883: ERROR/MainProcess] beat: Connection error: Error 111 connecting to localhost:6379. Connection refused.. Trying again in 32.0 seconds...
[2025-03-23 13:37:21,888: ERROR/MainProcess] beat: Connection error: Error 111 connecting to localhost:6379. Connection refused.. Trying again in 32.0 seconds...
[2025-03-23 13:37:53,894: ERROR/MainProcess] beat: Connection error: Error 111 connecting to localhost:6379. Connection refused.. Trying again in 32.0 seconds...
[2025-03-23 13:38:25,909: ERROR/MainProcess] beat: Connection error: Error 111 connecting to localhost:6379. Connection refused.. Trying again in 32.0 seconds...
[2025-03-23 13:38:57,919: ERROR/MainProcess] beat: Connection error: Error 111 connecting to localhost:6379. Connection refused.. Trying again in 32.0 seconds...
[2025-03-23 13:39:29,928: ERROR/MainProcess] beat: Connection error: Error 111 connecting to localhost:6379. Connection refused.. Trying again in 32.0 seconds...
[2025-03-23 13:40:01,939: ERROR/MainProcess] beat: Connection error: Error 111 connecting to localhost:6379. Connection refused.. Trying again in 32.0 seconds...
[2025-03-23 13:40:33,948: ERROR/MainProcess] beat: Connection error: Error 111 connecting to localhost:6379. Connection refused.. Trying again in 32.0 seconds...
[2025-03-23 13:41:05,954: ERROR/MainProcess] beat: Connection error: Error 111 connecting to localhost:6379. Connection refused.. Trying again in 32.0 seconds...
[2025-03-23 13:41:37,962: ERROR/MainProcess] beat: Connection error: Error 111 connecting to localhost:6379. Connection refused.. Trying again in 32.0 seconds...
[2025-03-23 13:42:09,971: ERROR/MainProcess] beat: Connection error: Error 111 connecting to localhost:6379. Connection refused.. Trying again in 32.0 seconds...
[2025-03-23 13:42:41,979: ERROR/MainProcess] beat: Connection error: Error 111 connecting to localhost:6379. Connection refused.. Trying again in 32.0 seconds...
[2025-03-23 13:43:13,987: ERROR/MainProcess] beat: Connection error: Error 111 connecting to localhost:6379. Connection refused.. Trying again in 32.0 seconds...
[2025-03-23 13:43:45,996: ERROR/MainProcess] beat: Connection error: Error 111 connecting to localhost:6379. Connection refused.. Trying again in 32.0 seconds...
[2025-03-23 13:44:18,004: ERROR/MainProcess] beat: Connection error: Error 111 connecting to localhost:6379. Connection refused.. Trying again in 32.0 seconds...
[2025-03-23 13:44:50,011: ERROR/MainProcess] beat: Connection error: Error 111 connecting to localhost:6379. Connection refused.. Trying again in 32.0 seconds...
[2025-03-23 13:45:22,020: ERROR/MainProcess] beat: Connection error: Error 111 connecting to localhost:6379. Connection refused.. Trying again in 32.0 seconds...
[2025-03-23 13:45:54,029: ERROR/MainProcess] beat: Connection error: Error 111 connecting to localhost:6379. Connection refused.. Trying again in 32.0 seconds...
[2025-03-23 13:46:26,034: ERROR/MainProcess] beat: Connection error: Error 111 connecting to localhost:6379. Connection refused.. Trying again in 32.0 seconds...
[2025-03-23 13:46:58,041: ERROR/MainProcess] beat: Connection error: Error 111 connecting to localhost:6379. Connection refused.. Trying again in 32.0 seconds...
[2025-03-23 13:47:30,047: ERROR/MainProcess] beat: Connection error: Error 111 connecting to localhost:6379. Connection refused.. Trying again in 32.0 seconds...
[2025-03-23 13:48:02,055: ERROR/MainProcess] beat: Connection error: Error 111 connecting to localhost:6379. Connection refused.. Trying again in 32.0 seconds...
[2025-03-23 13:48:34,062: ERROR/MainProcess] beat: Connection error: Error 111 connecting to localhost:6379. Connection refused.. Trying again in 32.0 seconds...
[2025-03-23 13:49:06,072: ERROR/MainProcess] beat: Connection error: Error 111 connecting to localhost:6379. Connection refused.. Trying again in 32.0 seconds...
[2025-03-23 13:49:38,081: ERROR/MainProcess] beat: Connection error: Error 111 connecting to localhost:6379. Connection refused.. Trying again in 32.0 seconds...
[2025-03-23 13:50:10,090: ERROR/MainProcess] beat: Connection error: Error 111 connecting to localhost:6379. Connection refused.. Trying again in 32.0 seconds...
[2025-03-23 13:50:42,097: ERROR/MainProcess] beat: Connection error: Error 111 connecting to localhost:6379. Connection refused.. Trying again in 32.0 seconds...
[2025-03-23 13:51:14,107: ERROR/MainProcess] beat: Connection error: Error 111 connecting to localhost:6379. Connection refused.. Trying again in 32.0 seconds...
[2025-03-23 13:51:46,122: ERROR/MainProcess] beat: Connection error: Error 111 connecting to localhost:6379. Connection refused.. Trying again in 32.0 seconds...
[2025-03-23 13:52:18,132: ERROR/MainProcess] beat: Connection error: Error 111 connecting to localhost:6379. Connection refused.. Trying again in 32.0 seconds...
[2025-03-23 13:52:50,143: ERROR/MainProcess] beat: Connection error: Error 111 connecting to localhost:6379. Connection refused.. Trying again in 32.0 seconds...
[2025-03-23 13:53:22,151: ERROR/MainProcess] beat: Connection error: Error 111 connecting to localhost:6379. Connection refused.. Trying again in 32.0 seconds...
[2025-03-23 13:53:54,164: ERROR/MainProcess] beat: Connection error: Error 111 connecting to localhost:6379. Connection refused.. Trying again in 32.0 seconds...
[2025-03-23 13:54:26,176: ERROR/MainProcess] beat: Connection error: Error 111 connecting to localhost:6379. Connection refused.. Trying again in 32.0 seconds...
[2025-03-23 13:54:58,188: ERROR/MainProcess] beat: Connection error: Error 111 connecting to localhost:6379. Connection refused.. Trying again in 32.0 seconds...
[2025-03-23 13:55:30,195: ERROR/MainProcess] beat: Connection error: Error 111 connecting to localhost:6379. Connection refused.. Trying again in 32.0 seconds...
[2025-03-23 13:56:02,205: ERROR/MainProcess] beat: Connection error: Error 111 connecting to localhost:6379. Connection refused.. Trying again in 32.0 seconds...
[2025-03-23 13:56:34,213: ERROR/MainProcess] beat: Connection error: Error 111 connecting to localhost:6379. Connection refused.. Trying again in 32.0 seconds...
[2025-03-23 13:57:06,225: ERROR/MainProcess] beat: Connection error: Error 111 connecting to localhost:6379. Connection refused.. Trying again in 32.0 seconds...
[2025-03-23 13:57:38,235: ERROR/MainProcess] beat: Connection error: Error 111 connecting to localhost:6379. Connection refused.. Trying again in 32.0 seconds...
[2025-03-23 13:58:10,252: ERROR/MainProcess] beat: Connection error: Error 111 connecting to localhost:6379. Connection refused.. Trying again in 32.0 seconds...
[2025-03-23 13:58:42,269: ERROR/MainProcess] beat: Connection error: Error 111 connecting to localhost:6379. Connection refused.. Trying again in 32.0 seconds...
[2025-03-23 13:59:14,283: ERROR/MainProcess] beat: Connection error: Error 111 connecting to localhost:6379. Connection refused.. Trying again in 32.0 seconds...
[2025-03-23 13:59:46,294: ERROR/MainProcess] beat: Connection error: Error 111 connecting to localhost:6379. Connection refused.. Trying again in 32.0 seconds...
[2025-03-23 14:00:18,304: ERROR/MainProcess] beat: Connection error: Error 111 connecting to localhost:6379. Connection refused.. Trying again in 32.0 seconds...
[2025-03-23 14:00:50,316: ERROR/MainProcess] beat: Connection error: Error 111 connecting to localhost:6379. Connection refused.. Trying again in 32.0 seconds...
[2025-03-23 14:01:22,330: ERROR/MainProcess] beat: Connection error: Error 111 connecting to localhost:6379. Connection refused.. Trying again in 32.0 seconds...
[2025-03-23 14:01:54,346: ERROR/MainProcess] beat: Connection error: Error 111 connecting to localhost:6379. Connection refused.. Trying again in 32.0 seconds...
[2025-03-23 14:02:26,362: ERROR/MainProcess] beat: Connection error: Error 111 connecting to localhost:6379. Connection refused.. Trying again in 32.0 seconds...
[2025-03-23 14:02:58,387: ERROR/MainProcess] beat: Connection error: Error 111 connecting to localhost:6379. Connection refused.. Trying again in 32.0 seconds...
[2025-03-23 14:03:30,401: ERROR/MainProcess] beat: Connection error: Error 111 connecting to localhost:6379. Connection refused.. Trying again in 32.0 seconds...
[2025-03-23 14:04:02,415: ERROR/MainProcess] beat: Connection error: Error 111 connecting to localhost:6379. Connection refused.. Trying again in 32.0 seconds...
[2025-03-23 14:04:34,427: ERROR/MainProcess] beat: Connection error: Error 111 connecting to localhost:6379. Connection refused.. Trying again in 32.0 seconds...
[2025-03-23 14:05:06,434: ERROR/MainProcess] beat: Connection error: Error 111 connecting to localhost:6379. Connection refused.. Trying again in 32.0 seconds...
[2025-03-23 14:05:38,441: ERROR/MainProcess] beat: Connection error: Error 111 connecting to localhost:6379. Connection refused.. Trying again in 32.0 seconds...
[2025-03-23 14:06:10,451: ERROR/MainProcess] beat: Connection error: Error 111 connecting to localhost:6379. Connection refused.. Trying again in 32.0 seconds...
[2025-03-23 14:06:42,467: ERROR/MainProcess] beat: Connection error: Error 111 connecting to localhost:6379. Connection refused.. Trying again in 32.0 seconds...
[2025-03-23 14:07:14,479: ERROR/MainProcess] beat: Connection error: Error 111 connecting to localhost:6379. Connection refused.. Trying again in 32.0 seconds...
[2025-03-23 14:07:46,489: ERROR/MainProcess] beat: Connection error: Error 111 connecting to localhost:6379. Connection refused.. Trying again in 32.0 seconds...
[2025-03-23 14:08:18,497: ERROR/MainProcess] beat: Connection error: Error 111 connecting to localhost:6379. Connection refused.. Trying again in 32.0 seconds...
[2025-03-23 14:08:50,507: ERROR/MainProcess] beat: Connection error: Error 111 connecting to localhost:6379. Connection refused.. Trying again in 32.0 seconds...
[2025-03-23 14:09:22,519: ERROR/MainProcess] beat: Connection error: Error 111 connecting to localhost:6379. Connection refused.. Trying again in 32.0 seconds...
[2025-03-23 14:09:54,528: ERROR/MainProcess] beat: Connection error: Error 111 connecting to localhost:6379. Connection refused.. Trying again in 32.0 seconds...
[2025-03-23 14:10:26,537: ERROR/MainProcess] beat: Connection error: Error 111 connecting to localhost:6379. Connection refused.. Trying again in 32.0 seconds...
[2025-03-23 14:10:58,547: ERROR/MainProcess] beat: Connection error: Error 111 connecting to localhost:6379. Connection refused.. Trying again in 32.0 seconds...
[2025-03-23 14:11:30,556: ERROR/MainProcess] beat: Connection error: Error 111 connecting to localhost:6379. Connection refused.. Trying again in 32.0 seconds...
[2025-03-23 14:12:02,564: ERROR/MainProcess] beat: Connection error: Error 111 connecting to localhost:6379. Connection refused.. Trying again in 32.0 seconds...
[2025-03-23 14:12:34,574: ERROR/MainProcess] beat: Connection error: Error 111 connecting to localhost:6379. Connection refused.. Trying again in 32.0 seconds...
[2025-03-23 14:13:06,578: ERROR/MainProcess] beat: Connection error: Error 111 connecting to localhost:6379. Connection refused.. Trying again in 32.0 seconds...
[2025-03-23 14:13:38,582: ERROR/MainProcess] beat: Connection error: Error 111 connecting to localhost:6379. Connection refused.. Trying again in 32.0 seconds...
[2025-03-23 14:14:10,597: ERROR/MainProcess] beat: Connection error: Error 111 connecting to localhost:6379. Connection refused.. Trying again in 32.0 seconds...
[2025-03-23 14:14:42,617: ERROR/MainProcess] beat: Connection error: Error 111 connecting to localhost:6379. Connection refused.. Trying again in 32.0 seconds...
[2025-03-23 14:15:14,633: ERROR/MainProcess] beat: Connection error: Error 111 connecting to localhost:6379. Connection refused.. Trying again in 32.0 seconds...
[2025-03-23 14:15:46,646: ERROR/MainProcess] beat: Connection error: Error 111 connecting to localhost:6379. Connection refused.. Trying again in 32.0 seconds...
[2025-03-23 14:16:18,657: ERROR/MainProcess] beat: Connection error: Error 111 connecting to localhost:6379. Connection refused.. Trying again in 32.0 seconds...
[2025-03-23 14:16:50,668: ERROR/MainProcess] beat: Connection error: Error 111 connecting to localhost:6379. Connection refused.. Trying again in 32.0 seconds...
[2025-03-23 14:17:22,683: ERROR/MainProcess] beat: Connection error: Error 111 connecting to localhost:6379. Connection refused.. Trying again in 32.0 seconds...
[2025-03-23 14:17:54,712: CRITICAL/MainProcess] beat raised exception <class 'kombu.exceptions.OperationalError'>: OperationalError('Error 111 connecting to localhost:6379. Connection refused.')
Traceback (most recent call last):
  File "/home/abba/Desktop/skillsverse-backend/.venv/lib/python3.13/site-packages/kombu/transport/virtual/base.py", line 951, in create_channel
    return self._avail_channels.pop()
           ~~~~~~~~~~~~~~~~~~~~~~~~^^
IndexError: pop from empty list

During handling of the above exception, another exception occurred:

Traceback (most recent call last):
  File "/home/abba/Desktop/skillsverse-backend/.venv/lib/python3.13/site-packages/redis/connection.py", line 357, in connect
    sock = self.retry.call_with_retry(
        lambda: self._connect(), lambda error: self.disconnect(error)
    )
  File "/home/abba/Desktop/skillsverse-backend/.venv/lib/python3.13/site-packages/redis/retry.py", line 62, in call_with_retry
    return do()
  File "/home/abba/Desktop/skillsverse-backend/.venv/lib/python3.13/site-packages/redis/connection.py", line 358, in <lambda>
    lambda: self._connect(), lambda error: self.disconnect(error)
            ~~~~~~~~~~~~~^^
  File "/home/abba/Desktop/skillsverse-backend/.venv/lib/python3.13/site-packages/redis/connection.py", line 730, in _connect
    raise err
  File "/home/abba/Desktop/skillsverse-backend/.venv/lib/python3.13/site-packages/redis/connection.py", line 718, in _connect
    sock.connect(socket_address)
    ~~~~~~~~~~~~^^^^^^^^^^^^^^^^
ConnectionRefusedError: [Errno 111] Connection refused

During handling of the above exception, another exception occurred:

Traceback (most recent call last):
  File "/home/abba/Desktop/skillsverse-backend/.venv/lib/python3.13/site-packages/kombu/connection.py", line 472, in _reraise_as_library_errors
    yield
  File "/home/abba/Desktop/skillsverse-backend/.venv/lib/python3.13/site-packages/kombu/connection.py", line 459, in _ensure_connection
    return retry_over_time(
        self._connection_factory, self.recoverable_connection_errors,
    ...<2 lines>...
        callback, timeout=timeout
    )
  File "/home/abba/Desktop/skillsverse-backend/.venv/lib/python3.13/site-packages/kombu/utils/functional.py", line 318, in retry_over_time
    return fun(*args, **kwargs)
  File "/home/abba/Desktop/skillsverse-backend/.venv/lib/python3.13/site-packages/kombu/connection.py", line 934, in _connection_factory
    self._connection = self._establish_connection()
                       ~~~~~~~~~~~~~~~~~~~~~~~~~~^^
  File "/home/abba/Desktop/skillsverse-backend/.venv/lib/python3.13/site-packages/kombu/connection.py", line 860, in _establish_connection
    conn = self.transport.establish_connection()
  File "/home/abba/Desktop/skillsverse-backend/.venv/lib/python3.13/site-packages/kombu/transport/virtual/base.py", line 975, in establish_connection
    self._avail_channels.append(self.create_channel(self))
                                ~~~~~~~~~~~~~~~~~~~^^^^^^
  File "/home/abba/Desktop/skillsverse-backend/.venv/lib/python3.13/site-packages/kombu/transport/virtual/base.py", line 953, in create_channel
    channel = self.Channel(connection)
  File "/home/abba/Desktop/skillsverse-backend/.venv/lib/python3.13/site-packages/kombu/transport/redis.py", line 744, in __init__
    self.client.ping()
    ~~~~~~~~~~~~~~~~^^
  File "/home/abba/Desktop/skillsverse-backend/.venv/lib/python3.13/site-packages/redis/commands/core.py", line 1212, in ping
    return self.execute_command("PING", **kwargs)
           ~~~~~~~~~~~~~~~~~~~~^^^^^^^^^^^^^^^^^^
  File "/home/abba/Desktop/skillsverse-backend/.venv/lib/python3.13/site-packages/redis/client.py", line 559, in execute_command
    return self._execute_command(*args, **options)
           ~~~~~~~~~~~~~~~~~~~~~^^^^^^^^^^^^^^^^^^
  File "/home/abba/Desktop/skillsverse-backend/.venv/lib/python3.13/site-packages/redis/client.py", line 565, in _execute_command
    conn = self.connection or pool.get_connection(command_name, **options)
                              ~~~~~~~~~~~~~~~~~~~^^^^^^^^^^^^^^^^^^^^^^^^^
  File "/home/abba/Desktop/skillsverse-backend/.venv/lib/python3.13/site-packages/redis/connection.py", line 1422, in get_connection
    connection.connect()
    ~~~~~~~~~~~~~~~~~~^^
  File "/home/abba/Desktop/skillsverse-backend/.venv/lib/python3.13/site-packages/redis/connection.py", line 363, in connect
    raise ConnectionError(self._error_message(e))
redis.exceptions.ConnectionError: Error 111 connecting to localhost:6379. Connection refused.

The above exception was the direct cause of the following exception:

Traceback (most recent call last):
  File "/home/abba/Desktop/skillsverse-backend/.venv/lib/python3.13/site-packages/celery/apps/beat.py", line 113, in start_scheduler
    service.start()
    ~~~~~~~~~~~~~^^
  File "/home/abba/Desktop/skillsverse-backend/.venv/lib/python3.13/site-packages/celery/beat.py", line 643, in start
    interval = self.scheduler.tick()
  File "/home/abba/Desktop/skillsverse-backend/.venv/lib/python3.13/site-packages/celery/beat.py", line 353, in tick
    self.apply_entry(entry, producer=self.producer)
                                     ^^^^^^^^^^^^^
  File "/home/abba/Desktop/skillsverse-backend/.venv/lib/python3.13/site-packages/kombu/utils/objects.py", line 40, in __get__
    return super().__get__(instance, owner)
           ~~~~~~~~~~~~~~~^^^^^^^^^^^^^^^^^
  File "/usr/lib/python3.13/functools.py", line 1042, in __get__
    val = self.func(instance)
  File "/home/abba/Desktop/skillsverse-backend/.venv/lib/python3.13/site-packages/celery/beat.py", line 496, in producer
    return self.Producer(self._ensure_connected(), auto_declare=False)
                         ~~~~~~~~~~~~~~~~~~~~~~^^
  File "/home/abba/Desktop/skillsverse-backend/.venv/lib/python3.13/site-packages/celery/beat.py", line 479, in _ensure_connected
    return self.connection.ensure_connection(
           ~~~~~~~~~~~~~~~~~~~~~~~~~~~~~~~~~^
        _error_handler, self.app.conf.broker_connection_max_retries
        ^^^^^^^^^^^^^^^^^^^^^^^^^^^^^^^^^^^^^^^^^^^^^^^^^^^^^^^^^^^
    )
    ^
  File "/home/abba/Desktop/skillsverse-backend/.venv/lib/python3.13/site-packages/kombu/connection.py", line 406, in ensure_connection
    self._ensure_connection(*args, **kwargs)
    ~~~~~~~~~~~~~~~~~~~~~~~^^^^^^^^^^^^^^^^^
  File "/home/abba/Desktop/skillsverse-backend/.venv/lib/python3.13/site-packages/kombu/connection.py", line 458, in _ensure_connection
    with ctx():
         ~~~^^
  File "/usr/lib/python3.13/contextlib.py", line 162, in __exit__
    self.gen.throw(value)
    ~~~~~~~~~~~~~~^^^^^^^
  File "/home/abba/Desktop/skillsverse-backend/.venv/lib/python3.13/site-packages/kombu/connection.py", line 476, in _reraise_as_library_errors
    raise ConnectionError(str(exc)) from exc
kombu.exceptions.OperationalError: Error 111 connecting to localhost:6379. Connection refused.
[2025-03-23 14:17:54,727: WARNING/MainProcess] Traceback (most recent call last):
[2025-03-23 14:17:54,728: WARNING/MainProcess]   File "/home/abba/Desktop/skillsverse-backend/.venv/lib/python3.13/site-packages/kombu/transport/virtual/base.py", line 951, in create_channel
    return self._avail_channels.pop()
           ~~~~~~~~~~~~~~~~~~~~~~~~^^
[2025-03-23 14:17:54,728: WARNING/MainProcess] IndexError: pop from empty list
[2025-03-23 14:17:54,728: WARNING/MainProcess] 
During handling of the above exception, another exception occurred:
[2025-03-23 14:17:54,728: WARNING/MainProcess] Traceback (most recent call last):
[2025-03-23 14:17:54,729: WARNING/MainProcess]   File "/home/abba/Desktop/skillsverse-backend/.venv/lib/python3.13/site-packages/redis/connection.py", line 357, in connect
    sock = self.retry.call_with_retry(
        lambda: self._connect(), lambda error: self.disconnect(error)
    )
[2025-03-23 14:17:54,729: WARNING/MainProcess]   File "/home/abba/Desktop/skillsverse-backend/.venv/lib/python3.13/site-packages/redis/retry.py", line 62, in call_with_retry
    return do()
[2025-03-23 14:17:54,729: WARNING/MainProcess]   File "/home/abba/Desktop/skillsverse-backend/.venv/lib/python3.13/site-packages/redis/connection.py", line 358, in <lambda>
    lambda: self._connect(), lambda error: self.disconnect(error)
            ~~~~~~~~~~~~~^^
[2025-03-23 14:17:54,729: WARNING/MainProcess]   File "/home/abba/Desktop/skillsverse-backend/.venv/lib/python3.13/site-packages/redis/connection.py", line 730, in _connect
    raise err
[2025-03-23 14:17:54,729: WARNING/MainProcess]   File "/home/abba/Desktop/skillsverse-backend/.venv/lib/python3.13/site-packages/redis/connection.py", line 718, in _connect
    sock.connect(socket_address)
    ~~~~~~~~~~~~^^^^^^^^^^^^^^^^
[2025-03-23 14:17:54,729: WARNING/MainProcess] ConnectionRefusedError: [Errno 111] Connection refused
[2025-03-23 14:17:54,729: WARNING/MainProcess] 
During handling of the above exception, another exception occurred:
[2025-03-23 14:17:54,729: WARNING/MainProcess] Traceback (most recent call last):
[2025-03-23 14:17:54,731: WARNING/MainProcess]   File "/home/abba/Desktop/skillsverse-backend/.venv/lib/python3.13/site-packages/kombu/connection.py", line 472, in _reraise_as_library_errors
    yield
[2025-03-23 14:17:54,731: WARNING/MainProcess]   File "/home/abba/Desktop/skillsverse-backend/.venv/lib/python3.13/site-packages/kombu/connection.py", line 459, in _ensure_connection
    return retry_over_time(
        self._connection_factory, self.recoverable_connection_errors,
    ...<2 lines>...
        callback, timeout=timeout
    )
[2025-03-23 14:17:54,731: WARNING/MainProcess]   File "/home/abba/Desktop/skillsverse-backend/.venv/lib/python3.13/site-packages/kombu/utils/functional.py", line 318, in retry_over_time
    return fun(*args, **kwargs)
[2025-03-23 14:17:54,731: WARNING/MainProcess]   File "/home/abba/Desktop/skillsverse-backend/.venv/lib/python3.13/site-packages/kombu/connection.py", line 934, in _connection_factory
    self._connection = self._establish_connection()
                       ~~~~~~~~~~~~~~~~~~~~~~~~~~^^
[2025-03-23 14:17:54,731: WARNING/MainProcess]   File "/home/abba/Desktop/skillsverse-backend/.venv/lib/python3.13/site-packages/kombu/connection.py", line 860, in _establish_connection
    conn = self.transport.establish_connection()
[2025-03-23 14:17:54,732: WARNING/MainProcess]   File "/home/abba/Desktop/skillsverse-backend/.venv/lib/python3.13/site-packages/kombu/transport/virtual/base.py", line 975, in establish_connection
    self._avail_channels.append(self.create_channel(self))
                                ~~~~~~~~~~~~~~~~~~~^^^^^^
[2025-03-23 14:17:54,732: WARNING/MainProcess]   File "/home/abba/Desktop/skillsverse-backend/.venv/lib/python3.13/site-packages/kombu/transport/virtual/base.py", line 953, in create_channel
    channel = self.Channel(connection)
[2025-03-23 14:17:54,732: WARNING/MainProcess]   File "/home/abba/Desktop/skillsverse-backend/.venv/lib/python3.13/site-packages/kombu/transport/redis.py", line 744, in __init__
    self.client.ping()
    ~~~~~~~~~~~~~~~~^^
[2025-03-23 14:17:54,732: WARNING/MainProcess]   File "/home/abba/Desktop/skillsverse-backend/.venv/lib/python3.13/site-packages/redis/commands/core.py", line 1212, in ping
    return self.execute_command("PING", **kwargs)
           ~~~~~~~~~~~~~~~~~~~~^^^^^^^^^^^^^^^^^^
[2025-03-23 14:17:54,732: WARNING/MainProcess]   File "/home/abba/Desktop/skillsverse-backend/.venv/lib/python3.13/site-packages/redis/client.py", line 559, in execute_command
    return self._execute_command(*args, **options)
           ~~~~~~~~~~~~~~~~~~~~~^^^^^^^^^^^^^^^^^^
[2025-03-23 14:17:54,732: WARNING/MainProcess]   File "/home/abba/Desktop/skillsverse-backend/.venv/lib/python3.13/site-packages/redis/client.py", line 565, in _execute_command
    conn = self.connection or pool.get_connection(command_name, **options)
                              ~~~~~~~~~~~~~~~~~~~^^^^^^^^^^^^^^^^^^^^^^^^^
[2025-03-23 14:17:54,732: WARNING/MainProcess]   File "/home/abba/Desktop/skillsverse-backend/.venv/lib/python3.13/site-packages/redis/connection.py", line 1422, in get_connection
    connection.connect()
    ~~~~~~~~~~~~~~~~~~^^
[2025-03-23 14:17:54,732: WARNING/MainProcess]   File "/home/abba/Desktop/skillsverse-backend/.venv/lib/python3.13/site-packages/redis/connection.py", line 363, in connect
    raise ConnectionError(self._error_message(e))
[2025-03-23 14:17:54,732: WARNING/MainProcess] redis.exceptions.ConnectionError: Error 111 connecting to localhost:6379. Connection refused.
[2025-03-23 14:17:54,732: WARNING/MainProcess] 
The above exception was the direct cause of the following exception:
[2025-03-23 14:17:54,732: WARNING/MainProcess] Traceback (most recent call last):
[2025-03-23 14:17:54,735: WARNING/MainProcess]   File "/home/abba/Desktop/skillsverse-backend/.venv/bin/celery", line 8, in <module>
    sys.exit(main())
             ~~~~^^
[2025-03-23 14:17:54,736: WARNING/MainProcess]   File "/home/abba/Desktop/skillsverse-backend/.venv/lib/python3.13/site-packages/celery/__main__.py", line 15, in main
    sys.exit(_main())
             ~~~~~^^
[2025-03-23 14:17:54,736: WARNING/MainProcess]   File "/home/abba/Desktop/skillsverse-backend/.venv/lib/python3.13/site-packages/celery/bin/celery.py", line 236, in main
    return celery(auto_envvar_prefix="CELERY")
[2025-03-23 14:17:54,736: WARNING/MainProcess]   File "/home/abba/Desktop/skillsverse-backend/.venv/lib/python3.13/site-packages/click/core.py", line 1161, in __call__
    return self.main(*args, **kwargs)
           ~~~~~~~~~^^^^^^^^^^^^^^^^^
[2025-03-23 14:17:54,736: WARNING/MainProcess]   File "/home/abba/Desktop/skillsverse-backend/.venv/lib/python3.13/site-packages/click/core.py", line 1082, in main
    rv = self.invoke(ctx)
[2025-03-23 14:17:54,736: WARNING/MainProcess]   File "/home/abba/Desktop/skillsverse-backend/.venv/lib/python3.13/site-packages/click/core.py", line 1697, in invoke
    return _process_result(sub_ctx.command.invoke(sub_ctx))
                           ~~~~~~~~~~~~~~~~~~~~~~^^^^^^^^^
[2025-03-23 14:17:54,736: WARNING/MainProcess]   File "/home/abba/Desktop/skillsverse-backend/.venv/lib/python3.13/site-packages/click/core.py", line 1443, in invoke
    return ctx.invoke(self.callback, **ctx.params)
           ~~~~~~~~~~^^^^^^^^^^^^^^^^^^^^^^^^^^^^^
[2025-03-23 14:17:54,736: WARNING/MainProcess]   File "/home/abba/Desktop/skillsverse-backend/.venv/lib/python3.13/site-packages/click/core.py", line 788, in invoke
    return __callback(*args, **kwargs)
[2025-03-23 14:17:54,736: WARNING/MainProcess]   File "/home/abba/Desktop/skillsverse-backend/.venv/lib/python3.13/site-packages/click/decorators.py", line 33, in new_func
    return f(get_current_context(), *args, **kwargs)
[2025-03-23 14:17:54,736: WARNING/MainProcess]   File "/home/abba/Desktop/skillsverse-backend/.venv/lib/python3.13/site-packages/celery/bin/base.py", line 135, in caller
    return f(ctx, *args, **kwargs)
[2025-03-23 14:17:54,736: WARNING/MainProcess]   File "/home/abba/Desktop/skillsverse-backend/.venv/lib/python3.13/site-packages/celery/bin/beat.py", line 72, in beat
    return beat().run()
           ~~~~~~~~~~^^
[2025-03-23 14:17:54,736: WARNING/MainProcess]   File "/home/abba/Desktop/skillsverse-backend/.venv/lib/python3.13/site-packages/celery/apps/beat.py", line 84, in run
    self.start_scheduler()
    ~~~~~~~~~~~~~~~~~~~~^^
[2025-03-23 14:17:54,736: WARNING/MainProcess]   File "/home/abba/Desktop/skillsverse-backend/.venv/lib/python3.13/site-packages/celery/apps/beat.py", line 113, in start_scheduler
    service.start()
    ~~~~~~~~~~~~~^^
[2025-03-23 14:17:54,736: WARNING/MainProcess]   File "/home/abba/Desktop/skillsverse-backend/.venv/lib/python3.13/site-packages/celery/beat.py", line 643, in start
    interval = self.scheduler.tick()
[2025-03-23 14:17:54,736: WARNING/MainProcess]   File "/home/abba/Desktop/skillsverse-backend/.venv/lib/python3.13/site-packages/celery/beat.py", line 353, in tick
    self.apply_entry(entry, producer=self.producer)
                                     ^^^^^^^^^^^^^
[2025-03-23 14:17:54,737: WARNING/MainProcess]   File "/home/abba/Desktop/skillsverse-backend/.venv/lib/python3.13/site-packages/kombu/utils/objects.py", line 40, in __get__
    return super().__get__(instance, owner)
           ~~~~~~~~~~~~~~~^^^^^^^^^^^^^^^^^
[2025-03-23 14:17:54,737: WARNING/MainProcess]   File "/usr/lib/python3.13/functools.py", line 1042, in __get__
    val = self.func(instance)
[2025-03-23 14:17:54,737: WARNING/MainProcess]   File "/home/abba/Desktop/skillsverse-backend/.venv/lib/python3.13/site-packages/celery/beat.py", line 496, in producer
    return self.Producer(self._ensure_connected(), auto_declare=False)
                         ~~~~~~~~~~~~~~~~~~~~~~^^
[2025-03-23 14:17:54,737: WARNING/MainProcess]   File "/home/abba/Desktop/skillsverse-backend/.venv/lib/python3.13/site-packages/celery/beat.py", line 479, in _ensure_connected
    return self.connection.ensure_connection(
           ~~~~~~~~~~~~~~~~~~~~~~~~~~~~~~~~~^
        _error_handler, self.app.conf.broker_connection_max_retries
        ^^^^^^^^^^^^^^^^^^^^^^^^^^^^^^^^^^^^^^^^^^^^^^^^^^^^^^^^^^^
    )
    ^
[2025-03-23 14:17:54,737: WARNING/MainProcess]   File "/home/abba/Desktop/skillsverse-backend/.venv/lib/python3.13/site-packages/kombu/connection.py", line 406, in ensure_connection
    self._ensure_connection(*args, **kwargs)
    ~~~~~~~~~~~~~~~~~~~~~~~^^^^^^^^^^^^^^^^^
[2025-03-23 14:17:54,737: WARNING/MainProcess]   File "/home/abba/Desktop/skillsverse-backend/.venv/lib/python3.13/site-packages/kombu/connection.py", line 458, in _ensure_connection
    with ctx():
         ~~~^^
[2025-03-23 14:17:54,737: WARNING/MainProcess]   File "/usr/lib/python3.13/contextlib.py", line 162, in __exit__
    self.gen.throw(value)
    ~~~~~~~~~~~~~~^^^^^^^
[2025-03-23 14:17:54,737: WARNING/MainProcess]   File "/home/abba/Desktop/skillsverse-backend/.venv/lib/python3.13/site-packages/kombu/connection.py", line 476, in _reraise_as_library_errors
    raise ConnectionError(str(exc)) from exc
[2025-03-23 14:17:54,737: WARNING/MainProcess] kombu.exceptions.OperationalError: Error 111 connecting to localhost:6379. Connection refused.
[2025-03-28 15:24:45,411: INFO/MainProcess] beat: Starting...
[2025-03-28 15:24:45,473: INFO/MainProcess] DatabaseScheduler: Schedule changed.
[2025-03-28 15:24:45,498: ERROR/MainProcess] beat: Connection error: Error 111 connecting to localhost:6379. Connection refused.. Trying again in 2.0 seconds...
[2025-03-28 15:24:47,500: ERROR/MainProcess] beat: Connection error: Error 111 connecting to localhost:6379. Connection refused.. Trying again in 4.0 seconds...
[2025-03-28 15:24:51,504: ERROR/MainProcess] beat: Connection error: Error 111 connecting to localhost:6379. Connection refused.. Trying again in 6.0 seconds...
[2025-03-28 15:24:57,510: ERROR/MainProcess] beat: Connection error: Error 111 connecting to localhost:6379. Connection refused.. Trying again in 8.0 seconds...
[2025-03-28 15:25:05,515: ERROR/MainProcess] beat: Connection error: Error 111 connecting to localhost:6379. Connection refused.. Trying again in 10.0 seconds...
[2025-03-28 15:25:15,522: ERROR/MainProcess] beat: Connection error: Error 111 connecting to localhost:6379. Connection refused.. Trying again in 12.0 seconds...
[2025-03-28 15:25:27,528: ERROR/MainProcess] beat: Connection error: Error 111 connecting to localhost:6379. Connection refused.. Trying again in 14.0 seconds...
[2025-03-28 15:25:41,532: ERROR/MainProcess] beat: Connection error: Error 111 connecting to localhost:6379. Connection refused.. Trying again in 16.0 seconds...
[2025-03-28 15:25:57,538: ERROR/MainProcess] beat: Connection error: Error 111 connecting to localhost:6379. Connection refused.. Trying again in 18.0 seconds...
[2025-03-28 15:26:15,545: ERROR/MainProcess] beat: Connection error: Error 111 connecting to localhost:6379. Connection refused.. Trying again in 20.0 seconds...
[2025-03-28 15:26:35,552: ERROR/MainProcess] beat: Connection error: Error 111 connecting to localhost:6379. Connection refused.. Trying again in 22.0 seconds...
[2025-03-28 15:26:57,559: ERROR/MainProcess] beat: Connection error: Error 111 connecting to localhost:6379. Connection refused.. Trying again in 24.0 seconds...
[2025-03-28 15:27:21,567: ERROR/MainProcess] beat: Connection error: Error 111 connecting to localhost:6379. Connection refused.. Trying again in 26.0 seconds...
[2025-03-28 15:27:47,577: ERROR/MainProcess] beat: Connection error: Error 111 connecting to localhost:6379. Connection refused.. Trying again in 28.0 seconds...
[2025-03-28 15:28:15,585: ERROR/MainProcess] beat: Connection error: Error 111 connecting to localhost:6379. Connection refused.. Trying again in 30.0 seconds...
[2025-03-28 15:28:45,593: ERROR/MainProcess] beat: Connection error: Error 111 connecting to localhost:6379. Connection refused.. Trying again in 32.0 seconds...
[2025-03-28 15:29:17,604: ERROR/MainProcess] beat: Connection error: Error 111 connecting to localhost:6379. Connection refused.. Trying again in 32.0 seconds...
[2025-03-28 15:29:49,616: ERROR/MainProcess] beat: Connection error: Error 111 connecting to localhost:6379. Connection refused.. Trying again in 32.0 seconds...
[2025-03-28 15:30:21,632: ERROR/MainProcess] beat: Connection error: Error 111 connecting to localhost:6379. Connection refused.. Trying again in 32.0 seconds...
[2025-03-28 15:30:53,642: ERROR/MainProcess] beat: Connection error: Error 111 connecting to localhost:6379. Connection refused.. Trying again in 32.0 seconds...
[2025-03-28 15:31:25,648: ERROR/MainProcess] beat: Connection error: Error 111 connecting to localhost:6379. Connection refused.. Trying again in 32.0 seconds...
[2025-03-28 15:31:57,656: ERROR/MainProcess] beat: Connection error: Error 111 connecting to localhost:6379. Connection refused.. Trying again in 32.0 seconds...
[2025-03-28 15:32:29,666: ERROR/MainProcess] beat: Connection error: Error 111 connecting to localhost:6379. Connection refused.. Trying again in 32.0 seconds...
[2025-03-28 15:33:01,675: ERROR/MainProcess] beat: Connection error: Error 111 connecting to localhost:6379. Connection refused.. Trying again in 32.0 seconds...
[2025-03-28 15:33:33,685: ERROR/MainProcess] beat: Connection error: Error 111 connecting to localhost:6379. Connection refused.. Trying again in 32.0 seconds...
[2025-03-28 15:34:05,697: ERROR/MainProcess] beat: Connection error: Error 111 connecting to localhost:6379. Connection refused.. Trying again in 32.0 seconds...
[2025-03-28 15:34:37,713: ERROR/MainProcess] beat: Connection error: Error 111 connecting to localhost:6379. Connection refused.. Trying again in 32.0 seconds...
[2025-03-28 15:35:09,724: ERROR/MainProcess] beat: Connection error: Error 111 connecting to localhost:6379. Connection refused.. Trying again in 32.0 seconds...
[2025-03-28 15:35:41,734: ERROR/MainProcess] beat: Connection error: Error 111 connecting to localhost:6379. Connection refused.. Trying again in 32.0 seconds...
[2025-03-28 15:36:13,745: ERROR/MainProcess] beat: Connection error: Error 111 connecting to localhost:6379. Connection refused.. Trying again in 32.0 seconds...
[2025-03-28 15:36:45,753: ERROR/MainProcess] beat: Connection error: Error 111 connecting to localhost:6379. Connection refused.. Trying again in 32.0 seconds...
[2025-03-28 15:37:17,763: ERROR/MainProcess] beat: Connection error: Error 111 connecting to localhost:6379. Connection refused.. Trying again in 32.0 seconds...
[2025-03-28 15:37:49,772: ERROR/MainProcess] beat: Connection error: Error 111 connecting to localhost:6379. Connection refused.. Trying again in 32.0 seconds...
[2025-03-28 15:38:21,782: ERROR/MainProcess] beat: Connection error: Error 111 connecting to localhost:6379. Connection refused.. Trying again in 32.0 seconds...
[2025-03-28 15:38:53,791: ERROR/MainProcess] beat: Connection error: Error 111 connecting to localhost:6379. Connection refused.. Trying again in 32.0 seconds...
[2025-03-28 15:39:25,799: ERROR/MainProcess] beat: Connection error: Error 111 connecting to localhost:6379. Connection refused.. Trying again in 32.0 seconds...
[2025-03-28 15:39:57,808: ERROR/MainProcess] beat: Connection error: Error 111 connecting to localhost:6379. Connection refused.. Trying again in 32.0 seconds...
[2025-03-28 15:40:29,818: ERROR/MainProcess] beat: Connection error: Error 111 connecting to localhost:6379. Connection refused.. Trying again in 32.0 seconds...
[2025-03-28 15:41:01,826: ERROR/MainProcess] beat: Connection error: Error 111 connecting to localhost:6379. Connection refused.. Trying again in 32.0 seconds...
[2025-03-28 15:41:33,834: ERROR/MainProcess] beat: Connection error: Error 111 connecting to localhost:6379. Connection refused.. Trying again in 32.0 seconds...
[2025-03-28 15:42:05,842: ERROR/MainProcess] beat: Connection error: Error 111 connecting to localhost:6379. Connection refused.. Trying again in 32.0 seconds...
[2025-03-28 15:42:37,860: ERROR/MainProcess] beat: Connection error: Error 111 connecting to localhost:6379. Connection refused.. Trying again in 32.0 seconds...
[2025-03-28 15:43:09,868: ERROR/MainProcess] beat: Connection error: Error 111 connecting to localhost:6379. Connection refused.. Trying again in 32.0 seconds...
[2025-03-28 15:43:41,874: ERROR/MainProcess] beat: Connection error: Error 111 connecting to localhost:6379. Connection refused.. Trying again in 32.0 seconds...
[2025-03-28 15:44:13,886: ERROR/MainProcess] beat: Connection error: Error 111 connecting to localhost:6379. Connection refused.. Trying again in 32.0 seconds...
[2025-03-28 15:44:45,897: ERROR/MainProcess] beat: Connection error: Error 111 connecting to localhost:6379. Connection refused.. Trying again in 32.0 seconds...
[2025-03-28 15:45:17,905: ERROR/MainProcess] beat: Connection error: Error 111 connecting to localhost:6379. Connection refused.. Trying again in 32.0 seconds...
[2025-03-28 15:45:49,914: ERROR/MainProcess] beat: Connection error: Error 111 connecting to localhost:6379. Connection refused.. Trying again in 32.0 seconds...
[2025-03-28 15:46:21,923: ERROR/MainProcess] beat: Connection error: Error 111 connecting to localhost:6379. Connection refused.. Trying again in 32.0 seconds...
[2025-03-28 15:46:53,933: ERROR/MainProcess] beat: Connection error: Error 111 connecting to localhost:6379. Connection refused.. Trying again in 32.0 seconds...
[2025-03-28 15:47:25,940: ERROR/MainProcess] beat: Connection error: Error 111 connecting to localhost:6379. Connection refused.. Trying again in 32.0 seconds...
[2025-03-28 15:47:57,947: ERROR/MainProcess] beat: Connection error: Error 111 connecting to localhost:6379. Connection refused.. Trying again in 32.0 seconds...
[2025-03-28 15:48:29,956: ERROR/MainProcess] beat: Connection error: Error 111 connecting to localhost:6379. Connection refused.. Trying again in 32.0 seconds...
[2025-03-28 15:49:01,970: ERROR/MainProcess] beat: Connection error: Error 111 connecting to localhost:6379. Connection refused.. Trying again in 32.0 seconds...
[2025-03-28 15:49:33,989: ERROR/MainProcess] beat: Connection error: Error 111 connecting to localhost:6379. Connection refused.. Trying again in 32.0 seconds...
[2025-03-28 15:50:05,997: ERROR/MainProcess] beat: Connection error: Error 111 connecting to localhost:6379. Connection refused.. Trying again in 32.0 seconds...
[2025-03-28 15:50:38,007: ERROR/MainProcess] beat: Connection error: Error 111 connecting to localhost:6379. Connection refused.. Trying again in 32.0 seconds...
[2025-03-28 15:51:10,019: ERROR/MainProcess] beat: Connection error: Error 111 connecting to localhost:6379. Connection refused.. Trying again in 32.0 seconds...
[2025-03-28 15:51:42,032: ERROR/MainProcess] beat: Connection error: Error 111 connecting to localhost:6379. Connection refused.. Trying again in 32.0 seconds...
[2025-03-28 15:52:14,045: ERROR/MainProcess] beat: Connection error: Error 111 connecting to localhost:6379. Connection refused.. Trying again in 32.0 seconds...
[2025-03-28 15:52:46,057: ERROR/MainProcess] beat: Connection error: Error 111 connecting to localhost:6379. Connection refused.. Trying again in 32.0 seconds...
[2025-03-28 15:53:18,070: ERROR/MainProcess] beat: Connection error: Error 111 connecting to localhost:6379. Connection refused.. Trying again in 32.0 seconds...
[2025-03-28 15:53:50,081: ERROR/MainProcess] beat: Connection error: Error 111 connecting to localhost:6379. Connection refused.. Trying again in 32.0 seconds...
[2025-03-28 15:54:22,093: ERROR/MainProcess] beat: Connection error: Error 111 connecting to localhost:6379. Connection refused.. Trying again in 32.0 seconds...
[2025-03-28 15:54:54,103: ERROR/MainProcess] beat: Connection error: Error 111 connecting to localhost:6379. Connection refused.. Trying again in 32.0 seconds...
[2025-03-28 15:55:26,115: ERROR/MainProcess] beat: Connection error: Error 111 connecting to localhost:6379. Connection refused.. Trying again in 32.0 seconds...
[2025-03-28 15:55:58,122: ERROR/MainProcess] beat: Connection error: Error 111 connecting to localhost:6379. Connection refused.. Trying again in 32.0 seconds...
[2025-03-28 15:56:30,130: ERROR/MainProcess] beat: Connection error: Error 111 connecting to localhost:6379. Connection refused.. Trying again in 32.0 seconds...
[2025-03-28 15:57:02,141: ERROR/MainProcess] beat: Connection error: Error 111 connecting to localhost:6379. Connection refused.. Trying again in 32.0 seconds...
[2025-03-28 15:57:34,152: ERROR/MainProcess] beat: Connection error: Error 111 connecting to localhost:6379. Connection refused.. Trying again in 32.0 seconds...
[2025-03-28 15:58:06,164: ERROR/MainProcess] beat: Connection error: Error 111 connecting to localhost:6379. Connection refused.. Trying again in 32.0 seconds...
[2025-03-28 15:58:38,171: ERROR/MainProcess] beat: Connection error: Error 111 connecting to localhost:6379. Connection refused.. Trying again in 32.0 seconds...
[2025-03-28 15:59:10,183: ERROR/MainProcess] beat: Connection error: Error 111 connecting to localhost:6379. Connection refused.. Trying again in 32.0 seconds...
[2025-03-28 15:59:42,196: ERROR/MainProcess] beat: Connection error: Error 111 connecting to localhost:6379. Connection refused.. Trying again in 32.0 seconds...
[2025-03-28 16:00:14,204: ERROR/MainProcess] beat: Connection error: Error 111 connecting to localhost:6379. Connection refused.. Trying again in 32.0 seconds...
[2025-03-28 16:00:46,211: ERROR/MainProcess] beat: Connection error: Error 111 connecting to localhost:6379. Connection refused.. Trying again in 32.0 seconds...
[2025-03-28 16:01:18,219: ERROR/MainProcess] beat: Connection error: Error 111 connecting to localhost:6379. Connection refused.. Trying again in 32.0 seconds...
[2025-03-28 16:01:50,231: ERROR/MainProcess] beat: Connection error: Error 111 connecting to localhost:6379. Connection refused.. Trying again in 32.0 seconds...
[2025-03-28 16:02:22,242: ERROR/MainProcess] beat: Connection error: Error 111 connecting to localhost:6379. Connection refused.. Trying again in 32.0 seconds...
[2025-03-28 16:02:54,254: ERROR/MainProcess] beat: Connection error: Error 111 connecting to localhost:6379. Connection refused.. Trying again in 32.0 seconds...
[2025-03-28 16:03:26,262: ERROR/MainProcess] beat: Connection error: Error 111 connecting to localhost:6379. Connection refused.. Trying again in 32.0 seconds...
[2025-03-28 16:03:58,272: ERROR/MainProcess] beat: Connection error: Error 111 connecting to localhost:6379. Connection refused.. Trying again in 32.0 seconds...
[2025-03-28 16:04:30,281: ERROR/MainProcess] beat: Connection error: Error 111 connecting to localhost:6379. Connection refused.. Trying again in 32.0 seconds...
[2025-03-28 16:05:02,288: ERROR/MainProcess] beat: Connection error: Error 111 connecting to localhost:6379. Connection refused.. Trying again in 32.0 seconds...
[2025-03-28 16:05:34,295: ERROR/MainProcess] beat: Connection error: Error 111 connecting to localhost:6379. Connection refused.. Trying again in 32.0 seconds...
[2025-03-28 16:06:06,304: ERROR/MainProcess] beat: Connection error: Error 111 connecting to localhost:6379. Connection refused.. Trying again in 32.0 seconds...
[2025-03-28 16:06:38,313: ERROR/MainProcess] beat: Connection error: Error 111 connecting to localhost:6379. Connection refused.. Trying again in 32.0 seconds...
[2025-03-28 16:07:10,322: ERROR/MainProcess] beat: Connection error: Error 111 connecting to localhost:6379. Connection refused.. Trying again in 32.0 seconds...
[2025-03-28 16:07:42,331: ERROR/MainProcess] beat: Connection error: Error 111 connecting to localhost:6379. Connection refused.. Trying again in 32.0 seconds...
[2025-03-28 16:08:14,337: ERROR/MainProcess] beat: Connection error: Error 111 connecting to localhost:6379. Connection refused.. Trying again in 32.0 seconds...
[2025-03-28 16:08:46,345: ERROR/MainProcess] beat: Connection error: Error 111 connecting to localhost:6379. Connection refused.. Trying again in 32.0 seconds...
[2025-03-28 16:09:18,353: ERROR/MainProcess] beat: Connection error: Error 111 connecting to localhost:6379. Connection refused.. Trying again in 32.0 seconds...
[2025-03-28 16:09:50,364: ERROR/MainProcess] beat: Connection error: Error 111 connecting to localhost:6379. Connection refused.. Trying again in 32.0 seconds...
[2025-03-28 16:10:22,376: ERROR/MainProcess] beat: Connection error: Error 111 connecting to localhost:6379. Connection refused.. Trying again in 32.0 seconds...
[2025-03-28 16:10:54,385: ERROR/MainProcess] beat: Connection error: Error 111 connecting to localhost:6379. Connection refused.. Trying again in 32.0 seconds...
[2025-03-28 16:11:26,394: ERROR/MainProcess] beat: Connection error: Error 111 connecting to localhost:6379. Connection refused.. Trying again in 32.0 seconds...
[2025-03-28 16:11:58,402: ERROR/MainProcess] beat: Connection error: Error 111 connecting to localhost:6379. Connection refused.. Trying again in 32.0 seconds...
[2025-03-28 16:12:30,411: ERROR/MainProcess] beat: Connection error: Error 111 connecting to localhost:6379. Connection refused.. Trying again in 32.0 seconds...
[2025-03-28 16:13:02,417: ERROR/MainProcess] beat: Connection error: Error 111 connecting to localhost:6379. Connection refused.. Trying again in 32.0 seconds...
[2025-03-28 16:13:34,427: ERROR/MainProcess] beat: Connection error: Error 111 connecting to localhost:6379. Connection refused.. Trying again in 32.0 seconds...
[2025-03-28 16:14:06,453: CRITICAL/MainProcess] beat raised exception <class 'kombu.exceptions.OperationalError'>: OperationalError('Error 111 connecting to localhost:6379. Connection refused.')
Traceback (most recent call last):
  File "/home/abba/Desktop/skillsverse-backend/.venv/lib/python3.13/site-packages/kombu/transport/virtual/base.py", line 951, in create_channel
    return self._avail_channels.pop()
           ~~~~~~~~~~~~~~~~~~~~~~~~^^
IndexError: pop from empty list

During handling of the above exception, another exception occurred:

Traceback (most recent call last):
  File "/home/abba/Desktop/skillsverse-backend/.venv/lib/python3.13/site-packages/redis/connection.py", line 357, in connect
    sock = self.retry.call_with_retry(
        lambda: self._connect(), lambda error: self.disconnect(error)
    )
  File "/home/abba/Desktop/skillsverse-backend/.venv/lib/python3.13/site-packages/redis/retry.py", line 62, in call_with_retry
    return do()
  File "/home/abba/Desktop/skillsverse-backend/.venv/lib/python3.13/site-packages/redis/connection.py", line 358, in <lambda>
    lambda: self._connect(), lambda error: self.disconnect(error)
            ~~~~~~~~~~~~~^^
  File "/home/abba/Desktop/skillsverse-backend/.venv/lib/python3.13/site-packages/redis/connection.py", line 730, in _connect
    raise err
  File "/home/abba/Desktop/skillsverse-backend/.venv/lib/python3.13/site-packages/redis/connection.py", line 718, in _connect
    sock.connect(socket_address)
    ~~~~~~~~~~~~^^^^^^^^^^^^^^^^
ConnectionRefusedError: [Errno 111] Connection refused

During handling of the above exception, another exception occurred:

Traceback (most recent call last):
  File "/home/abba/Desktop/skillsverse-backend/.venv/lib/python3.13/site-packages/kombu/connection.py", line 472, in _reraise_as_library_errors
    yield
  File "/home/abba/Desktop/skillsverse-backend/.venv/lib/python3.13/site-packages/kombu/connection.py", line 459, in _ensure_connection
    return retry_over_time(
        self._connection_factory, self.recoverable_connection_errors,
    ...<2 lines>...
        callback, timeout=timeout
    )
  File "/home/abba/Desktop/skillsverse-backend/.venv/lib/python3.13/site-packages/kombu/utils/functional.py", line 318, in retry_over_time
    return fun(*args, **kwargs)
  File "/home/abba/Desktop/skillsverse-backend/.venv/lib/python3.13/site-packages/kombu/connection.py", line 934, in _connection_factory
    self._connection = self._establish_connection()
                       ~~~~~~~~~~~~~~~~~~~~~~~~~~^^
  File "/home/abba/Desktop/skillsverse-backend/.venv/lib/python3.13/site-packages/kombu/connection.py", line 860, in _establish_connection
    conn = self.transport.establish_connection()
  File "/home/abba/Desktop/skillsverse-backend/.venv/lib/python3.13/site-packages/kombu/transport/virtual/base.py", line 975, in establish_connection
    self._avail_channels.append(self.create_channel(self))
                                ~~~~~~~~~~~~~~~~~~~^^^^^^
  File "/home/abba/Desktop/skillsverse-backend/.venv/lib/python3.13/site-packages/kombu/transport/virtual/base.py", line 953, in create_channel
    channel = self.Channel(connection)
  File "/home/abba/Desktop/skillsverse-backend/.venv/lib/python3.13/site-packages/kombu/transport/redis.py", line 744, in __init__
    self.client.ping()
    ~~~~~~~~~~~~~~~~^^
  File "/home/abba/Desktop/skillsverse-backend/.venv/lib/python3.13/site-packages/redis/commands/core.py", line 1212, in ping
    return self.execute_command("PING", **kwargs)
           ~~~~~~~~~~~~~~~~~~~~^^^^^^^^^^^^^^^^^^
  File "/home/abba/Desktop/skillsverse-backend/.venv/lib/python3.13/site-packages/redis/client.py", line 559, in execute_command
    return self._execute_command(*args, **options)
           ~~~~~~~~~~~~~~~~~~~~~^^^^^^^^^^^^^^^^^^
  File "/home/abba/Desktop/skillsverse-backend/.venv/lib/python3.13/site-packages/redis/client.py", line 565, in _execute_command
    conn = self.connection or pool.get_connection(command_name, **options)
                              ~~~~~~~~~~~~~~~~~~~^^^^^^^^^^^^^^^^^^^^^^^^^
  File "/home/abba/Desktop/skillsverse-backend/.venv/lib/python3.13/site-packages/redis/connection.py", line 1422, in get_connection
    connection.connect()
    ~~~~~~~~~~~~~~~~~~^^
  File "/home/abba/Desktop/skillsverse-backend/.venv/lib/python3.13/site-packages/redis/connection.py", line 363, in connect
    raise ConnectionError(self._error_message(e))
redis.exceptions.ConnectionError: Error 111 connecting to localhost:6379. Connection refused.

The above exception was the direct cause of the following exception:

Traceback (most recent call last):
  File "/home/abba/Desktop/skillsverse-backend/.venv/lib/python3.13/site-packages/celery/apps/beat.py", line 113, in start_scheduler
    service.start()
    ~~~~~~~~~~~~~^^
  File "/home/abba/Desktop/skillsverse-backend/.venv/lib/python3.13/site-packages/celery/beat.py", line 643, in start
    interval = self.scheduler.tick()
  File "/home/abba/Desktop/skillsverse-backend/.venv/lib/python3.13/site-packages/celery/beat.py", line 353, in tick
    self.apply_entry(entry, producer=self.producer)
                                     ^^^^^^^^^^^^^
  File "/home/abba/Desktop/skillsverse-backend/.venv/lib/python3.13/site-packages/kombu/utils/objects.py", line 40, in __get__
    return super().__get__(instance, owner)
           ~~~~~~~~~~~~~~~^^^^^^^^^^^^^^^^^
  File "/usr/lib/python3.13/functools.py", line 1042, in __get__
    val = self.func(instance)
  File "/home/abba/Desktop/skillsverse-backend/.venv/lib/python3.13/site-packages/celery/beat.py", line 496, in producer
    return self.Producer(self._ensure_connected(), auto_declare=False)
                         ~~~~~~~~~~~~~~~~~~~~~~^^
  File "/home/abba/Desktop/skillsverse-backend/.venv/lib/python3.13/site-packages/celery/beat.py", line 479, in _ensure_connected
    return self.connection.ensure_connection(
           ~~~~~~~~~~~~~~~~~~~~~~~~~~~~~~~~~^
        _error_handler, self.app.conf.broker_connection_max_retries
        ^^^^^^^^^^^^^^^^^^^^^^^^^^^^^^^^^^^^^^^^^^^^^^^^^^^^^^^^^^^
    )
    ^
  File "/home/abba/Desktop/skillsverse-backend/.venv/lib/python3.13/site-packages/kombu/connection.py", line 406, in ensure_connection
    self._ensure_connection(*args, **kwargs)
    ~~~~~~~~~~~~~~~~~~~~~~~^^^^^^^^^^^^^^^^^
  File "/home/abba/Desktop/skillsverse-backend/.venv/lib/python3.13/site-packages/kombu/connection.py", line 458, in _ensure_connection
    with ctx():
         ~~~^^
  File "/usr/lib/python3.13/contextlib.py", line 162, in __exit__
    self.gen.throw(value)
    ~~~~~~~~~~~~~~^^^^^^^
  File "/home/abba/Desktop/skillsverse-backend/.venv/lib/python3.13/site-packages/kombu/connection.py", line 476, in _reraise_as_library_errors
    raise ConnectionError(str(exc)) from exc
kombu.exceptions.OperationalError: Error 111 connecting to localhost:6379. Connection refused.
[2025-03-28 16:14:06,480: WARNING/MainProcess] Traceback (most recent call last):
[2025-03-28 16:14:06,480: WARNING/MainProcess]   File "/home/abba/Desktop/skillsverse-backend/.venv/lib/python3.13/site-packages/kombu/transport/virtual/base.py", line 951, in create_channel
    return self._avail_channels.pop()
           ~~~~~~~~~~~~~~~~~~~~~~~~^^
[2025-03-28 16:14:06,480: WARNING/MainProcess] IndexError: pop from empty list
[2025-03-28 16:14:06,481: WARNING/MainProcess] 
During handling of the above exception, another exception occurred:
[2025-03-28 16:14:06,481: WARNING/MainProcess] Traceback (most recent call last):
[2025-03-28 16:14:06,482: WARNING/MainProcess]   File "/home/abba/Desktop/skillsverse-backend/.venv/lib/python3.13/site-packages/redis/connection.py", line 357, in connect
    sock = self.retry.call_with_retry(
        lambda: self._connect(), lambda error: self.disconnect(error)
    )
[2025-03-28 16:14:06,482: WARNING/MainProcess]   File "/home/abba/Desktop/skillsverse-backend/.venv/lib/python3.13/site-packages/redis/retry.py", line 62, in call_with_retry
    return do()
[2025-03-28 16:14:06,482: WARNING/MainProcess]   File "/home/abba/Desktop/skillsverse-backend/.venv/lib/python3.13/site-packages/redis/connection.py", line 358, in <lambda>
    lambda: self._connect(), lambda error: self.disconnect(error)
            ~~~~~~~~~~~~~^^
[2025-03-28 16:14:06,482: WARNING/MainProcess]   File "/home/abba/Desktop/skillsverse-backend/.venv/lib/python3.13/site-packages/redis/connection.py", line 730, in _connect
    raise err
[2025-03-28 16:14:06,482: WARNING/MainProcess]   File "/home/abba/Desktop/skillsverse-backend/.venv/lib/python3.13/site-packages/redis/connection.py", line 718, in _connect
    sock.connect(socket_address)
    ~~~~~~~~~~~~^^^^^^^^^^^^^^^^
[2025-03-28 16:14:06,482: WARNING/MainProcess] ConnectionRefusedError: [Errno 111] Connection refused
[2025-03-28 16:14:06,482: WARNING/MainProcess] 
During handling of the above exception, another exception occurred:
[2025-03-28 16:14:06,482: WARNING/MainProcess] Traceback (most recent call last):
[2025-03-28 16:14:06,484: WARNING/MainProcess]   File "/home/abba/Desktop/skillsverse-backend/.venv/lib/python3.13/site-packages/kombu/connection.py", line 472, in _reraise_as_library_errors
    yield
[2025-03-28 16:14:06,484: WARNING/MainProcess]   File "/home/abba/Desktop/skillsverse-backend/.venv/lib/python3.13/site-packages/kombu/connection.py", line 459, in _ensure_connection
    return retry_over_time(
        self._connection_factory, self.recoverable_connection_errors,
    ...<2 lines>...
        callback, timeout=timeout
    )
[2025-03-28 16:14:06,484: WARNING/MainProcess]   File "/home/abba/Desktop/skillsverse-backend/.venv/lib/python3.13/site-packages/kombu/utils/functional.py", line 318, in retry_over_time
    return fun(*args, **kwargs)
[2025-03-28 16:14:06,484: WARNING/MainProcess]   File "/home/abba/Desktop/skillsverse-backend/.venv/lib/python3.13/site-packages/kombu/connection.py", line 934, in _connection_factory
    self._connection = self._establish_connection()
                       ~~~~~~~~~~~~~~~~~~~~~~~~~~^^
[2025-03-28 16:14:06,484: WARNING/MainProcess]   File "/home/abba/Desktop/skillsverse-backend/.venv/lib/python3.13/site-packages/kombu/connection.py", line 860, in _establish_connection
    conn = self.transport.establish_connection()
[2025-03-28 16:14:06,484: WARNING/MainProcess]   File "/home/abba/Desktop/skillsverse-backend/.venv/lib/python3.13/site-packages/kombu/transport/virtual/base.py", line 975, in establish_connection
    self._avail_channels.append(self.create_channel(self))
                                ~~~~~~~~~~~~~~~~~~~^^^^^^
[2025-03-28 16:14:06,485: WARNING/MainProcess]   File "/home/abba/Desktop/skillsverse-backend/.venv/lib/python3.13/site-packages/kombu/transport/virtual/base.py", line 953, in create_channel
    channel = self.Channel(connection)
[2025-03-28 16:14:06,485: WARNING/MainProcess]   File "/home/abba/Desktop/skillsverse-backend/.venv/lib/python3.13/site-packages/kombu/transport/redis.py", line 744, in __init__
    self.client.ping()
    ~~~~~~~~~~~~~~~~^^
[2025-03-28 16:14:06,485: WARNING/MainProcess]   File "/home/abba/Desktop/skillsverse-backend/.venv/lib/python3.13/site-packages/redis/commands/core.py", line 1212, in ping
    return self.execute_command("PING", **kwargs)
           ~~~~~~~~~~~~~~~~~~~~^^^^^^^^^^^^^^^^^^
[2025-03-28 16:14:06,485: WARNING/MainProcess]   File "/home/abba/Desktop/skillsverse-backend/.venv/lib/python3.13/site-packages/redis/client.py", line 559, in execute_command
    return self._execute_command(*args, **options)
           ~~~~~~~~~~~~~~~~~~~~~^^^^^^^^^^^^^^^^^^
[2025-03-28 16:14:06,485: WARNING/MainProcess]   File "/home/abba/Desktop/skillsverse-backend/.venv/lib/python3.13/site-packages/redis/client.py", line 565, in _execute_command
    conn = self.connection or pool.get_connection(command_name, **options)
                              ~~~~~~~~~~~~~~~~~~~^^^^^^^^^^^^^^^^^^^^^^^^^
[2025-03-28 16:14:06,485: WARNING/MainProcess]   File "/home/abba/Desktop/skillsverse-backend/.venv/lib/python3.13/site-packages/redis/connection.py", line 1422, in get_connection
    connection.connect()
    ~~~~~~~~~~~~~~~~~~^^
[2025-03-28 16:14:06,485: WARNING/MainProcess]   File "/home/abba/Desktop/skillsverse-backend/.venv/lib/python3.13/site-packages/redis/connection.py", line 363, in connect
    raise ConnectionError(self._error_message(e))
[2025-03-28 16:14:06,485: WARNING/MainProcess] redis.exceptions.ConnectionError: Error 111 connecting to localhost:6379. Connection refused.
[2025-03-28 16:14:06,485: WARNING/MainProcess] 
The above exception was the direct cause of the following exception:
[2025-03-28 16:14:06,485: WARNING/MainProcess] Traceback (most recent call last):
[2025-03-28 16:14:06,488: WARNING/MainProcess]   File "/home/abba/Desktop/skillsverse-backend/.venv/bin/celery", line 8, in <module>
    sys.exit(main())
             ~~~~^^
[2025-03-28 16:14:06,488: WARNING/MainProcess]   File "/home/abba/Desktop/skillsverse-backend/.venv/lib/python3.13/site-packages/celery/__main__.py", line 15, in main
    sys.exit(_main())
             ~~~~~^^
[2025-03-28 16:14:06,488: WARNING/MainProcess]   File "/home/abba/Desktop/skillsverse-backend/.venv/lib/python3.13/site-packages/celery/bin/celery.py", line 236, in main
    return celery(auto_envvar_prefix="CELERY")
[2025-03-28 16:14:06,488: WARNING/MainProcess]   File "/home/abba/Desktop/skillsverse-backend/.venv/lib/python3.13/site-packages/click/core.py", line 1161, in __call__
    return self.main(*args, **kwargs)
           ~~~~~~~~~^^^^^^^^^^^^^^^^^
[2025-03-28 16:14:06,488: WARNING/MainProcess]   File "/home/abba/Desktop/skillsverse-backend/.venv/lib/python3.13/site-packages/click/core.py", line 1082, in main
    rv = self.invoke(ctx)
[2025-03-28 16:14:06,488: WARNING/MainProcess]   File "/home/abba/Desktop/skillsverse-backend/.venv/lib/python3.13/site-packages/click/core.py", line 1697, in invoke
    return _process_result(sub_ctx.command.invoke(sub_ctx))
                           ~~~~~~~~~~~~~~~~~~~~~~^^^^^^^^^
[2025-03-28 16:14:06,488: WARNING/MainProcess]   File "/home/abba/Desktop/skillsverse-backend/.venv/lib/python3.13/site-packages/click/core.py", line 1443, in invoke
    return ctx.invoke(self.callback, **ctx.params)
           ~~~~~~~~~~^^^^^^^^^^^^^^^^^^^^^^^^^^^^^
[2025-03-28 16:14:06,488: WARNING/MainProcess]   File "/home/abba/Desktop/skillsverse-backend/.venv/lib/python3.13/site-packages/click/core.py", line 788, in invoke
    return __callback(*args, **kwargs)
[2025-03-28 16:14:06,488: WARNING/MainProcess]   File "/home/abba/Desktop/skillsverse-backend/.venv/lib/python3.13/site-packages/click/decorators.py", line 33, in new_func
    return f(get_current_context(), *args, **kwargs)
[2025-03-28 16:14:06,488: WARNING/MainProcess]   File "/home/abba/Desktop/skillsverse-backend/.venv/lib/python3.13/site-packages/celery/bin/base.py", line 135, in caller
    return f(ctx, *args, **kwargs)
[2025-03-28 16:14:06,488: WARNING/MainProcess]   File "/home/abba/Desktop/skillsverse-backend/.venv/lib/python3.13/site-packages/celery/bin/beat.py", line 72, in beat
    return beat().run()
           ~~~~~~~~~~^^
[2025-03-28 16:14:06,488: WARNING/MainProcess]   File "/home/abba/Desktop/skillsverse-backend/.venv/lib/python3.13/site-packages/celery/apps/beat.py", line 84, in run
    self.start_scheduler()
    ~~~~~~~~~~~~~~~~~~~~^^
[2025-03-28 16:14:06,489: WARNING/MainProcess]   File "/home/abba/Desktop/skillsverse-backend/.venv/lib/python3.13/site-packages/celery/apps/beat.py", line 113, in start_scheduler
    service.start()
    ~~~~~~~~~~~~~^^
[2025-03-28 16:14:06,489: WARNING/MainProcess]   File "/home/abba/Desktop/skillsverse-backend/.venv/lib/python3.13/site-packages/celery/beat.py", line 643, in start
    interval = self.scheduler.tick()
[2025-03-28 16:14:06,489: WARNING/MainProcess]   File "/home/abba/Desktop/skillsverse-backend/.venv/lib/python3.13/site-packages/celery/beat.py", line 353, in tick
    self.apply_entry(entry, producer=self.producer)
                                     ^^^^^^^^^^^^^
[2025-03-28 16:14:06,489: WARNING/MainProcess]   File "/home/abba/Desktop/skillsverse-backend/.venv/lib/python3.13/site-packages/kombu/utils/objects.py", line 40, in __get__
    return super().__get__(instance, owner)
           ~~~~~~~~~~~~~~~^^^^^^^^^^^^^^^^^
[2025-03-28 16:14:06,489: WARNING/MainProcess]   File "/usr/lib/python3.13/functools.py", line 1042, in __get__
    val = self.func(instance)
[2025-03-28 16:14:06,489: WARNING/MainProcess]   File "/home/abba/Desktop/skillsverse-backend/.venv/lib/python3.13/site-packages/celery/beat.py", line 496, in producer
    return self.Producer(self._ensure_connected(), auto_declare=False)
                         ~~~~~~~~~~~~~~~~~~~~~~^^
[2025-03-28 16:14:06,489: WARNING/MainProcess]   File "/home/abba/Desktop/skillsverse-backend/.venv/lib/python3.13/site-packages/celery/beat.py", line 479, in _ensure_connected
    return self.connection.ensure_connection(
           ~~~~~~~~~~~~~~~~~~~~~~~~~~~~~~~~~^
        _error_handler, self.app.conf.broker_connection_max_retries
        ^^^^^^^^^^^^^^^^^^^^^^^^^^^^^^^^^^^^^^^^^^^^^^^^^^^^^^^^^^^
    )
    ^
[2025-03-28 16:14:06,489: WARNING/MainProcess]   File "/home/abba/Desktop/skillsverse-backend/.venv/lib/python3.13/site-packages/kombu/connection.py", line 406, in ensure_connection
    self._ensure_connection(*args, **kwargs)
    ~~~~~~~~~~~~~~~~~~~~~~~^^^^^^^^^^^^^^^^^
[2025-03-28 16:14:06,489: WARNING/MainProcess]   File "/home/abba/Desktop/skillsverse-backend/.venv/lib/python3.13/site-packages/kombu/connection.py", line 458, in _ensure_connection
    with ctx():
         ~~~^^
[2025-03-28 16:14:06,489: WARNING/MainProcess]   File "/usr/lib/python3.13/contextlib.py", line 162, in __exit__
    self.gen.throw(value)
    ~~~~~~~~~~~~~~^^^^^^^
[2025-03-28 16:14:06,489: WARNING/MainProcess]   File "/home/abba/Desktop/skillsverse-backend/.venv/lib/python3.13/site-packages/kombu/connection.py", line 476, in _reraise_as_library_errors
    raise ConnectionError(str(exc)) from exc
[2025-03-28 16:14:06,489: WARNING/MainProcess] kombu.exceptions.OperationalError: Error 111 connecting to localhost:6379. Connection refused.
