[2025-03-22 20:28:49,635: WARNING/MainProcess] /home/abba/Desktop/skillsverse-backend/.venv/lib/python3.13/site-packages/celery/worker/consumer/consumer.py:508: CPendingDeprecationWarning: The broker_connection_retry configuration setting will no longer determine
whether broker connection retries are made during startup in Celery 6.0 and above.
If you wish to retain the existing behavior for retrying connections on startup,
you should set broker_connection_retry_on_startup to True.
  warnings.warn(

[2025-03-22 20:28:49,642: INFO/MainProcess] Connected to redis://localhost:6379/0
[2025-03-22 20:28:49,643: WARNING/MainProcess] /home/abba/Desktop/skillsverse-backend/.venv/lib/python3.13/site-packages/celery/worker/consumer/consumer.py:508: CPendingDeprecationWarning: The broker_connection_retry configuration setting will no longer determine
whether broker connection retries are made during startup in Celery 6.0 and above.
If you wish to retain the existing behavior for retrying connections on startup,
you should set broker_connection_retry_on_startup to True.
  warnings.warn(

[2025-03-22 20:28:49,645: INFO/MainProcess] mingle: searching for neighbors
[2025-03-22 20:28:50,654: INFO/MainProcess] mingle: all alone
[2025-03-22 20:28:50,663: INFO/MainProcess] celery@abba ready.
[2025-03-22 21:00:00,047: INFO/MainProcess] Task jobs.tasks.fetch_jobs_task[37c071b1-10be-4711-b98d-ccdf45a49537] received
[2025-03-22 21:00:00,052: INFO/MainProcess] Task jobs.tasks.fetch_jobs_task[1806a4ef-5d00-42fc-83e5-8ccc131e69af] received
[2025-03-22 21:00:10,128: ERROR/ForkPoolWorker-7] Task jobs.tasks.fetch_jobs_task[37c071b1-10be-4711-b98d-ccdf45a49537] raised unexpected: OperationalError('no such table: jobs_job')
Traceback (most recent call last):
  File "/home/abba/Desktop/skillsverse-backend/.venv/lib/python3.13/site-packages/django/db/backends/utils.py", line 105, in _execute
    return self.cursor.execute(sql, params)
           ~~~~~~~~~~~~~~~~~~~^^^^^^^^^^^^^
  File "/home/abba/Desktop/skillsverse-backend/.venv/lib/python3.13/site-packages/django/db/backends/sqlite3/base.py", line 354, in execute
    return super().execute(query, params)
           ~~~~~~~~~~~~~~~^^^^^^^^^^^^^^^
sqlite3.OperationalError: no such table: jobs_job

The above exception was the direct cause of the following exception:

Traceback (most recent call last):
  File "/home/abba/Desktop/skillsverse-backend/.venv/lib/python3.13/site-packages/celery/app/trace.py", line 453, in trace_task
    R = retval = fun(*args, **kwargs)
                 ~~~^^^^^^^^^^^^^^^^^
  File "/home/abba/Desktop/skillsverse-backend/.venv/lib/python3.13/site-packages/celery/app/trace.py", line 736, in __protected_call__
    return self.run(*args, **kwargs)
           ~~~~~~~~^^^^^^^^^^^^^^^^^
  File "/home/abba/Desktop/skillsverse-backend/jobs/tasks.py", line 7, in fetch_jobs_task
    return fetch_and_store_jobs()
  File "/home/abba/Desktop/skillsverse-backend/jobs/job_fetcher.py", line 35, in fetch_and_store_jobs
    save_jobs_to_db(jobs)
    ~~~~~~~~~~~~~~~^^^^^^
  File "/home/abba/Desktop/skillsverse-backend/jobs/job_fetcher.py", line 24, in save_jobs_to_db
    if not Job.objects.filter(title=job.get("title"), company_name=job.get("company"), location=job.get("location")).exists():
           ~~~~~~~~~~~~~~~~~~~~~~~~~~~~~~~~~~~~~~~~~~~~~~~~~~~~~~~~~~~~~~~~~~~~~~~~~~~~~~~~~~~~~~~~~~~~~~~~~~~~~~~~~~~~~~~~^^
  File "/home/abba/Desktop/skillsverse-backend/.venv/lib/python3.13/site-packages/django/db/models/query.py", line 1288, in exists
    return self.query.has_results(using=self.db)
           ~~~~~~~~~~~~~~~~~~~~~~^^^^^^^^^^^^^^^
  File "/home/abba/Desktop/skillsverse-backend/.venv/lib/python3.13/site-packages/django/db/models/sql/query.py", line 660, in has_results
    return compiler.has_results()
           ~~~~~~~~~~~~~~~~~~~~^^
  File "/home/abba/Desktop/skillsverse-backend/.venv/lib/python3.13/site-packages/django/db/models/sql/compiler.py", line 1542, in has_results
    return bool(self.execute_sql(SINGLE))
                ~~~~~~~~~~~~~~~~^^^^^^^^
  File "/home/abba/Desktop/skillsverse-backend/.venv/lib/python3.13/site-packages/django/db/models/sql/compiler.py", line 1574, in execute_sql
    cursor.execute(sql, params)
    ~~~~~~~~~~~~~~^^^^^^^^^^^^^
  File "/home/abba/Desktop/skillsverse-backend/.venv/lib/python3.13/site-packages/django/db/backends/utils.py", line 122, in execute
    return super().execute(sql, params)
           ~~~~~~~~~~~~~~~^^^^^^^^^^^^^
  File "/home/abba/Desktop/skillsverse-backend/.venv/lib/python3.13/site-packages/django/db/backends/utils.py", line 79, in execute
    return self._execute_with_wrappers(
           ~~~~~~~~~~~~~~~~~~~~~~~~~~~^
        sql, params, many=False, executor=self._execute
        ^^^^^^^^^^^^^^^^^^^^^^^^^^^^^^^^^^^^^^^^^^^^^^^
    )
    ^
  File "/home/abba/Desktop/skillsverse-backend/.venv/lib/python3.13/site-packages/django/db/backends/utils.py", line 92, in _execute_with_wrappers
    return executor(sql, params, many, context)
  File "/home/abba/Desktop/skillsverse-backend/.venv/lib/python3.13/site-packages/django/db/backends/utils.py", line 100, in _execute
    with self.db.wrap_database_errors:
         ^^^^^^^^^^^^^^^^^^^^^^^^^^^^
  File "/home/abba/Desktop/skillsverse-backend/.venv/lib/python3.13/site-packages/django/db/utils.py", line 91, in __exit__
    raise dj_exc_value.with_traceback(traceback) from exc_value
  File "/home/abba/Desktop/skillsverse-backend/.venv/lib/python3.13/site-packages/django/db/backends/utils.py", line 105, in _execute
    return self.cursor.execute(sql, params)
           ~~~~~~~~~~~~~~~~~~~^^^^^^^^^^^^^
  File "/home/abba/Desktop/skillsverse-backend/.venv/lib/python3.13/site-packages/django/db/backends/sqlite3/base.py", line 354, in execute
    return super().execute(query, params)
           ~~~~~~~~~~~~~~~^^^^^^^^^^^^^^^
django.db.utils.OperationalError: no such table: jobs_job
[2025-03-22 21:00:12,291: ERROR/ForkPoolWorker-8] Task jobs.tasks.fetch_jobs_task[1806a4ef-5d00-42fc-83e5-8ccc131e69af] raised unexpected: OperationalError('no such table: jobs_job')
Traceback (most recent call last):
  File "/home/abba/Desktop/skillsverse-backend/.venv/lib/python3.13/site-packages/django/db/backends/utils.py", line 105, in _execute
    return self.cursor.execute(sql, params)
           ~~~~~~~~~~~~~~~~~~~^^^^^^^^^^^^^
  File "/home/abba/Desktop/skillsverse-backend/.venv/lib/python3.13/site-packages/django/db/backends/sqlite3/base.py", line 354, in execute
    return super().execute(query, params)
           ~~~~~~~~~~~~~~~^^^^^^^^^^^^^^^
sqlite3.OperationalError: no such table: jobs_job

The above exception was the direct cause of the following exception:

Traceback (most recent call last):
  File "/home/abba/Desktop/skillsverse-backend/.venv/lib/python3.13/site-packages/celery/app/trace.py", line 453, in trace_task
    R = retval = fun(*args, **kwargs)
                 ~~~^^^^^^^^^^^^^^^^^
  File "/home/abba/Desktop/skillsverse-backend/.venv/lib/python3.13/site-packages/celery/app/trace.py", line 736, in __protected_call__
    return self.run(*args, **kwargs)
           ~~~~~~~~^^^^^^^^^^^^^^^^^
  File "/home/abba/Desktop/skillsverse-backend/jobs/tasks.py", line 7, in fetch_jobs_task
    return fetch_and_store_jobs()
  File "/home/abba/Desktop/skillsverse-backend/jobs/job_fetcher.py", line 35, in fetch_and_store_jobs
    save_jobs_to_db(jobs)
    ~~~~~~~~~~~~~~~^^^^^^
  File "/home/abba/Desktop/skillsverse-backend/jobs/job_fetcher.py", line 24, in save_jobs_to_db
    if not Job.objects.filter(title=job.get("title"), company_name=job.get("company"), location=job.get("location")).exists():
           ~~~~~~~~~~~~~~~~~~~~~~~~~~~~~~~~~~~~~~~~~~~~~~~~~~~~~~~~~~~~~~~~~~~~~~~~~~~~~~~~~~~~~~~~~~~~~~~~~~~~~~~~~~~~~~~~^^
  File "/home/abba/Desktop/skillsverse-backend/.venv/lib/python3.13/site-packages/django/db/models/query.py", line 1288, in exists
    return self.query.has_results(using=self.db)
           ~~~~~~~~~~~~~~~~~~~~~~^^^^^^^^^^^^^^^
  File "/home/abba/Desktop/skillsverse-backend/.venv/lib/python3.13/site-packages/django/db/models/sql/query.py", line 660, in has_results
    return compiler.has_results()
           ~~~~~~~~~~~~~~~~~~~~^^
  File "/home/abba/Desktop/skillsverse-backend/.venv/lib/python3.13/site-packages/django/db/models/sql/compiler.py", line 1542, in has_results
    return bool(self.execute_sql(SINGLE))
                ~~~~~~~~~~~~~~~~^^^^^^^^
  File "/home/abba/Desktop/skillsverse-backend/.venv/lib/python3.13/site-packages/django/db/models/sql/compiler.py", line 1574, in execute_sql
    cursor.execute(sql, params)
    ~~~~~~~~~~~~~~^^^^^^^^^^^^^
  File "/home/abba/Desktop/skillsverse-backend/.venv/lib/python3.13/site-packages/django/db/backends/utils.py", line 122, in execute
    return super().execute(sql, params)
           ~~~~~~~~~~~~~~~^^^^^^^^^^^^^
  File "/home/abba/Desktop/skillsverse-backend/.venv/lib/python3.13/site-packages/django/db/backends/utils.py", line 79, in execute
    return self._execute_with_wrappers(
           ~~~~~~~~~~~~~~~~~~~~~~~~~~~^
        sql, params, many=False, executor=self._execute
        ^^^^^^^^^^^^^^^^^^^^^^^^^^^^^^^^^^^^^^^^^^^^^^^
    )
    ^
  File "/home/abba/Desktop/skillsverse-backend/.venv/lib/python3.13/site-packages/django/db/backends/utils.py", line 92, in _execute_with_wrappers
    return executor(sql, params, many, context)
  File "/home/abba/Desktop/skillsverse-backend/.venv/lib/python3.13/site-packages/django/db/backends/utils.py", line 100, in _execute
    with self.db.wrap_database_errors:
         ^^^^^^^^^^^^^^^^^^^^^^^^^^^^
  File "/home/abba/Desktop/skillsverse-backend/.venv/lib/python3.13/site-packages/django/db/utils.py", line 91, in __exit__
    raise dj_exc_value.with_traceback(traceback) from exc_value
  File "/home/abba/Desktop/skillsverse-backend/.venv/lib/python3.13/site-packages/django/db/backends/utils.py", line 105, in _execute
    return self.cursor.execute(sql, params)
           ~~~~~~~~~~~~~~~~~~~^^^^^^^^^^^^^
  File "/home/abba/Desktop/skillsverse-backend/.venv/lib/python3.13/site-packages/django/db/backends/sqlite3/base.py", line 354, in execute
    return super().execute(query, params)
           ~~~~~~~~~~~~~~~^^^^^^^^^^^^^^^
django.db.utils.OperationalError: no such table: jobs_job
[2025-03-22 21:25:38,032: INFO/MainProcess] Task jobs.tasks.fetch_jobs_task[0e8c33b6-ae35-4e4e-ba42-7c11235dddde] received
[2025-03-22 21:25:56,436: ERROR/ForkPoolWorker-7] Task jobs.tasks.fetch_jobs_task[0e8c33b6-ae35-4e4e-ba42-7c11235dddde] raised unexpected: IntegrityError('NOT NULL constraint failed: jobs_job.title')
Traceback (most recent call last):
  File "/home/abba/Desktop/skillsverse-backend/.venv/lib/python3.13/site-packages/django/db/backends/utils.py", line 105, in _execute
    return self.cursor.execute(sql, params)
           ~~~~~~~~~~~~~~~~~~~^^^^^^^^^^^^^
  File "/home/abba/Desktop/skillsverse-backend/.venv/lib/python3.13/site-packages/django/db/backends/sqlite3/base.py", line 354, in execute
    return super().execute(query, params)
           ~~~~~~~~~~~~~~~^^^^^^^^^^^^^^^
sqlite3.IntegrityError: NOT NULL constraint failed: jobs_job.title

The above exception was the direct cause of the following exception:

Traceback (most recent call last):
  File "/home/abba/Desktop/skillsverse-backend/.venv/lib/python3.13/site-packages/celery/app/trace.py", line 453, in trace_task
    R = retval = fun(*args, **kwargs)
                 ~~~^^^^^^^^^^^^^^^^^
  File "/home/abba/Desktop/skillsverse-backend/.venv/lib/python3.13/site-packages/celery/app/trace.py", line 736, in __protected_call__
    return self.run(*args, **kwargs)
           ~~~~~~~~^^^^^^^^^^^^^^^^^
  File "/home/abba/Desktop/skillsverse-backend/jobs/tasks.py", line 7, in fetch_jobs_task
    return fetch_and_store_jobs()
  File "/home/abba/Desktop/skillsverse-backend/jobs/job_fetcher.py", line 35, in fetch_and_store_jobs
    save_jobs_to_db(jobs)
    ~~~~~~~~~~~~~~~^^^^^^
  File "/home/abba/Desktop/skillsverse-backend/jobs/job_fetcher.py", line 25, in save_jobs_to_db
    Job.objects.create(
    ~~~~~~~~~~~~~~~~~~^
        title=job.get("title"),
        ^^^^^^^^^^^^^^^^^^^^^^^
    ...<3 lines>...
        external_link=job.get("url"),
        ^^^^^^^^^^^^^^^^^^^^^^^^^^^^^
    )
    ^
  File "/home/abba/Desktop/skillsverse-backend/.venv/lib/python3.13/site-packages/django/db/models/manager.py", line 87, in manager_method
    return getattr(self.get_queryset(), name)(*args, **kwargs)
           ~~~~~~~~~~~~~~~~~~~~~~~~~~~~~~~~~~^^^^^^^^^^^^^^^^^
  File "/home/abba/Desktop/skillsverse-backend/.venv/lib/python3.13/site-packages/django/db/models/query.py", line 679, in create
    obj.save(force_insert=True, using=self.db)
    ~~~~~~~~^^^^^^^^^^^^^^^^^^^^^^^^^^^^^^^^^^
  File "/home/abba/Desktop/skillsverse-backend/.venv/lib/python3.13/site-packages/django/db/models/base.py", line 892, in save
    self.save_base(
    ~~~~~~~~~~~~~~^
        using=using,
        ^^^^^^^^^^^^
    ...<2 lines>...
        update_fields=update_fields,
        ^^^^^^^^^^^^^^^^^^^^^^^^^^^^
    )
    ^
  File "/home/abba/Desktop/skillsverse-backend/.venv/lib/python3.13/site-packages/django/db/models/base.py", line 998, in save_base
    updated = self._save_table(
        raw,
    ...<4 lines>...
        update_fields,
    )
  File "/home/abba/Desktop/skillsverse-backend/.venv/lib/python3.13/site-packages/django/db/models/base.py", line 1161, in _save_table
    results = self._do_insert(
        cls._base_manager, using, fields, returning_fields, raw
    )
  File "/home/abba/Desktop/skillsverse-backend/.venv/lib/python3.13/site-packages/django/db/models/base.py", line 1202, in _do_insert
    return manager._insert(
           ~~~~~~~~~~~~~~~^
        [self],
        ^^^^^^^
    ...<3 lines>...
        raw=raw,
        ^^^^^^^^
    )
    ^
  File "/home/abba/Desktop/skillsverse-backend/.venv/lib/python3.13/site-packages/django/db/models/manager.py", line 87, in manager_method
    return getattr(self.get_queryset(), name)(*args, **kwargs)
           ~~~~~~~~~~~~~~~~~~~~~~~~~~~~~~~~~~^^^^^^^^^^^^^^^^^
  File "/home/abba/Desktop/skillsverse-backend/.venv/lib/python3.13/site-packages/django/db/models/query.py", line 1847, in _insert
    return query.get_compiler(using=using).execute_sql(returning_fields)
           ~~~~~~~~~~~~~~~~~~~~~~~~~~~~~~~~~~~~~~~~~~~^^^^^^^^^^^^^^^^^^
  File "/home/abba/Desktop/skillsverse-backend/.venv/lib/python3.13/site-packages/django/db/models/sql/compiler.py", line 1836, in execute_sql
    cursor.execute(sql, params)
    ~~~~~~~~~~~~~~^^^^^^^^^^^^^
  File "/home/abba/Desktop/skillsverse-backend/.venv/lib/python3.13/site-packages/django/db/backends/utils.py", line 122, in execute
    return super().execute(sql, params)
           ~~~~~~~~~~~~~~~^^^^^^^^^^^^^
  File "/home/abba/Desktop/skillsverse-backend/.venv/lib/python3.13/site-packages/django/db/backends/utils.py", line 79, in execute
    return self._execute_with_wrappers(
           ~~~~~~~~~~~~~~~~~~~~~~~~~~~^
        sql, params, many=False, executor=self._execute
        ^^^^^^^^^^^^^^^^^^^^^^^^^^^^^^^^^^^^^^^^^^^^^^^
    )
    ^
  File "/home/abba/Desktop/skillsverse-backend/.venv/lib/python3.13/site-packages/django/db/backends/utils.py", line 92, in _execute_with_wrappers
    return executor(sql, params, many, context)
  File "/home/abba/Desktop/skillsverse-backend/.venv/lib/python3.13/site-packages/django/db/backends/utils.py", line 100, in _execute
    with self.db.wrap_database_errors:
         ^^^^^^^^^^^^^^^^^^^^^^^^^^^^
  File "/home/abba/Desktop/skillsverse-backend/.venv/lib/python3.13/site-packages/django/db/utils.py", line 91, in __exit__
    raise dj_exc_value.with_traceback(traceback) from exc_value
  File "/home/abba/Desktop/skillsverse-backend/.venv/lib/python3.13/site-packages/django/db/backends/utils.py", line 105, in _execute
    return self.cursor.execute(sql, params)
           ~~~~~~~~~~~~~~~~~~~^^^^^^^^^^^^^
  File "/home/abba/Desktop/skillsverse-backend/.venv/lib/python3.13/site-packages/django/db/backends/sqlite3/base.py", line 354, in execute
    return super().execute(query, params)
           ~~~~~~~~~~~~~~~^^^^^^^^^^^^^^^
django.db.utils.IntegrityError: NOT NULL constraint failed: jobs_job.title
[2025-03-22 21:45:40,803: INFO/MainProcess] Task jobs.tasks.fetch_jobs_task[9cd80f53-2be8-4813-8994-6d59b1bf1a24] received
[2025-03-22 21:45:40,818: INFO/MainProcess] Task jobs.tasks.fetch_jobs_task[e09ccb7b-9348-4a37-b4ea-4a57dc73fd0c] received
[2025-03-22 21:45:44,699: ERROR/ForkPoolWorker-8] Task jobs.tasks.fetch_jobs_task[e09ccb7b-9348-4a37-b4ea-4a57dc73fd0c] raised unexpected: IntegrityError('NOT NULL constraint failed: jobs_job.title')
Traceback (most recent call last):
  File "/home/abba/Desktop/skillsverse-backend/.venv/lib/python3.13/site-packages/django/db/backends/utils.py", line 105, in _execute
    return self.cursor.execute(sql, params)
           ~~~~~~~~~~~~~~~~~~~^^^^^^^^^^^^^
  File "/home/abba/Desktop/skillsverse-backend/.venv/lib/python3.13/site-packages/django/db/backends/sqlite3/base.py", line 354, in execute
    return super().execute(query, params)
           ~~~~~~~~~~~~~~~^^^^^^^^^^^^^^^
sqlite3.IntegrityError: NOT NULL constraint failed: jobs_job.title

The above exception was the direct cause of the following exception:

Traceback (most recent call last):
  File "/home/abba/Desktop/skillsverse-backend/.venv/lib/python3.13/site-packages/celery/app/trace.py", line 453, in trace_task
    R = retval = fun(*args, **kwargs)
                 ~~~^^^^^^^^^^^^^^^^^
  File "/home/abba/Desktop/skillsverse-backend/.venv/lib/python3.13/site-packages/celery/app/trace.py", line 736, in __protected_call__
    return self.run(*args, **kwargs)
           ~~~~~~~~^^^^^^^^^^^^^^^^^
  File "/home/abba/Desktop/skillsverse-backend/jobs/tasks.py", line 7, in fetch_jobs_task
    return fetch_and_store_jobs()
  File "/home/abba/Desktop/skillsverse-backend/jobs/job_fetcher.py", line 35, in fetch_and_store_jobs
    jobs = fetch_external_jobs()
    ^^^^^^^^^^^^^^^^^^^^^
  File "/home/abba/Desktop/skillsverse-backend/jobs/job_fetcher.py", line 25, in save_jobs_to_db
    #         if not Job.objects.filter(title=job.get("title"), company_name=job.get("company"), location=job.get("location")).exists():
    ...<5 lines>...
    #                 external_link=job.get("url"),
  File "/home/abba/Desktop/skillsverse-backend/.venv/lib/python3.13/site-packages/django/db/models/manager.py", line 87, in manager_method
    return getattr(self.get_queryset(), name)(*args, **kwargs)
           ~~~~~~~~~~~~~~~~~~~~~~~~~~~~~~~~~~^^^^^^^^^^^^^^^^^
  File "/home/abba/Desktop/skillsverse-backend/.venv/lib/python3.13/site-packages/django/db/models/query.py", line 679, in create
    obj.save(force_insert=True, using=self.db)
    ~~~~~~~~^^^^^^^^^^^^^^^^^^^^^^^^^^^^^^^^^^
  File "/home/abba/Desktop/skillsverse-backend/.venv/lib/python3.13/site-packages/django/db/models/base.py", line 892, in save
    self.save_base(
    ~~~~~~~~~~~~~~^
        using=using,
        ^^^^^^^^^^^^
    ...<2 lines>...
        update_fields=update_fields,
        ^^^^^^^^^^^^^^^^^^^^^^^^^^^^
    )
    ^
  File "/home/abba/Desktop/skillsverse-backend/.venv/lib/python3.13/site-packages/django/db/models/base.py", line 998, in save_base
    updated = self._save_table(
        raw,
    ...<4 lines>...
        update_fields,
    )
  File "/home/abba/Desktop/skillsverse-backend/.venv/lib/python3.13/site-packages/django/db/models/base.py", line 1161, in _save_table
    results = self._do_insert(
        cls._base_manager, using, fields, returning_fields, raw
    )
  File "/home/abba/Desktop/skillsverse-backend/.venv/lib/python3.13/site-packages/django/db/models/base.py", line 1202, in _do_insert
    return manager._insert(
           ~~~~~~~~~~~~~~~^
        [self],
        ^^^^^^^
    ...<3 lines>...
        raw=raw,
        ^^^^^^^^
    )
    ^
  File "/home/abba/Desktop/skillsverse-backend/.venv/lib/python3.13/site-packages/django/db/models/manager.py", line 87, in manager_method
    return getattr(self.get_queryset(), name)(*args, **kwargs)
           ~~~~~~~~~~~~~~~~~~~~~~~~~~~~~~~~~~^^^^^^^^^^^^^^^^^
  File "/home/abba/Desktop/skillsverse-backend/.venv/lib/python3.13/site-packages/django/db/models/query.py", line 1847, in _insert
    return query.get_compiler(using=using).execute_sql(returning_fields)
           ~~~~~~~~~~~~~~~~~~~~~~~~~~~~~~~~~~~~~~~~~~~^^^^^^^^^^^^^^^^^^
  File "/home/abba/Desktop/skillsverse-backend/.venv/lib/python3.13/site-packages/django/db/models/sql/compiler.py", line 1836, in execute_sql
    cursor.execute(sql, params)
    ~~~~~~~~~~~~~~^^^^^^^^^^^^^
  File "/home/abba/Desktop/skillsverse-backend/.venv/lib/python3.13/site-packages/django/db/backends/utils.py", line 122, in execute
    return super().execute(sql, params)
           ~~~~~~~~~~~~~~~^^^^^^^^^^^^^
  File "/home/abba/Desktop/skillsverse-backend/.venv/lib/python3.13/site-packages/django/db/backends/utils.py", line 79, in execute
    return self._execute_with_wrappers(
           ~~~~~~~~~~~~~~~~~~~~~~~~~~~^
        sql, params, many=False, executor=self._execute
        ^^^^^^^^^^^^^^^^^^^^^^^^^^^^^^^^^^^^^^^^^^^^^^^
    )
    ^
  File "/home/abba/Desktop/skillsverse-backend/.venv/lib/python3.13/site-packages/django/db/backends/utils.py", line 92, in _execute_with_wrappers
    return executor(sql, params, many, context)
  File "/home/abba/Desktop/skillsverse-backend/.venv/lib/python3.13/site-packages/django/db/backends/utils.py", line 100, in _execute
    with self.db.wrap_database_errors:
         ^^^^^^^^^^^^^^^^^^^^^^^^^^^^
  File "/home/abba/Desktop/skillsverse-backend/.venv/lib/python3.13/site-packages/django/db/utils.py", line 91, in __exit__
    raise dj_exc_value.with_traceback(traceback) from exc_value
  File "/home/abba/Desktop/skillsverse-backend/.venv/lib/python3.13/site-packages/django/db/backends/utils.py", line 105, in _execute
    return self.cursor.execute(sql, params)
           ~~~~~~~~~~~~~~~~~~~^^^^^^^^^^^^^
  File "/home/abba/Desktop/skillsverse-backend/.venv/lib/python3.13/site-packages/django/db/backends/sqlite3/base.py", line 354, in execute
    return super().execute(query, params)
           ~~~~~~~~~~~~~~~^^^^^^^^^^^^^^^
django.db.utils.IntegrityError: NOT NULL constraint failed: jobs_job.title
[2025-03-22 21:45:46,457: ERROR/ForkPoolWorker-7] Task jobs.tasks.fetch_jobs_task[9cd80f53-2be8-4813-8994-6d59b1bf1a24] raised unexpected: IntegrityError('NOT NULL constraint failed: jobs_job.title')
Traceback (most recent call last):
  File "/home/abba/Desktop/skillsverse-backend/.venv/lib/python3.13/site-packages/django/db/backends/utils.py", line 105, in _execute
    return self.cursor.execute(sql, params)
           ~~~~~~~~~~~~~~~~~~~^^^^^^^^^^^^^
  File "/home/abba/Desktop/skillsverse-backend/.venv/lib/python3.13/site-packages/django/db/backends/sqlite3/base.py", line 354, in execute
    return super().execute(query, params)
           ~~~~~~~~~~~~~~~^^^^^^^^^^^^^^^
sqlite3.IntegrityError: NOT NULL constraint failed: jobs_job.title

The above exception was the direct cause of the following exception:

Traceback (most recent call last):
  File "/home/abba/Desktop/skillsverse-backend/.venv/lib/python3.13/site-packages/celery/app/trace.py", line 453, in trace_task
    R = retval = fun(*args, **kwargs)
                 ~~~^^^^^^^^^^^^^^^^^
  File "/home/abba/Desktop/skillsverse-backend/.venv/lib/python3.13/site-packages/celery/app/trace.py", line 736, in __protected_call__
    return self.run(*args, **kwargs)
           ~~~~~~~~^^^^^^^^^^^^^^^^^
  File "/home/abba/Desktop/skillsverse-backend/jobs/tasks.py", line 7, in fetch_jobs_task
    return fetch_and_store_jobs()
  File "/home/abba/Desktop/skillsverse-backend/jobs/job_fetcher.py", line 35, in fetch_and_store_jobs
    jobs = fetch_external_jobs()
    ^^^^^^^^^^^^^^^^^^^^^
  File "/home/abba/Desktop/skillsverse-backend/jobs/job_fetcher.py", line 25, in save_jobs_to_db
    #         if not Job.objects.filter(title=job.get("title"), company_name=job.get("company"), location=job.get("location")).exists():
    ...<5 lines>...
    #                 external_link=job.get("url"),
  File "/home/abba/Desktop/skillsverse-backend/.venv/lib/python3.13/site-packages/django/db/models/manager.py", line 87, in manager_method
    return getattr(self.get_queryset(), name)(*args, **kwargs)
           ~~~~~~~~~~~~~~~~~~~~~~~~~~~~~~~~~~^^^^^^^^^^^^^^^^^
  File "/home/abba/Desktop/skillsverse-backend/.venv/lib/python3.13/site-packages/django/db/models/query.py", line 679, in create
    obj.save(force_insert=True, using=self.db)
    ~~~~~~~~^^^^^^^^^^^^^^^^^^^^^^^^^^^^^^^^^^
  File "/home/abba/Desktop/skillsverse-backend/.venv/lib/python3.13/site-packages/django/db/models/base.py", line 892, in save
    self.save_base(
    ~~~~~~~~~~~~~~^
        using=using,
        ^^^^^^^^^^^^
    ...<2 lines>...
        update_fields=update_fields,
        ^^^^^^^^^^^^^^^^^^^^^^^^^^^^
    )
    ^
  File "/home/abba/Desktop/skillsverse-backend/.venv/lib/python3.13/site-packages/django/db/models/base.py", line 998, in save_base
    updated = self._save_table(
        raw,
    ...<4 lines>...
        update_fields,
    )
  File "/home/abba/Desktop/skillsverse-backend/.venv/lib/python3.13/site-packages/django/db/models/base.py", line 1161, in _save_table
    results = self._do_insert(
        cls._base_manager, using, fields, returning_fields, raw
    )
  File "/home/abba/Desktop/skillsverse-backend/.venv/lib/python3.13/site-packages/django/db/models/base.py", line 1202, in _do_insert
    return manager._insert(
           ~~~~~~~~~~~~~~~^
        [self],
        ^^^^^^^
    ...<3 lines>...
        raw=raw,
        ^^^^^^^^
    )
    ^
  File "/home/abba/Desktop/skillsverse-backend/.venv/lib/python3.13/site-packages/django/db/models/manager.py", line 87, in manager_method
    return getattr(self.get_queryset(), name)(*args, **kwargs)
           ~~~~~~~~~~~~~~~~~~~~~~~~~~~~~~~~~~^^^^^^^^^^^^^^^^^
  File "/home/abba/Desktop/skillsverse-backend/.venv/lib/python3.13/site-packages/django/db/models/query.py", line 1847, in _insert
    return query.get_compiler(using=using).execute_sql(returning_fields)
           ~~~~~~~~~~~~~~~~~~~~~~~~~~~~~~~~~~~~~~~~~~~^^^^^^^^^^^^^^^^^^
  File "/home/abba/Desktop/skillsverse-backend/.venv/lib/python3.13/site-packages/django/db/models/sql/compiler.py", line 1836, in execute_sql
    cursor.execute(sql, params)
    ~~~~~~~~~~~~~~^^^^^^^^^^^^^
  File "/home/abba/Desktop/skillsverse-backend/.venv/lib/python3.13/site-packages/django/db/backends/utils.py", line 122, in execute
    return super().execute(sql, params)
           ~~~~~~~~~~~~~~~^^^^^^^^^^^^^
  File "/home/abba/Desktop/skillsverse-backend/.venv/lib/python3.13/site-packages/django/db/backends/utils.py", line 79, in execute
    return self._execute_with_wrappers(
           ~~~~~~~~~~~~~~~~~~~~~~~~~~~^
        sql, params, many=False, executor=self._execute
        ^^^^^^^^^^^^^^^^^^^^^^^^^^^^^^^^^^^^^^^^^^^^^^^
    )
    ^
  File "/home/abba/Desktop/skillsverse-backend/.venv/lib/python3.13/site-packages/django/db/backends/utils.py", line 92, in _execute_with_wrappers
    return executor(sql, params, many, context)
  File "/home/abba/Desktop/skillsverse-backend/.venv/lib/python3.13/site-packages/django/db/backends/utils.py", line 100, in _execute
    with self.db.wrap_database_errors:
         ^^^^^^^^^^^^^^^^^^^^^^^^^^^^
  File "/home/abba/Desktop/skillsverse-backend/.venv/lib/python3.13/site-packages/django/db/utils.py", line 91, in __exit__
    raise dj_exc_value.with_traceback(traceback) from exc_value
  File "/home/abba/Desktop/skillsverse-backend/.venv/lib/python3.13/site-packages/django/db/backends/utils.py", line 105, in _execute
    return self.cursor.execute(sql, params)
           ~~~~~~~~~~~~~~~~~~~^^^^^^^^^^^^^
  File "/home/abba/Desktop/skillsverse-backend/.venv/lib/python3.13/site-packages/django/db/backends/sqlite3/base.py", line 354, in execute
    return super().execute(query, params)
           ~~~~~~~~~~~~~~~^^^^^^^^^^^^^^^
django.db.utils.IntegrityError: NOT NULL constraint failed: jobs_job.title
[2025-03-22 22:00:00,006: INFO/MainProcess] Task jobs.tasks.fetch_jobs_task[cd0e62e6-e272-4b0f-ad1a-d33f8d0f7312] received
[2025-03-22 22:00:00,009: INFO/MainProcess] Task jobs.tasks.fetch_jobs_task[435ec5e0-0e29-411f-a38f-7394fdc47e23] received
[2025-03-22 22:00:13,561: ERROR/ForkPoolWorker-7] Task jobs.tasks.fetch_jobs_task[cd0e62e6-e272-4b0f-ad1a-d33f8d0f7312] raised unexpected: OperationalError('table jobs_job has no column named salary')
Traceback (most recent call last):
  File "/home/abba/Desktop/skillsverse-backend/.venv/lib/python3.13/site-packages/django/db/backends/utils.py", line 105, in _execute
    return self.cursor.execute(sql, params)
           ~~~~~~~~~~~~~~~~~~~^^^^^^^^^^^^^
  File "/home/abba/Desktop/skillsverse-backend/.venv/lib/python3.13/site-packages/django/db/backends/sqlite3/base.py", line 354, in execute
    return super().execute(query, params)
           ~~~~~~~~~~~~~~~^^^^^^^^^^^^^^^
sqlite3.OperationalError: table jobs_job has no column named salary

The above exception was the direct cause of the following exception:

Traceback (most recent call last):
  File "/home/abba/Desktop/skillsverse-backend/.venv/lib/python3.13/site-packages/celery/app/trace.py", line 453, in trace_task
    R = retval = fun(*args, **kwargs)
                 ~~~^^^^^^^^^^^^^^^^^
  File "/home/abba/Desktop/skillsverse-backend/.venv/lib/python3.13/site-packages/celery/app/trace.py", line 736, in __protected_call__
    return self.run(*args, **kwargs)
           ~~~~~~~~^^^^^^^^^^^^^^^^^
  File "/home/abba/Desktop/skillsverse-backend/jobs/tasks.py", line 7, in fetch_jobs_task
    return fetch_and_store_jobs()
  File "/home/abba/Desktop/skillsverse-backend/jobs/job_fetcher.py", line 35, in fetch_and_store_jobs
    """Generate a unique slug from the job title."""
    ^^^^^^^^^^^^^^^^^^^^^
  File "/home/abba/Desktop/skillsverse-backend/jobs/job_fetcher.py", line 25, in save_jobs_to_db
            elif isinstance(data, dict):
            ^^^^^^^^^^^^^^^^^^^^^^^^^^^^
    ...<5 lines>...
    return jobs
    ^^^^^^^^^
  File "/home/abba/Desktop/skillsverse-backend/.venv/lib/python3.13/site-packages/django/db/models/manager.py", line 87, in manager_method
    return getattr(self.get_queryset(), name)(*args, **kwargs)
           ~~~~~~~~~~~~~~~~~~~~~~~~~~~~~~~~~~^^^^^^^^^^^^^^^^^
  File "/home/abba/Desktop/skillsverse-backend/.venv/lib/python3.13/site-packages/django/db/models/query.py", line 679, in create
    obj.save(force_insert=True, using=self.db)
    ~~~~~~~~^^^^^^^^^^^^^^^^^^^^^^^^^^^^^^^^^^
  File "/home/abba/Desktop/skillsverse-backend/.venv/lib/python3.13/site-packages/django/db/models/base.py", line 892, in save
    self.save_base(
    ~~~~~~~~~~~~~~^
        using=using,
        ^^^^^^^^^^^^
    ...<2 lines>...
        update_fields=update_fields,
        ^^^^^^^^^^^^^^^^^^^^^^^^^^^^
    )
    ^
  File "/home/abba/Desktop/skillsverse-backend/.venv/lib/python3.13/site-packages/django/db/models/base.py", line 998, in save_base
    updated = self._save_table(
        raw,
    ...<4 lines>...
        update_fields,
    )
  File "/home/abba/Desktop/skillsverse-backend/.venv/lib/python3.13/site-packages/django/db/models/base.py", line 1161, in _save_table
    results = self._do_insert(
        cls._base_manager, using, fields, returning_fields, raw
    )
  File "/home/abba/Desktop/skillsverse-backend/.venv/lib/python3.13/site-packages/django/db/models/base.py", line 1202, in _do_insert
    return manager._insert(
           ~~~~~~~~~~~~~~~^
        [self],
        ^^^^^^^
    ...<3 lines>...
        raw=raw,
        ^^^^^^^^
    )
    ^
  File "/home/abba/Desktop/skillsverse-backend/.venv/lib/python3.13/site-packages/django/db/models/manager.py", line 87, in manager_method
    return getattr(self.get_queryset(), name)(*args, **kwargs)
           ~~~~~~~~~~~~~~~~~~~~~~~~~~~~~~~~~~^^^^^^^^^^^^^^^^^
  File "/home/abba/Desktop/skillsverse-backend/.venv/lib/python3.13/site-packages/django/db/models/query.py", line 1847, in _insert
    return query.get_compiler(using=using).execute_sql(returning_fields)
           ~~~~~~~~~~~~~~~~~~~~~~~~~~~~~~~~~~~~~~~~~~~^^^^^^^^^^^^^^^^^^
  File "/home/abba/Desktop/skillsverse-backend/.venv/lib/python3.13/site-packages/django/db/models/sql/compiler.py", line 1836, in execute_sql
    cursor.execute(sql, params)
    ~~~~~~~~~~~~~~^^^^^^^^^^^^^
  File "/home/abba/Desktop/skillsverse-backend/.venv/lib/python3.13/site-packages/django/db/backends/utils.py", line 122, in execute
    return super().execute(sql, params)
           ~~~~~~~~~~~~~~~^^^^^^^^^^^^^
  File "/home/abba/Desktop/skillsverse-backend/.venv/lib/python3.13/site-packages/django/db/backends/utils.py", line 79, in execute
    return self._execute_with_wrappers(
           ~~~~~~~~~~~~~~~~~~~~~~~~~~~^
        sql, params, many=False, executor=self._execute
        ^^^^^^^^^^^^^^^^^^^^^^^^^^^^^^^^^^^^^^^^^^^^^^^
    )
    ^
  File "/home/abba/Desktop/skillsverse-backend/.venv/lib/python3.13/site-packages/django/db/backends/utils.py", line 92, in _execute_with_wrappers
    return executor(sql, params, many, context)
  File "/home/abba/Desktop/skillsverse-backend/.venv/lib/python3.13/site-packages/django/db/backends/utils.py", line 100, in _execute
    with self.db.wrap_database_errors:
         ^^^^^^^^^^^^^^^^^^^^^^^^^^^^
  File "/home/abba/Desktop/skillsverse-backend/.venv/lib/python3.13/site-packages/django/db/utils.py", line 91, in __exit__
    raise dj_exc_value.with_traceback(traceback) from exc_value
  File "/home/abba/Desktop/skillsverse-backend/.venv/lib/python3.13/site-packages/django/db/backends/utils.py", line 105, in _execute
    return self.cursor.execute(sql, params)
           ~~~~~~~~~~~~~~~~~~~^^^^^^^^^^^^^
  File "/home/abba/Desktop/skillsverse-backend/.venv/lib/python3.13/site-packages/django/db/backends/sqlite3/base.py", line 354, in execute
    return super().execute(query, params)
           ~~~~~~~~~~~~~~~^^^^^^^^^^^^^^^
django.db.utils.OperationalError: table jobs_job has no column named salary
[2025-03-22 22:00:13,658: ERROR/ForkPoolWorker-8] Task jobs.tasks.fetch_jobs_task[435ec5e0-0e29-411f-a38f-7394fdc47e23] raised unexpected: OperationalError('table jobs_job has no column named salary')
Traceback (most recent call last):
  File "/home/abba/Desktop/skillsverse-backend/.venv/lib/python3.13/site-packages/django/db/backends/utils.py", line 105, in _execute
    return self.cursor.execute(sql, params)
           ~~~~~~~~~~~~~~~~~~~^^^^^^^^^^^^^
  File "/home/abba/Desktop/skillsverse-backend/.venv/lib/python3.13/site-packages/django/db/backends/sqlite3/base.py", line 354, in execute
    return super().execute(query, params)
           ~~~~~~~~~~~~~~~^^^^^^^^^^^^^^^
sqlite3.OperationalError: table jobs_job has no column named salary

The above exception was the direct cause of the following exception:

Traceback (most recent call last):
  File "/home/abba/Desktop/skillsverse-backend/.venv/lib/python3.13/site-packages/celery/app/trace.py", line 453, in trace_task
    R = retval = fun(*args, **kwargs)
                 ~~~^^^^^^^^^^^^^^^^^
  File "/home/abba/Desktop/skillsverse-backend/.venv/lib/python3.13/site-packages/celery/app/trace.py", line 736, in __protected_call__
    return self.run(*args, **kwargs)
           ~~~~~~~~^^^^^^^^^^^^^^^^^
  File "/home/abba/Desktop/skillsverse-backend/jobs/tasks.py", line 7, in fetch_jobs_task
    return fetch_and_store_jobs()
  File "/home/abba/Desktop/skillsverse-backend/jobs/job_fetcher.py", line 35, in fetch_and_store_jobs
    """Generate a unique slug from the job title."""
    ^^^^^^^^^^^^^^^^^^^^^
  File "/home/abba/Desktop/skillsverse-backend/jobs/job_fetcher.py", line 25, in save_jobs_to_db
            elif isinstance(data, dict):
            ^^^^^^^^^^^^^^^^^^^^^^^^^^^^
    ...<5 lines>...
    return jobs
    ^^^^^^^^^
  File "/home/abba/Desktop/skillsverse-backend/.venv/lib/python3.13/site-packages/django/db/models/manager.py", line 87, in manager_method
    return getattr(self.get_queryset(), name)(*args, **kwargs)
           ~~~~~~~~~~~~~~~~~~~~~~~~~~~~~~~~~~^^^^^^^^^^^^^^^^^
  File "/home/abba/Desktop/skillsverse-backend/.venv/lib/python3.13/site-packages/django/db/models/query.py", line 679, in create
    obj.save(force_insert=True, using=self.db)
    ~~~~~~~~^^^^^^^^^^^^^^^^^^^^^^^^^^^^^^^^^^
  File "/home/abba/Desktop/skillsverse-backend/.venv/lib/python3.13/site-packages/django/db/models/base.py", line 892, in save
    self.save_base(
    ~~~~~~~~~~~~~~^
        using=using,
        ^^^^^^^^^^^^
    ...<2 lines>...
        update_fields=update_fields,
        ^^^^^^^^^^^^^^^^^^^^^^^^^^^^
    )
    ^
  File "/home/abba/Desktop/skillsverse-backend/.venv/lib/python3.13/site-packages/django/db/models/base.py", line 998, in save_base
    updated = self._save_table(
        raw,
    ...<4 lines>...
        update_fields,
    )
  File "/home/abba/Desktop/skillsverse-backend/.venv/lib/python3.13/site-packages/django/db/models/base.py", line 1161, in _save_table
    results = self._do_insert(
        cls._base_manager, using, fields, returning_fields, raw
    )
  File "/home/abba/Desktop/skillsverse-backend/.venv/lib/python3.13/site-packages/django/db/models/base.py", line 1202, in _do_insert
    return manager._insert(
           ~~~~~~~~~~~~~~~^
        [self],
        ^^^^^^^
    ...<3 lines>...
        raw=raw,
        ^^^^^^^^
    )
    ^
  File "/home/abba/Desktop/skillsverse-backend/.venv/lib/python3.13/site-packages/django/db/models/manager.py", line 87, in manager_method
    return getattr(self.get_queryset(), name)(*args, **kwargs)
           ~~~~~~~~~~~~~~~~~~~~~~~~~~~~~~~~~~^^^^^^^^^^^^^^^^^
  File "/home/abba/Desktop/skillsverse-backend/.venv/lib/python3.13/site-packages/django/db/models/query.py", line 1847, in _insert
    return query.get_compiler(using=using).execute_sql(returning_fields)
           ~~~~~~~~~~~~~~~~~~~~~~~~~~~~~~~~~~~~~~~~~~~^^^^^^^^^^^^^^^^^^
  File "/home/abba/Desktop/skillsverse-backend/.venv/lib/python3.13/site-packages/django/db/models/sql/compiler.py", line 1836, in execute_sql
    cursor.execute(sql, params)
    ~~~~~~~~~~~~~~^^^^^^^^^^^^^
  File "/home/abba/Desktop/skillsverse-backend/.venv/lib/python3.13/site-packages/django/db/backends/utils.py", line 122, in execute
    return super().execute(sql, params)
           ~~~~~~~~~~~~~~~^^^^^^^^^^^^^
  File "/home/abba/Desktop/skillsverse-backend/.venv/lib/python3.13/site-packages/django/db/backends/utils.py", line 79, in execute
    return self._execute_with_wrappers(
           ~~~~~~~~~~~~~~~~~~~~~~~~~~~^
        sql, params, many=False, executor=self._execute
        ^^^^^^^^^^^^^^^^^^^^^^^^^^^^^^^^^^^^^^^^^^^^^^^
    )
    ^
  File "/home/abba/Desktop/skillsverse-backend/.venv/lib/python3.13/site-packages/django/db/backends/utils.py", line 92, in _execute_with_wrappers
    return executor(sql, params, many, context)
  File "/home/abba/Desktop/skillsverse-backend/.venv/lib/python3.13/site-packages/django/db/backends/utils.py", line 100, in _execute
    with self.db.wrap_database_errors:
         ^^^^^^^^^^^^^^^^^^^^^^^^^^^^
  File "/home/abba/Desktop/skillsverse-backend/.venv/lib/python3.13/site-packages/django/db/utils.py", line 91, in __exit__
    raise dj_exc_value.with_traceback(traceback) from exc_value
  File "/home/abba/Desktop/skillsverse-backend/.venv/lib/python3.13/site-packages/django/db/backends/utils.py", line 105, in _execute
    return self.cursor.execute(sql, params)
           ~~~~~~~~~~~~~~~~~~~^^^^^^^^^^^^^
  File "/home/abba/Desktop/skillsverse-backend/.venv/lib/python3.13/site-packages/django/db/backends/sqlite3/base.py", line 354, in execute
    return super().execute(query, params)
           ~~~~~~~~~~~~~~~^^^^^^^^^^^^^^^
django.db.utils.OperationalError: table jobs_job has no column named salary
[2025-03-22 22:15:40,807: INFO/MainProcess] Task jobs.tasks.fetch_jobs_task[46eab520-fbd3-42c9-9629-04c0d94cccd6] received
[2025-03-22 22:15:40,817: INFO/MainProcess] Task jobs.tasks.fetch_jobs_task[f2a3e036-386a-483e-9629-eb7701a33cc0] received
[2025-03-22 22:15:45,942: ERROR/ForkPoolWorker-8] Task jobs.tasks.fetch_jobs_task[f2a3e036-386a-483e-9629-eb7701a33cc0] raised unexpected: OperationalError('table jobs_job has no column named salary')
Traceback (most recent call last):
  File "/home/abba/Desktop/skillsverse-backend/.venv/lib/python3.13/site-packages/django/db/backends/utils.py", line 105, in _execute
    return self.cursor.execute(sql, params)
           ~~~~~~~~~~~~~~~~~~~^^^^^^^^^^^^^
  File "/home/abba/Desktop/skillsverse-backend/.venv/lib/python3.13/site-packages/django/db/backends/sqlite3/base.py", line 354, in execute
    return super().execute(query, params)
           ~~~~~~~~~~~~~~~^^^^^^^^^^^^^^^
sqlite3.OperationalError: table jobs_job has no column named salary

The above exception was the direct cause of the following exception:

Traceback (most recent call last):
  File "/home/abba/Desktop/skillsverse-backend/.venv/lib/python3.13/site-packages/celery/app/trace.py", line 453, in trace_task
    R = retval = fun(*args, **kwargs)
                 ~~~^^^^^^^^^^^^^^^^^
  File "/home/abba/Desktop/skillsverse-backend/.venv/lib/python3.13/site-packages/celery/app/trace.py", line 736, in __protected_call__
    return self.run(*args, **kwargs)
           ~~~~~~~~^^^^^^^^^^^^^^^^^
  File "/home/abba/Desktop/skillsverse-backend/jobs/tasks.py", line 7, in fetch_jobs_task
    return fetch_and_store_jobs()
  File "/home/abba/Desktop/skillsverse-backend/jobs/job_fetcher.py", line 35, in fetch_and_store_jobs
    jobs.extend(data.get("jobs", []))  # Adjust if necessary
    ^^^^^^^^^
  File "/home/abba/Desktop/skillsverse-backend/jobs/job_fetcher.py", line 25, in save_jobs_to_db
    try:
    
    ...<5 lines>...
        # Some APIs might return wrapped data, unwrap if needed
        ^
  File "/home/abba/Desktop/skillsverse-backend/.venv/lib/python3.13/site-packages/django/db/models/manager.py", line 87, in manager_method
    return getattr(self.get_queryset(), name)(*args, **kwargs)
           ~~~~~~~~~~~~~~~~~~~~~~~~~~~~~~~~~~^^^^^^^^^^^^^^^^^
  File "/home/abba/Desktop/skillsverse-backend/.venv/lib/python3.13/site-packages/django/db/models/query.py", line 679, in create
    obj.save(force_insert=True, using=self.db)
    ~~~~~~~~^^^^^^^^^^^^^^^^^^^^^^^^^^^^^^^^^^
  File "/home/abba/Desktop/skillsverse-backend/.venv/lib/python3.13/site-packages/django/db/models/base.py", line 892, in save
    self.save_base(
    ~~~~~~~~~~~~~~^
        using=using,
        ^^^^^^^^^^^^
    ...<2 lines>...
        update_fields=update_fields,
        ^^^^^^^^^^^^^^^^^^^^^^^^^^^^
    )
    ^
  File "/home/abba/Desktop/skillsverse-backend/.venv/lib/python3.13/site-packages/django/db/models/base.py", line 998, in save_base
    updated = self._save_table(
        raw,
    ...<4 lines>...
        update_fields,
    )
  File "/home/abba/Desktop/skillsverse-backend/.venv/lib/python3.13/site-packages/django/db/models/base.py", line 1161, in _save_table
    results = self._do_insert(
        cls._base_manager, using, fields, returning_fields, raw
    )
  File "/home/abba/Desktop/skillsverse-backend/.venv/lib/python3.13/site-packages/django/db/models/base.py", line 1202, in _do_insert
    return manager._insert(
           ~~~~~~~~~~~~~~~^
        [self],
        ^^^^^^^
    ...<3 lines>...
        raw=raw,
        ^^^^^^^^
    )
    ^
  File "/home/abba/Desktop/skillsverse-backend/.venv/lib/python3.13/site-packages/django/db/models/manager.py", line 87, in manager_method
    return getattr(self.get_queryset(), name)(*args, **kwargs)
           ~~~~~~~~~~~~~~~~~~~~~~~~~~~~~~~~~~^^^^^^^^^^^^^^^^^
  File "/home/abba/Desktop/skillsverse-backend/.venv/lib/python3.13/site-packages/django/db/models/query.py", line 1847, in _insert
    return query.get_compiler(using=using).execute_sql(returning_fields)
           ~~~~~~~~~~~~~~~~~~~~~~~~~~~~~~~~~~~~~~~~~~~^^^^^^^^^^^^^^^^^^
  File "/home/abba/Desktop/skillsverse-backend/.venv/lib/python3.13/site-packages/django/db/models/sql/compiler.py", line 1836, in execute_sql
    cursor.execute(sql, params)
    ~~~~~~~~~~~~~~^^^^^^^^^^^^^
  File "/home/abba/Desktop/skillsverse-backend/.venv/lib/python3.13/site-packages/django/db/backends/utils.py", line 122, in execute
    return super().execute(sql, params)
           ~~~~~~~~~~~~~~~^^^^^^^^^^^^^
  File "/home/abba/Desktop/skillsverse-backend/.venv/lib/python3.13/site-packages/django/db/backends/utils.py", line 79, in execute
    return self._execute_with_wrappers(
           ~~~~~~~~~~~~~~~~~~~~~~~~~~~^
        sql, params, many=False, executor=self._execute
        ^^^^^^^^^^^^^^^^^^^^^^^^^^^^^^^^^^^^^^^^^^^^^^^
    )
    ^
  File "/home/abba/Desktop/skillsverse-backend/.venv/lib/python3.13/site-packages/django/db/backends/utils.py", line 92, in _execute_with_wrappers
    return executor(sql, params, many, context)
  File "/home/abba/Desktop/skillsverse-backend/.venv/lib/python3.13/site-packages/django/db/backends/utils.py", line 100, in _execute
    with self.db.wrap_database_errors:
         ^^^^^^^^^^^^^^^^^^^^^^^^^^^^
  File "/home/abba/Desktop/skillsverse-backend/.venv/lib/python3.13/site-packages/django/db/utils.py", line 91, in __exit__
    raise dj_exc_value.with_traceback(traceback) from exc_value
  File "/home/abba/Desktop/skillsverse-backend/.venv/lib/python3.13/site-packages/django/db/backends/utils.py", line 105, in _execute
    return self.cursor.execute(sql, params)
           ~~~~~~~~~~~~~~~~~~~^^^^^^^^^^^^^
  File "/home/abba/Desktop/skillsverse-backend/.venv/lib/python3.13/site-packages/django/db/backends/sqlite3/base.py", line 354, in execute
    return super().execute(query, params)
           ~~~~~~~~~~~~~~~^^^^^^^^^^^^^^^
django.db.utils.OperationalError: table jobs_job has no column named salary
[2025-03-22 22:15:45,992: ERROR/ForkPoolWorker-7] Task jobs.tasks.fetch_jobs_task[46eab520-fbd3-42c9-9629-04c0d94cccd6] raised unexpected: OperationalError('table jobs_job has no column named salary')
Traceback (most recent call last):
  File "/home/abba/Desktop/skillsverse-backend/.venv/lib/python3.13/site-packages/django/db/backends/utils.py", line 105, in _execute
    return self.cursor.execute(sql, params)
           ~~~~~~~~~~~~~~~~~~~^^^^^^^^^^^^^
  File "/home/abba/Desktop/skillsverse-backend/.venv/lib/python3.13/site-packages/django/db/backends/sqlite3/base.py", line 354, in execute
    return super().execute(query, params)
           ~~~~~~~~~~~~~~~^^^^^^^^^^^^^^^
sqlite3.OperationalError: table jobs_job has no column named salary

The above exception was the direct cause of the following exception:

Traceback (most recent call last):
  File "/home/abba/Desktop/skillsverse-backend/.venv/lib/python3.13/site-packages/celery/app/trace.py", line 453, in trace_task
    R = retval = fun(*args, **kwargs)
                 ~~~^^^^^^^^^^^^^^^^^
  File "/home/abba/Desktop/skillsverse-backend/.venv/lib/python3.13/site-packages/celery/app/trace.py", line 736, in __protected_call__
    return self.run(*args, **kwargs)
           ~~~~~~~~^^^^^^^^^^^^^^^^^
  File "/home/abba/Desktop/skillsverse-backend/jobs/tasks.py", line 7, in fetch_jobs_task
    return fetch_and_store_jobs()
  File "/home/abba/Desktop/skillsverse-backend/jobs/job_fetcher.py", line 35, in fetch_and_store_jobs
    jobs.extend(data.get("jobs", []))  # Adjust if necessary
    ^^^^^^^^^
  File "/home/abba/Desktop/skillsverse-backend/jobs/job_fetcher.py", line 25, in save_jobs_to_db
    try:
    
    ...<5 lines>...
        # Some APIs might return wrapped data, unwrap if needed
        ^
  File "/home/abba/Desktop/skillsverse-backend/.venv/lib/python3.13/site-packages/django/db/models/manager.py", line 87, in manager_method
    return getattr(self.get_queryset(), name)(*args, **kwargs)
           ~~~~~~~~~~~~~~~~~~~~~~~~~~~~~~~~~~^^^^^^^^^^^^^^^^^
  File "/home/abba/Desktop/skillsverse-backend/.venv/lib/python3.13/site-packages/django/db/models/query.py", line 679, in create
    obj.save(force_insert=True, using=self.db)
    ~~~~~~~~^^^^^^^^^^^^^^^^^^^^^^^^^^^^^^^^^^
  File "/home/abba/Desktop/skillsverse-backend/.venv/lib/python3.13/site-packages/django/db/models/base.py", line 892, in save
    self.save_base(
    ~~~~~~~~~~~~~~^
        using=using,
        ^^^^^^^^^^^^
    ...<2 lines>...
        update_fields=update_fields,
        ^^^^^^^^^^^^^^^^^^^^^^^^^^^^
    )
    ^
  File "/home/abba/Desktop/skillsverse-backend/.venv/lib/python3.13/site-packages/django/db/models/base.py", line 998, in save_base
    updated = self._save_table(
        raw,
    ...<4 lines>...
        update_fields,
    )
  File "/home/abba/Desktop/skillsverse-backend/.venv/lib/python3.13/site-packages/django/db/models/base.py", line 1161, in _save_table
    results = self._do_insert(
        cls._base_manager, using, fields, returning_fields, raw
    )
  File "/home/abba/Desktop/skillsverse-backend/.venv/lib/python3.13/site-packages/django/db/models/base.py", line 1202, in _do_insert
    return manager._insert(
           ~~~~~~~~~~~~~~~^
        [self],
        ^^^^^^^
    ...<3 lines>...
        raw=raw,
        ^^^^^^^^
    )
    ^
  File "/home/abba/Desktop/skillsverse-backend/.venv/lib/python3.13/site-packages/django/db/models/manager.py", line 87, in manager_method
    return getattr(self.get_queryset(), name)(*args, **kwargs)
           ~~~~~~~~~~~~~~~~~~~~~~~~~~~~~~~~~~^^^^^^^^^^^^^^^^^
  File "/home/abba/Desktop/skillsverse-backend/.venv/lib/python3.13/site-packages/django/db/models/query.py", line 1847, in _insert
    return query.get_compiler(using=using).execute_sql(returning_fields)
           ~~~~~~~~~~~~~~~~~~~~~~~~~~~~~~~~~~~~~~~~~~~^^^^^^^^^^^^^^^^^^
  File "/home/abba/Desktop/skillsverse-backend/.venv/lib/python3.13/site-packages/django/db/models/sql/compiler.py", line 1836, in execute_sql
    cursor.execute(sql, params)
    ~~~~~~~~~~~~~~^^^^^^^^^^^^^
  File "/home/abba/Desktop/skillsverse-backend/.venv/lib/python3.13/site-packages/django/db/backends/utils.py", line 122, in execute
    return super().execute(sql, params)
           ~~~~~~~~~~~~~~~^^^^^^^^^^^^^
  File "/home/abba/Desktop/skillsverse-backend/.venv/lib/python3.13/site-packages/django/db/backends/utils.py", line 79, in execute
    return self._execute_with_wrappers(
           ~~~~~~~~~~~~~~~~~~~~~~~~~~~^
        sql, params, many=False, executor=self._execute
        ^^^^^^^^^^^^^^^^^^^^^^^^^^^^^^^^^^^^^^^^^^^^^^^
    )
    ^
  File "/home/abba/Desktop/skillsverse-backend/.venv/lib/python3.13/site-packages/django/db/backends/utils.py", line 92, in _execute_with_wrappers
    return executor(sql, params, many, context)
  File "/home/abba/Desktop/skillsverse-backend/.venv/lib/python3.13/site-packages/django/db/backends/utils.py", line 100, in _execute
    with self.db.wrap_database_errors:
         ^^^^^^^^^^^^^^^^^^^^^^^^^^^^
  File "/home/abba/Desktop/skillsverse-backend/.venv/lib/python3.13/site-packages/django/db/utils.py", line 91, in __exit__
    raise dj_exc_value.with_traceback(traceback) from exc_value
  File "/home/abba/Desktop/skillsverse-backend/.venv/lib/python3.13/site-packages/django/db/backends/utils.py", line 105, in _execute
    return self.cursor.execute(sql, params)
           ~~~~~~~~~~~~~~~~~~~^^^^^^^^^^^^^
  File "/home/abba/Desktop/skillsverse-backend/.venv/lib/python3.13/site-packages/django/db/backends/sqlite3/base.py", line 354, in execute
    return super().execute(query, params)
           ~~~~~~~~~~~~~~~^^^^^^^^^^^^^^^
django.db.utils.OperationalError: table jobs_job has no column named salary
[2025-03-22 22:45:40,803: INFO/MainProcess] Task jobs.tasks.fetch_jobs_task[e88d78c7-1097-484e-a198-10656b95515b] received
[2025-03-22 22:45:40,817: INFO/MainProcess] Task jobs.tasks.fetch_jobs_task[d72e537e-d0b9-40d3-a0c5-7a5888551246] received
[2025-03-22 22:45:59,554: ERROR/ForkPoolWorker-8] Task jobs.tasks.fetch_jobs_task[d72e537e-d0b9-40d3-a0c5-7a5888551246] raised unexpected: OperationalError('table jobs_job has no column named salary')
Traceback (most recent call last):
  File "/home/abba/Desktop/skillsverse-backend/.venv/lib/python3.13/site-packages/django/db/backends/utils.py", line 105, in _execute
    return self.cursor.execute(sql, params)
           ~~~~~~~~~~~~~~~~~~~^^^^^^^^^^^^^
  File "/home/abba/Desktop/skillsverse-backend/.venv/lib/python3.13/site-packages/django/db/backends/sqlite3/base.py", line 354, in execute
    return super().execute(query, params)
           ~~~~~~~~~~~~~~~^^^^^^^^^^^^^^^
sqlite3.OperationalError: table jobs_job has no column named salary

The above exception was the direct cause of the following exception:

Traceback (most recent call last):
  File "/home/abba/Desktop/skillsverse-backend/.venv/lib/python3.13/site-packages/celery/app/trace.py", line 453, in trace_task
    R = retval = fun(*args, **kwargs)
                 ~~~^^^^^^^^^^^^^^^^^
  File "/home/abba/Desktop/skillsverse-backend/.venv/lib/python3.13/site-packages/celery/app/trace.py", line 736, in __protected_call__
    return self.run(*args, **kwargs)
           ~~~~~~~~^^^^^^^^^^^^^^^^^
  File "/home/abba/Desktop/skillsverse-backend/jobs/tasks.py", line 7, in fetch_jobs_task
    return fetch_jobs_task()
  File "/home/abba/Desktop/skillsverse-backend/jobs/job_fetcher.py", line 35, in fetch_and_store_jobs
    try:
  File "/home/abba/Desktop/skillsverse-backend/jobs/job_fetcher.py", line 25, in save_jobs_to_db
    
    ...<5 lines>...
        ]
  File "/home/abba/Desktop/skillsverse-backend/.venv/lib/python3.13/site-packages/django/db/models/manager.py", line 87, in manager_method
    return getattr(self.get_queryset(), name)(*args, **kwargs)
           ~~~~~~~~~~~~~~~~~~~~~~~~~~~~~~~~~~^^^^^^^^^^^^^^^^^
  File "/home/abba/Desktop/skillsverse-backend/.venv/lib/python3.13/site-packages/django/db/models/query.py", line 679, in create
    obj.save(force_insert=True, using=self.db)
    ~~~~~~~~^^^^^^^^^^^^^^^^^^^^^^^^^^^^^^^^^^
  File "/home/abba/Desktop/skillsverse-backend/.venv/lib/python3.13/site-packages/django/db/models/base.py", line 892, in save
    self.save_base(
    ~~~~~~~~~~~~~~^
        using=using,
        ^^^^^^^^^^^^
    ...<2 lines>...
        update_fields=update_fields,
        ^^^^^^^^^^^^^^^^^^^^^^^^^^^^
    )
    ^
  File "/home/abba/Desktop/skillsverse-backend/.venv/lib/python3.13/site-packages/django/db/models/base.py", line 998, in save_base
    updated = self._save_table(
        raw,
    ...<4 lines>...
        update_fields,
    )
  File "/home/abba/Desktop/skillsverse-backend/.venv/lib/python3.13/site-packages/django/db/models/base.py", line 1161, in _save_table
    results = self._do_insert(
        cls._base_manager, using, fields, returning_fields, raw
    )
  File "/home/abba/Desktop/skillsverse-backend/.venv/lib/python3.13/site-packages/django/db/models/base.py", line 1202, in _do_insert
    return manager._insert(
           ~~~~~~~~~~~~~~~^
        [self],
        ^^^^^^^
    ...<3 lines>...
        raw=raw,
        ^^^^^^^^
    )
    ^
  File "/home/abba/Desktop/skillsverse-backend/.venv/lib/python3.13/site-packages/django/db/models/manager.py", line 87, in manager_method
    return getattr(self.get_queryset(), name)(*args, **kwargs)
           ~~~~~~~~~~~~~~~~~~~~~~~~~~~~~~~~~~^^^^^^^^^^^^^^^^^
  File "/home/abba/Desktop/skillsverse-backend/.venv/lib/python3.13/site-packages/django/db/models/query.py", line 1847, in _insert
    return query.get_compiler(using=using).execute_sql(returning_fields)
           ~~~~~~~~~~~~~~~~~~~~~~~~~~~~~~~~~~~~~~~~~~~^^^^^^^^^^^^^^^^^^
  File "/home/abba/Desktop/skillsverse-backend/.venv/lib/python3.13/site-packages/django/db/models/sql/compiler.py", line 1836, in execute_sql
    cursor.execute(sql, params)
    ~~~~~~~~~~~~~~^^^^^^^^^^^^^
  File "/home/abba/Desktop/skillsverse-backend/.venv/lib/python3.13/site-packages/django/db/backends/utils.py", line 122, in execute
    return super().execute(sql, params)
           ~~~~~~~~~~~~~~~^^^^^^^^^^^^^
  File "/home/abba/Desktop/skillsverse-backend/.venv/lib/python3.13/site-packages/django/db/backends/utils.py", line 79, in execute
    return self._execute_with_wrappers(
           ~~~~~~~~~~~~~~~~~~~~~~~~~~~^
        sql, params, many=False, executor=self._execute
        ^^^^^^^^^^^^^^^^^^^^^^^^^^^^^^^^^^^^^^^^^^^^^^^
    )
    ^
  File "/home/abba/Desktop/skillsverse-backend/.venv/lib/python3.13/site-packages/django/db/backends/utils.py", line 92, in _execute_with_wrappers
    return executor(sql, params, many, context)
  File "/home/abba/Desktop/skillsverse-backend/.venv/lib/python3.13/site-packages/django/db/backends/utils.py", line 100, in _execute
    with self.db.wrap_database_errors:
         ^^^^^^^^^^^^^^^^^^^^^^^^^^^^
  File "/home/abba/Desktop/skillsverse-backend/.venv/lib/python3.13/site-packages/django/db/utils.py", line 91, in __exit__
    raise dj_exc_value.with_traceback(traceback) from exc_value
  File "/home/abba/Desktop/skillsverse-backend/.venv/lib/python3.13/site-packages/django/db/backends/utils.py", line 105, in _execute
    return self.cursor.execute(sql, params)
           ~~~~~~~~~~~~~~~~~~~^^^^^^^^^^^^^
  File "/home/abba/Desktop/skillsverse-backend/.venv/lib/python3.13/site-packages/django/db/backends/sqlite3/base.py", line 354, in execute
    return super().execute(query, params)
           ~~~~~~~~~~~~~~~^^^^^^^^^^^^^^^
django.db.utils.OperationalError: table jobs_job has no column named salary
[2025-03-22 22:46:00,404: ERROR/ForkPoolWorker-7] Task jobs.tasks.fetch_jobs_task[e88d78c7-1097-484e-a198-10656b95515b] raised unexpected: OperationalError('table jobs_job has no column named salary')
Traceback (most recent call last):
  File "/home/abba/Desktop/skillsverse-backend/.venv/lib/python3.13/site-packages/django/db/backends/utils.py", line 105, in _execute
    return self.cursor.execute(sql, params)
           ~~~~~~~~~~~~~~~~~~~^^^^^^^^^^^^^
  File "/home/abba/Desktop/skillsverse-backend/.venv/lib/python3.13/site-packages/django/db/backends/sqlite3/base.py", line 354, in execute
    return super().execute(query, params)
           ~~~~~~~~~~~~~~~^^^^^^^^^^^^^^^
sqlite3.OperationalError: table jobs_job has no column named salary

The above exception was the direct cause of the following exception:

Traceback (most recent call last):
  File "/home/abba/Desktop/skillsverse-backend/.venv/lib/python3.13/site-packages/celery/app/trace.py", line 453, in trace_task
    R = retval = fun(*args, **kwargs)
                 ~~~^^^^^^^^^^^^^^^^^
  File "/home/abba/Desktop/skillsverse-backend/.venv/lib/python3.13/site-packages/celery/app/trace.py", line 736, in __protected_call__
    return self.run(*args, **kwargs)
           ~~~~~~~~^^^^^^^^^^^^^^^^^
  File "/home/abba/Desktop/skillsverse-backend/jobs/tasks.py", line 7, in fetch_jobs_task
    return fetch_jobs_task()
  File "/home/abba/Desktop/skillsverse-backend/jobs/job_fetcher.py", line 35, in fetch_and_store_jobs
    try:
  File "/home/abba/Desktop/skillsverse-backend/jobs/job_fetcher.py", line 25, in save_jobs_to_db
    
    ...<5 lines>...
        ]
  File "/home/abba/Desktop/skillsverse-backend/.venv/lib/python3.13/site-packages/django/db/models/manager.py", line 87, in manager_method
    return getattr(self.get_queryset(), name)(*args, **kwargs)
           ~~~~~~~~~~~~~~~~~~~~~~~~~~~~~~~~~~^^^^^^^^^^^^^^^^^
  File "/home/abba/Desktop/skillsverse-backend/.venv/lib/python3.13/site-packages/django/db/models/query.py", line 679, in create
    obj.save(force_insert=True, using=self.db)
    ~~~~~~~~^^^^^^^^^^^^^^^^^^^^^^^^^^^^^^^^^^
  File "/home/abba/Desktop/skillsverse-backend/.venv/lib/python3.13/site-packages/django/db/models/base.py", line 892, in save
    self.save_base(
    ~~~~~~~~~~~~~~^
        using=using,
        ^^^^^^^^^^^^
    ...<2 lines>...
        update_fields=update_fields,
        ^^^^^^^^^^^^^^^^^^^^^^^^^^^^
    )
    ^
  File "/home/abba/Desktop/skillsverse-backend/.venv/lib/python3.13/site-packages/django/db/models/base.py", line 998, in save_base
    updated = self._save_table(
        raw,
    ...<4 lines>...
        update_fields,
    )
  File "/home/abba/Desktop/skillsverse-backend/.venv/lib/python3.13/site-packages/django/db/models/base.py", line 1161, in _save_table
    results = self._do_insert(
        cls._base_manager, using, fields, returning_fields, raw
    )
  File "/home/abba/Desktop/skillsverse-backend/.venv/lib/python3.13/site-packages/django/db/models/base.py", line 1202, in _do_insert
    return manager._insert(
           ~~~~~~~~~~~~~~~^
        [self],
        ^^^^^^^
    ...<3 lines>...
        raw=raw,
        ^^^^^^^^
    )
    ^
  File "/home/abba/Desktop/skillsverse-backend/.venv/lib/python3.13/site-packages/django/db/models/manager.py", line 87, in manager_method
    return getattr(self.get_queryset(), name)(*args, **kwargs)
           ~~~~~~~~~~~~~~~~~~~~~~~~~~~~~~~~~~^^^^^^^^^^^^^^^^^
  File "/home/abba/Desktop/skillsverse-backend/.venv/lib/python3.13/site-packages/django/db/models/query.py", line 1847, in _insert
    return query.get_compiler(using=using).execute_sql(returning_fields)
           ~~~~~~~~~~~~~~~~~~~~~~~~~~~~~~~~~~~~~~~~~~~^^^^^^^^^^^^^^^^^^
  File "/home/abba/Desktop/skillsverse-backend/.venv/lib/python3.13/site-packages/django/db/models/sql/compiler.py", line 1836, in execute_sql
    cursor.execute(sql, params)
    ~~~~~~~~~~~~~~^^^^^^^^^^^^^
  File "/home/abba/Desktop/skillsverse-backend/.venv/lib/python3.13/site-packages/django/db/backends/utils.py", line 122, in execute
    return super().execute(sql, params)
           ~~~~~~~~~~~~~~~^^^^^^^^^^^^^
  File "/home/abba/Desktop/skillsverse-backend/.venv/lib/python3.13/site-packages/django/db/backends/utils.py", line 79, in execute
    return self._execute_with_wrappers(
           ~~~~~~~~~~~~~~~~~~~~~~~~~~~^
        sql, params, many=False, executor=self._execute
        ^^^^^^^^^^^^^^^^^^^^^^^^^^^^^^^^^^^^^^^^^^^^^^^
    )
    ^
  File "/home/abba/Desktop/skillsverse-backend/.venv/lib/python3.13/site-packages/django/db/backends/utils.py", line 92, in _execute_with_wrappers
    return executor(sql, params, many, context)
  File "/home/abba/Desktop/skillsverse-backend/.venv/lib/python3.13/site-packages/django/db/backends/utils.py", line 100, in _execute
    with self.db.wrap_database_errors:
         ^^^^^^^^^^^^^^^^^^^^^^^^^^^^
  File "/home/abba/Desktop/skillsverse-backend/.venv/lib/python3.13/site-packages/django/db/utils.py", line 91, in __exit__
    raise dj_exc_value.with_traceback(traceback) from exc_value
  File "/home/abba/Desktop/skillsverse-backend/.venv/lib/python3.13/site-packages/django/db/backends/utils.py", line 105, in _execute
    return self.cursor.execute(sql, params)
           ~~~~~~~~~~~~~~~~~~~^^^^^^^^^^^^^
  File "/home/abba/Desktop/skillsverse-backend/.venv/lib/python3.13/site-packages/django/db/backends/sqlite3/base.py", line 354, in execute
    return super().execute(query, params)
           ~~~~~~~~~~~~~~~^^^^^^^^^^^^^^^
django.db.utils.OperationalError: table jobs_job has no column named salary
[2025-03-22 22:57:15,010: WARNING/MainProcess] consumer: Connection to broker lost. Trying to re-establish the connection...
Traceback (most recent call last):
  File "/home/abba/Desktop/skillsverse-backend/.venv/lib/python3.13/site-packages/celery/worker/consumer/consumer.py", line 340, in start
    blueprint.start(self)
    ~~~~~~~~~~~~~~~^^^^^^
  File "/home/abba/Desktop/skillsverse-backend/.venv/lib/python3.13/site-packages/celery/bootsteps.py", line 116, in start
    step.start(parent)
    ~~~~~~~~~~^^^^^^^^
  File "/home/abba/Desktop/skillsverse-backend/.venv/lib/python3.13/site-packages/celery/worker/consumer/consumer.py", line 746, in start
    c.loop(*c.loop_args())
    ~~~~~~^^^^^^^^^^^^^^^^
  File "/home/abba/Desktop/skillsverse-backend/.venv/lib/python3.13/site-packages/celery/worker/loops.py", line 97, in asynloop
    next(loop)
    ~~~~^^^^^^
  File "/home/abba/Desktop/skillsverse-backend/.venv/lib/python3.13/site-packages/kombu/asynchronous/hub.py", line 373, in create_loop
    cb(*cbargs)
    ~~^^^^^^^^^
  File "/home/abba/Desktop/skillsverse-backend/.venv/lib/python3.13/site-packages/kombu/transport/redis.py", line 1352, in on_readable
    self.cycle.on_readable(fileno)
    ~~~~~~~~~~~~~~~~~~~~~~^^^^^^^^
  File "/home/abba/Desktop/skillsverse-backend/.venv/lib/python3.13/site-packages/kombu/transport/redis.py", line 569, in on_readable
    chan.handlers[type]()
    ~~~~~~~~~~~~~~~~~~~^^
  File "/home/abba/Desktop/skillsverse-backend/.venv/lib/python3.13/site-packages/kombu/transport/redis.py", line 918, in _receive
    ret.append(self._receive_one(c))
               ~~~~~~~~~~~~~~~~~^^^
  File "/home/abba/Desktop/skillsverse-backend/.venv/lib/python3.13/site-packages/kombu/transport/redis.py", line 928, in _receive_one
    response = c.parse_response()
  File "/home/abba/Desktop/skillsverse-backend/.venv/lib/python3.13/site-packages/redis/client.py", line 865, in parse_response
    response = self._execute(conn, try_read)
  File "/home/abba/Desktop/skillsverse-backend/.venv/lib/python3.13/site-packages/redis/client.py", line 841, in _execute
    return conn.retry.call_with_retry(
           ~~~~~~~~~~~~~~~~~~~~~~~~~~^
        lambda: command(*args, **kwargs),
        ^^^^^^^^^^^^^^^^^^^^^^^^^^^^^^^^^
        lambda error: self._disconnect_raise_connect(conn, error),
        ^^^^^^^^^^^^^^^^^^^^^^^^^^^^^^^^^^^^^^^^^^^^^^^^^^^^^^^^^^
    )
    ^
  File "/home/abba/Desktop/skillsverse-backend/.venv/lib/python3.13/site-packages/redis/retry.py", line 65, in call_with_retry
    fail(error)
    ~~~~^^^^^^^
  File "/home/abba/Desktop/skillsverse-backend/.venv/lib/python3.13/site-packages/redis/client.py", line 843, in <lambda>
    lambda error: self._disconnect_raise_connect(conn, error),
                  ~~~~~~~~~~~~~~~~~~~~~~~~~~~~~~^^^^^^^^^^^^^
  File "/home/abba/Desktop/skillsverse-backend/.venv/lib/python3.13/site-packages/redis/client.py", line 830, in _disconnect_raise_connect
    raise error
  File "/home/abba/Desktop/skillsverse-backend/.venv/lib/python3.13/site-packages/redis/retry.py", line 62, in call_with_retry
    return do()
  File "/home/abba/Desktop/skillsverse-backend/.venv/lib/python3.13/site-packages/redis/client.py", line 842, in <lambda>
    lambda: command(*args, **kwargs),
            ~~~~~~~^^^^^^^^^^^^^^^^^
  File "/home/abba/Desktop/skillsverse-backend/.venv/lib/python3.13/site-packages/redis/client.py", line 863, in try_read
    return conn.read_response(disconnect_on_error=False, push_request=True)
           ~~~~~~~~~~~~~~~~~~^^^^^^^^^^^^^^^^^^^^^^^^^^^^^^^^^^^^^^^^^^^^^^
  File "/home/abba/Desktop/skillsverse-backend/.venv/lib/python3.13/site-packages/redis/connection.py", line 592, in read_response
    response = self._parser.read_response(disable_decoding=disable_decoding)
  File "/home/abba/Desktop/skillsverse-backend/.venv/lib/python3.13/site-packages/redis/_parsers/hiredis.py", line 128, in read_response
    self.read_from_socket()
    ~~~~~~~~~~~~~~~~~~~~~^^
  File "/home/abba/Desktop/skillsverse-backend/.venv/lib/python3.13/site-packages/redis/_parsers/hiredis.py", line 90, in read_from_socket
    raise ConnectionError(SERVER_CLOSED_CONNECTION_ERROR)
redis.exceptions.ConnectionError: Connection closed by server.
[2025-03-22 22:57:15,027: WARNING/MainProcess] /home/abba/Desktop/skillsverse-backend/.venv/lib/python3.13/site-packages/celery/worker/consumer/consumer.py:391: CPendingDeprecationWarning: 
In Celery 5.1 we introduced an optional breaking change which
on connection loss cancels all currently executed tasks with late acknowledgement enabled.
These tasks cannot be acknowledged as the connection is gone, and the tasks are automatically redelivered
back to the queue. You can enable this behavior using the worker_cancel_long_running_tasks_on_connection_loss
setting. In Celery 5.1 it is set to False by default. The setting will be set to True by default in Celery 6.0.

  warnings.warn(CANCEL_TASKS_BY_DEFAULT, CPendingDeprecationWarning)

[2025-03-22 22:57:15,036: WARNING/MainProcess] /home/abba/Desktop/skillsverse-backend/.venv/lib/python3.13/site-packages/celery/worker/consumer/consumer.py:508: CPendingDeprecationWarning: The broker_connection_retry configuration setting will no longer determine
whether broker connection retries are made during startup in Celery 6.0 and above.
If you wish to retain the existing behavior for retrying connections on startup,
you should set broker_connection_retry_on_startup to True.
  warnings.warn(

[2025-03-22 22:57:15,038: ERROR/MainProcess] consumer: Cannot connect to redis://localhost:6379/0: Error 111 connecting to localhost:6379. Connection refused..
Trying again in 2.00 seconds... (1/100)

[2025-03-22 22:57:15,789: CRITICAL/MainProcess] Unrecoverable error: OperationalError('[Errno 32] Broken pipe')
Traceback (most recent call last):
  File "/home/abba/Desktop/skillsverse-backend/.venv/lib/python3.13/site-packages/kombu/transport/virtual/base.py", line 951, in create_channel
    return self._avail_channels.pop()
           ~~~~~~~~~~~~~~~~~~~~~~~~^^
IndexError: pop from empty list

During handling of the above exception, another exception occurred:

Traceback (most recent call last):
  File "/home/abba/Desktop/skillsverse-backend/.venv/lib/python3.13/site-packages/redis/connection.py", line 357, in connect
    sock = self.retry.call_with_retry(
        lambda: self._connect(), lambda error: self.disconnect(error)
    )
  File "/home/abba/Desktop/skillsverse-backend/.venv/lib/python3.13/site-packages/redis/retry.py", line 62, in call_with_retry
    return do()
  File "/home/abba/Desktop/skillsverse-backend/.venv/lib/python3.13/site-packages/redis/connection.py", line 358, in <lambda>
    lambda: self._connect(), lambda error: self.disconnect(error)
            ~~~~~~~~~~~~~^^
  File "/home/abba/Desktop/skillsverse-backend/.venv/lib/python3.13/site-packages/redis/connection.py", line 730, in _connect
    raise err
  File "/home/abba/Desktop/skillsverse-backend/.venv/lib/python3.13/site-packages/redis/connection.py", line 718, in _connect
    sock.connect(socket_address)
    ~~~~~~~~~~~~^^^^^^^^^^^^^^^^
ConnectionRefusedError: [Errno 111] Connection refused

During handling of the above exception, another exception occurred:

Traceback (most recent call last):
  File "/home/abba/Desktop/skillsverse-backend/.venv/lib/python3.13/site-packages/kombu/utils/functional.py", line 318, in retry_over_time
    return fun(*args, **kwargs)
  File "/home/abba/Desktop/skillsverse-backend/.venv/lib/python3.13/site-packages/kombu/connection.py", line 934, in _connection_factory
    self._connection = self._establish_connection()
                       ~~~~~~~~~~~~~~~~~~~~~~~~~~^^
  File "/home/abba/Desktop/skillsverse-backend/.venv/lib/python3.13/site-packages/kombu/connection.py", line 860, in _establish_connection
    conn = self.transport.establish_connection()
  File "/home/abba/Desktop/skillsverse-backend/.venv/lib/python3.13/site-packages/kombu/transport/virtual/base.py", line 975, in establish_connection
    self._avail_channels.append(self.create_channel(self))
                                ~~~~~~~~~~~~~~~~~~~^^^^^^
  File "/home/abba/Desktop/skillsverse-backend/.venv/lib/python3.13/site-packages/kombu/transport/virtual/base.py", line 953, in create_channel
    channel = self.Channel(connection)
  File "/home/abba/Desktop/skillsverse-backend/.venv/lib/python3.13/site-packages/kombu/transport/redis.py", line 744, in __init__
    self.client.ping()
    ~~~~~~~~~~~~~~~~^^
  File "/home/abba/Desktop/skillsverse-backend/.venv/lib/python3.13/site-packages/redis/commands/core.py", line 1212, in ping
    return self.execute_command("PING", **kwargs)
           ~~~~~~~~~~~~~~~~~~~~^^^^^^^^^^^^^^^^^^
  File "/home/abba/Desktop/skillsverse-backend/.venv/lib/python3.13/site-packages/redis/client.py", line 559, in execute_command
    return self._execute_command(*args, **options)
           ~~~~~~~~~~~~~~~~~~~~~^^^^^^^^^^^^^^^^^^
  File "/home/abba/Desktop/skillsverse-backend/.venv/lib/python3.13/site-packages/redis/client.py", line 565, in _execute_command
    conn = self.connection or pool.get_connection(command_name, **options)
                              ~~~~~~~~~~~~~~~~~~~^^^^^^^^^^^^^^^^^^^^^^^^^
  File "/home/abba/Desktop/skillsverse-backend/.venv/lib/python3.13/site-packages/redis/connection.py", line 1422, in get_connection
    connection.connect()
    ~~~~~~~~~~~~~~~~~~^^
  File "/home/abba/Desktop/skillsverse-backend/.venv/lib/python3.13/site-packages/redis/connection.py", line 363, in connect
    raise ConnectionError(self._error_message(e))
redis.exceptions.ConnectionError: Error 111 connecting to localhost:6379. Connection refused.

During handling of the above exception, another exception occurred:

Traceback (most recent call last):
  File "/home/abba/Desktop/skillsverse-backend/.venv/lib/python3.13/site-packages/kombu/connection.py", line 472, in _reraise_as_library_errors
    yield
  File "/home/abba/Desktop/skillsverse-backend/.venv/lib/python3.13/site-packages/kombu/connection.py", line 459, in _ensure_connection
    return retry_over_time(
        self._connection_factory, self.recoverable_connection_errors,
    ...<2 lines>...
        callback, timeout=timeout
    )
  File "/home/abba/Desktop/skillsverse-backend/.venv/lib/python3.13/site-packages/kombu/utils/functional.py", line 332, in retry_over_time
    sleep(1.0)
    ~~~~~^^^^^
  File "/home/abba/Desktop/skillsverse-backend/.venv/lib/python3.13/site-packages/celery/apps/worker.py", line 289, in _handle_request
    safe_say(f'worker: {how} shutdown (MainProcess)', sys.__stdout__)
    ~~~~~~~~^^^^^^^^^^^^^^^^^^^^^^^^^^^^^^^^^^^^^^^^^^^^^^^^^^^^^^^^^
  File "/home/abba/Desktop/skillsverse-backend/.venv/lib/python3.13/site-packages/celery/apps/worker.py", line 81, in safe_say
    print(f'\n{msg}', file=f, flush=True)
    ~~~~~^^^^^^^^^^^^^^^^^^^^^^^^^^^^^^^^
BrokenPipeError: [Errno 32] Broken pipe

The above exception was the direct cause of the following exception:

Traceback (most recent call last):
  File "/home/abba/Desktop/skillsverse-backend/.venv/lib/python3.13/site-packages/celery/worker/worker.py", line 202, in start
    self.blueprint.start(self)
    ~~~~~~~~~~~~~~~~~~~~^^^^^^
  File "/home/abba/Desktop/skillsverse-backend/.venv/lib/python3.13/site-packages/celery/bootsteps.py", line 116, in start
    step.start(parent)
    ~~~~~~~~~~^^^^^^^^
  File "/home/abba/Desktop/skillsverse-backend/.venv/lib/python3.13/site-packages/celery/bootsteps.py", line 365, in start
    return self.obj.start()
           ~~~~~~~~~~~~~~^^
  File "/home/abba/Desktop/skillsverse-backend/.venv/lib/python3.13/site-packages/celery/worker/consumer/consumer.py", line 340, in start
    blueprint.start(self)
    ~~~~~~~~~~~~~~~^^^^^^
  File "/home/abba/Desktop/skillsverse-backend/.venv/lib/python3.13/site-packages/celery/bootsteps.py", line 116, in start
    step.start(parent)
    ~~~~~~~~~~^^^^^^^^
  File "/home/abba/Desktop/skillsverse-backend/.venv/lib/python3.13/site-packages/celery/worker/consumer/connection.py", line 21, in start
    c.connection = c.connect()
                   ~~~~~~~~~^^
  File "/home/abba/Desktop/skillsverse-backend/.venv/lib/python3.13/site-packages/celery/worker/consumer/consumer.py", line 470, in connect
    conn = self.connection_for_read(heartbeat=self.amqheartbeat)
  File "/home/abba/Desktop/skillsverse-backend/.venv/lib/python3.13/site-packages/celery/worker/consumer/consumer.py", line 476, in connection_for_read
    return self.ensure_connected(
           ~~~~~~~~~~~~~~~~~~~~~^
        self.app.connection_for_read(heartbeat=heartbeat))
        ^^^^^^^^^^^^^^^^^^^^^^^^^^^^^^^^^^^^^^^^^^^^^^^^^^
  File "/home/abba/Desktop/skillsverse-backend/.venv/lib/python3.13/site-packages/celery/worker/consumer/consumer.py", line 527, in ensure_connected
    conn = conn.ensure_connection(
        _error_handler, self.app.conf.broker_connection_max_retries,
        callback=maybe_shutdown,
    )
  File "/home/abba/Desktop/skillsverse-backend/.venv/lib/python3.13/site-packages/kombu/connection.py", line 406, in ensure_connection
    self._ensure_connection(*args, **kwargs)
    ~~~~~~~~~~~~~~~~~~~~~~~^^^^^^^^^^^^^^^^^
  File "/home/abba/Desktop/skillsverse-backend/.venv/lib/python3.13/site-packages/kombu/connection.py", line 458, in _ensure_connection
    with ctx():
         ~~~^^
  File "/usr/lib/python3.13/contextlib.py", line 162, in __exit__
    self.gen.throw(value)
    ~~~~~~~~~~~~~~^^^^^^^
  File "/home/abba/Desktop/skillsverse-backend/.venv/lib/python3.13/site-packages/kombu/connection.py", line 476, in _reraise_as_library_errors
    raise ConnectionError(str(exc)) from exc
kombu.exceptions.OperationalError: [Errno 32] Broken pipe
[2025-03-23 13:28:34,089: WARNING/MainProcess] /home/abba/Desktop/skillsverse-backend/.venv/lib/python3.13/site-packages/celery/worker/consumer/consumer.py:508: CPendingDeprecationWarning: The broker_connection_retry configuration setting will no longer determine
whether broker connection retries are made during startup in Celery 6.0 and above.
If you wish to retain the existing behavior for retrying connections on startup,
you should set broker_connection_retry_on_startup to True.
  warnings.warn(

[2025-03-23 13:28:34,092: ERROR/MainProcess] consumer: Cannot connect to redis://localhost:6379/0: Error 111 connecting to localhost:6379. Connection refused..
Trying again in 2.00 seconds... (1/100)

[2025-03-23 13:28:36,096: ERROR/MainProcess] consumer: Cannot connect to redis://localhost:6379/0: Error 111 connecting to localhost:6379. Connection refused..
Trying again in 4.00 seconds... (2/100)

[2025-03-23 13:28:40,100: ERROR/MainProcess] consumer: Cannot connect to redis://localhost:6379/0: Error 111 connecting to localhost:6379. Connection refused..
Trying again in 6.00 seconds... (3/100)

[2025-03-23 13:28:46,106: ERROR/MainProcess] consumer: Cannot connect to redis://localhost:6379/0: Error 111 connecting to localhost:6379. Connection refused..
Trying again in 8.00 seconds... (4/100)

[2025-03-23 13:28:54,109: ERROR/MainProcess] consumer: Cannot connect to redis://localhost:6379/0: Error 111 connecting to localhost:6379. Connection refused..
Trying again in 10.00 seconds... (5/100)

[2025-03-23 13:29:04,116: ERROR/MainProcess] consumer: Cannot connect to redis://localhost:6379/0: Error 111 connecting to localhost:6379. Connection refused..
Trying again in 12.00 seconds... (6/100)

[2025-03-23 13:29:16,118: ERROR/MainProcess] consumer: Cannot connect to redis://localhost:6379/0: Error 111 connecting to localhost:6379. Connection refused..
Trying again in 14.00 seconds... (7/100)

[2025-03-23 13:29:30,123: ERROR/MainProcess] consumer: Cannot connect to redis://localhost:6379/0: Error 111 connecting to localhost:6379. Connection refused..
Trying again in 16.00 seconds... (8/100)

[2025-03-23 13:29:46,128: ERROR/MainProcess] consumer: Cannot connect to redis://localhost:6379/0: Error 111 connecting to localhost:6379. Connection refused..
Trying again in 18.00 seconds... (9/100)

[2025-03-23 13:30:04,135: ERROR/MainProcess] consumer: Cannot connect to redis://localhost:6379/0: Error 111 connecting to localhost:6379. Connection refused..
Trying again in 20.00 seconds... (10/100)

[2025-03-23 13:30:24,141: ERROR/MainProcess] consumer: Cannot connect to redis://localhost:6379/0: Error 111 connecting to localhost:6379. Connection refused..
Trying again in 22.00 seconds... (11/100)

[2025-03-23 13:30:46,149: ERROR/MainProcess] consumer: Cannot connect to redis://localhost:6379/0: Error 111 connecting to localhost:6379. Connection refused..
Trying again in 24.00 seconds... (12/100)

[2025-03-23 13:31:10,159: ERROR/MainProcess] consumer: Cannot connect to redis://localhost:6379/0: Error 111 connecting to localhost:6379. Connection refused..
Trying again in 26.00 seconds... (13/100)

[2025-03-23 13:31:36,165: ERROR/MainProcess] consumer: Cannot connect to redis://localhost:6379/0: Error 111 connecting to localhost:6379. Connection refused..
Trying again in 28.00 seconds... (14/100)

[2025-03-23 13:32:04,173: ERROR/MainProcess] consumer: Cannot connect to redis://localhost:6379/0: Error 111 connecting to localhost:6379. Connection refused..
Trying again in 30.00 seconds... (15/100)

[2025-03-23 13:32:34,181: ERROR/MainProcess] consumer: Cannot connect to redis://localhost:6379/0: Error 111 connecting to localhost:6379. Connection refused..
Trying again in 32.00 seconds... (16/100)

[2025-03-23 13:33:06,185: ERROR/MainProcess] consumer: Cannot connect to redis://localhost:6379/0: Error 111 connecting to localhost:6379. Connection refused..
Trying again in 32.00 seconds... (16/100)

[2025-03-23 13:33:38,192: ERROR/MainProcess] consumer: Cannot connect to redis://localhost:6379/0: Error 111 connecting to localhost:6379. Connection refused..
Trying again in 32.00 seconds... (16/100)

[2025-03-23 13:34:10,199: ERROR/MainProcess] consumer: Cannot connect to redis://localhost:6379/0: Error 111 connecting to localhost:6379. Connection refused..
Trying again in 32.00 seconds... (16/100)

[2025-03-23 13:34:42,210: ERROR/MainProcess] consumer: Cannot connect to redis://localhost:6379/0: Error 111 connecting to localhost:6379. Connection refused..
Trying again in 32.00 seconds... (16/100)

[2025-03-23 13:35:14,218: ERROR/MainProcess] consumer: Cannot connect to redis://localhost:6379/0: Error 111 connecting to localhost:6379. Connection refused..
Trying again in 32.00 seconds... (16/100)

[2025-03-23 13:35:46,227: ERROR/MainProcess] consumer: Cannot connect to redis://localhost:6379/0: Error 111 connecting to localhost:6379. Connection refused..
Trying again in 32.00 seconds... (16/100)

[2025-03-23 13:36:18,239: ERROR/MainProcess] consumer: Cannot connect to redis://localhost:6379/0: Error 111 connecting to localhost:6379. Connection refused..
Trying again in 32.00 seconds... (16/100)

[2025-03-23 13:36:50,248: ERROR/MainProcess] consumer: Cannot connect to redis://localhost:6379/0: Error 111 connecting to localhost:6379. Connection refused..
Trying again in 32.00 seconds... (16/100)

[2025-03-23 13:37:22,252: ERROR/MainProcess] consumer: Cannot connect to redis://localhost:6379/0: Error 111 connecting to localhost:6379. Connection refused..
Trying again in 32.00 seconds... (16/100)

[2025-03-23 13:37:54,257: ERROR/MainProcess] consumer: Cannot connect to redis://localhost:6379/0: Error 111 connecting to localhost:6379. Connection refused..
Trying again in 32.00 seconds... (16/100)

[2025-03-23 13:38:26,266: ERROR/MainProcess] consumer: Cannot connect to redis://localhost:6379/0: Error 111 connecting to localhost:6379. Connection refused..
Trying again in 32.00 seconds... (16/100)

[2025-03-23 13:38:58,275: ERROR/MainProcess] consumer: Cannot connect to redis://localhost:6379/0: Error 111 connecting to localhost:6379. Connection refused..
Trying again in 32.00 seconds... (16/100)

[2025-03-23 13:39:30,282: ERROR/MainProcess] consumer: Cannot connect to redis://localhost:6379/0: Error 111 connecting to localhost:6379. Connection refused..
Trying again in 32.00 seconds... (16/100)

[2025-03-23 13:40:02,289: ERROR/MainProcess] consumer: Cannot connect to redis://localhost:6379/0: Error 111 connecting to localhost:6379. Connection refused..
Trying again in 32.00 seconds... (16/100)

[2025-03-23 13:40:34,297: ERROR/MainProcess] consumer: Cannot connect to redis://localhost:6379/0: Error 111 connecting to localhost:6379. Connection refused..
Trying again in 32.00 seconds... (16/100)

[2025-03-23 13:41:06,318: ERROR/MainProcess] consumer: Cannot connect to redis://localhost:6379/0: Error 111 connecting to localhost:6379. Connection refused..
Trying again in 32.00 seconds... (16/100)

[2025-03-23 13:41:38,334: ERROR/MainProcess] consumer: Cannot connect to redis://localhost:6379/0: Error 111 connecting to localhost:6379. Connection refused..
Trying again in 32.00 seconds... (16/100)

[2025-03-23 13:42:10,350: ERROR/MainProcess] consumer: Cannot connect to redis://localhost:6379/0: Error 111 connecting to localhost:6379. Connection refused..
Trying again in 32.00 seconds... (16/100)

[2025-03-23 13:42:42,356: ERROR/MainProcess] consumer: Cannot connect to redis://localhost:6379/0: Error 111 connecting to localhost:6379. Connection refused..
Trying again in 32.00 seconds... (16/100)

[2025-03-23 13:43:14,364: ERROR/MainProcess] consumer: Cannot connect to redis://localhost:6379/0: Error 111 connecting to localhost:6379. Connection refused..
Trying again in 32.00 seconds... (16/100)

[2025-03-23 13:43:46,374: ERROR/MainProcess] consumer: Cannot connect to redis://localhost:6379/0: Error 111 connecting to localhost:6379. Connection refused..
Trying again in 32.00 seconds... (16/100)

[2025-03-23 13:44:18,382: ERROR/MainProcess] consumer: Cannot connect to redis://localhost:6379/0: Error 111 connecting to localhost:6379. Connection refused..
Trying again in 32.00 seconds... (16/100)

[2025-03-23 13:44:50,391: ERROR/MainProcess] consumer: Cannot connect to redis://localhost:6379/0: Error 111 connecting to localhost:6379. Connection refused..
Trying again in 32.00 seconds... (16/100)

[2025-03-23 13:45:22,396: ERROR/MainProcess] consumer: Cannot connect to redis://localhost:6379/0: Error 111 connecting to localhost:6379. Connection refused..
Trying again in 32.00 seconds... (16/100)

[2025-03-23 13:45:54,406: ERROR/MainProcess] consumer: Cannot connect to redis://localhost:6379/0: Error 111 connecting to localhost:6379. Connection refused..
Trying again in 32.00 seconds... (16/100)

[2025-03-23 13:46:26,413: ERROR/MainProcess] consumer: Cannot connect to redis://localhost:6379/0: Error 111 connecting to localhost:6379. Connection refused..
Trying again in 32.00 seconds... (16/100)

[2025-03-23 13:46:58,419: ERROR/MainProcess] consumer: Cannot connect to redis://localhost:6379/0: Error 111 connecting to localhost:6379. Connection refused..
Trying again in 32.00 seconds... (16/100)

[2025-03-23 13:47:30,425: ERROR/MainProcess] consumer: Cannot connect to redis://localhost:6379/0: Error 111 connecting to localhost:6379. Connection refused..
Trying again in 32.00 seconds... (16/100)

[2025-03-23 13:48:02,434: ERROR/MainProcess] consumer: Cannot connect to redis://localhost:6379/0: Error 111 connecting to localhost:6379. Connection refused..
Trying again in 32.00 seconds... (16/100)

[2025-03-23 13:48:34,443: ERROR/MainProcess] consumer: Cannot connect to redis://localhost:6379/0: Error 111 connecting to localhost:6379. Connection refused..
Trying again in 32.00 seconds... (16/100)

[2025-03-23 13:49:06,455: ERROR/MainProcess] consumer: Cannot connect to redis://localhost:6379/0: Error 111 connecting to localhost:6379. Connection refused..
Trying again in 32.00 seconds... (16/100)

[2025-03-23 13:49:38,464: ERROR/MainProcess] consumer: Cannot connect to redis://localhost:6379/0: Error 111 connecting to localhost:6379. Connection refused..
Trying again in 32.00 seconds... (16/100)

[2025-03-23 13:50:10,475: ERROR/MainProcess] consumer: Cannot connect to redis://localhost:6379/0: Error 111 connecting to localhost:6379. Connection refused..
Trying again in 32.00 seconds... (16/100)

[2025-03-23 13:50:42,481: ERROR/MainProcess] consumer: Cannot connect to redis://localhost:6379/0: Error 111 connecting to localhost:6379. Connection refused..
Trying again in 32.00 seconds... (16/100)

[2025-03-23 13:51:14,493: ERROR/MainProcess] consumer: Cannot connect to redis://localhost:6379/0: Error 111 connecting to localhost:6379. Connection refused..
Trying again in 32.00 seconds... (16/100)

[2025-03-23 13:51:46,512: ERROR/MainProcess] consumer: Cannot connect to redis://localhost:6379/0: Error 111 connecting to localhost:6379. Connection refused..
Trying again in 32.00 seconds... (16/100)

[2025-03-23 13:52:18,523: ERROR/MainProcess] consumer: Cannot connect to redis://localhost:6379/0: Error 111 connecting to localhost:6379. Connection refused..
Trying again in 32.00 seconds... (16/100)

[2025-03-23 13:52:50,537: ERROR/MainProcess] consumer: Cannot connect to redis://localhost:6379/0: Error 111 connecting to localhost:6379. Connection refused..
Trying again in 32.00 seconds... (16/100)

[2025-03-23 13:53:22,546: ERROR/MainProcess] consumer: Cannot connect to redis://localhost:6379/0: Error 111 connecting to localhost:6379. Connection refused..
Trying again in 32.00 seconds... (16/100)

[2025-03-23 13:53:54,560: ERROR/MainProcess] consumer: Cannot connect to redis://localhost:6379/0: Error 111 connecting to localhost:6379. Connection refused..
Trying again in 32.00 seconds... (16/100)

[2025-03-23 13:54:26,578: ERROR/MainProcess] consumer: Cannot connect to redis://localhost:6379/0: Error 111 connecting to localhost:6379. Connection refused..
Trying again in 32.00 seconds... (16/100)

[2025-03-23 13:54:58,593: ERROR/MainProcess] consumer: Cannot connect to redis://localhost:6379/0: Error 111 connecting to localhost:6379. Connection refused..
Trying again in 32.00 seconds... (16/100)

[2025-03-23 13:55:30,603: ERROR/MainProcess] consumer: Cannot connect to redis://localhost:6379/0: Error 111 connecting to localhost:6379. Connection refused..
Trying again in 32.00 seconds... (16/100)

[2025-03-23 13:56:02,618: ERROR/MainProcess] consumer: Cannot connect to redis://localhost:6379/0: Error 111 connecting to localhost:6379. Connection refused..
Trying again in 32.00 seconds... (16/100)

[2025-03-23 13:56:34,630: ERROR/MainProcess] consumer: Cannot connect to redis://localhost:6379/0: Error 111 connecting to localhost:6379. Connection refused..
Trying again in 32.00 seconds... (16/100)

[2025-03-23 13:57:06,640: ERROR/MainProcess] consumer: Cannot connect to redis://localhost:6379/0: Error 111 connecting to localhost:6379. Connection refused..
Trying again in 32.00 seconds... (16/100)

[2025-03-23 13:57:38,658: ERROR/MainProcess] consumer: Cannot connect to redis://localhost:6379/0: Error 111 connecting to localhost:6379. Connection refused..
Trying again in 32.00 seconds... (16/100)

[2025-03-23 13:58:10,674: ERROR/MainProcess] consumer: Cannot connect to redis://localhost:6379/0: Error 111 connecting to localhost:6379. Connection refused..
Trying again in 32.00 seconds... (16/100)

[2025-03-23 13:58:42,689: ERROR/MainProcess] consumer: Cannot connect to redis://localhost:6379/0: Error 111 connecting to localhost:6379. Connection refused..
Trying again in 32.00 seconds... (16/100)

[2025-03-23 13:59:14,706: ERROR/MainProcess] consumer: Cannot connect to redis://localhost:6379/0: Error 111 connecting to localhost:6379. Connection refused..
Trying again in 32.00 seconds... (16/100)

[2025-03-23 13:59:46,720: ERROR/MainProcess] consumer: Cannot connect to redis://localhost:6379/0: Error 111 connecting to localhost:6379. Connection refused..
Trying again in 32.00 seconds... (16/100)

[2025-03-23 14:00:18,740: ERROR/MainProcess] consumer: Cannot connect to redis://localhost:6379/0: Error 111 connecting to localhost:6379. Connection refused..
Trying again in 32.00 seconds... (16/100)

[2025-03-23 14:00:50,756: ERROR/MainProcess] consumer: Cannot connect to redis://localhost:6379/0: Error 111 connecting to localhost:6379. Connection refused..
Trying again in 32.00 seconds... (16/100)

[2025-03-23 14:01:22,766: ERROR/MainProcess] consumer: Cannot connect to redis://localhost:6379/0: Error 111 connecting to localhost:6379. Connection refused..
Trying again in 32.00 seconds... (16/100)

[2025-03-23 14:01:54,778: ERROR/MainProcess] consumer: Cannot connect to redis://localhost:6379/0: Error 111 connecting to localhost:6379. Connection refused..
Trying again in 32.00 seconds... (16/100)

[2025-03-23 14:02:26,793: ERROR/MainProcess] consumer: Cannot connect to redis://localhost:6379/0: Error 111 connecting to localhost:6379. Connection refused..
Trying again in 32.00 seconds... (16/100)

[2025-03-23 14:02:58,807: ERROR/MainProcess] consumer: Cannot connect to redis://localhost:6379/0: Error 111 connecting to localhost:6379. Connection refused..
Trying again in 32.00 seconds... (16/100)

[2025-03-23 14:03:30,821: ERROR/MainProcess] consumer: Cannot connect to redis://localhost:6379/0: Error 111 connecting to localhost:6379. Connection refused..
Trying again in 32.00 seconds... (16/100)

[2025-03-23 14:04:02,838: ERROR/MainProcess] consumer: Cannot connect to redis://localhost:6379/0: Error 111 connecting to localhost:6379. Connection refused..
Trying again in 32.00 seconds... (16/100)

[2025-03-23 14:04:34,844: ERROR/MainProcess] consumer: Cannot connect to redis://localhost:6379/0: Error 111 connecting to localhost:6379. Connection refused..
Trying again in 32.00 seconds... (16/100)

[2025-03-23 14:05:06,852: ERROR/MainProcess] consumer: Cannot connect to redis://localhost:6379/0: Error 111 connecting to localhost:6379. Connection refused..
Trying again in 32.00 seconds... (16/100)

[2025-03-23 14:05:38,856: ERROR/MainProcess] consumer: Cannot connect to redis://localhost:6379/0: Error 111 connecting to localhost:6379. Connection refused..
Trying again in 32.00 seconds... (16/100)

[2025-03-23 14:06:10,872: ERROR/MainProcess] consumer: Cannot connect to redis://localhost:6379/0: Error 111 connecting to localhost:6379. Connection refused..
Trying again in 32.00 seconds... (16/100)

[2025-03-23 14:06:42,879: ERROR/MainProcess] consumer: Cannot connect to redis://localhost:6379/0: Error 111 connecting to localhost:6379. Connection refused..
Trying again in 32.00 seconds... (16/100)

[2025-03-23 14:07:14,888: ERROR/MainProcess] consumer: Cannot connect to redis://localhost:6379/0: Error 111 connecting to localhost:6379. Connection refused..
Trying again in 32.00 seconds... (16/100)

[2025-03-23 14:07:46,901: ERROR/MainProcess] consumer: Cannot connect to redis://localhost:6379/0: Error 111 connecting to localhost:6379. Connection refused..
Trying again in 32.00 seconds... (16/100)

[2025-03-23 14:08:18,909: ERROR/MainProcess] consumer: Cannot connect to redis://localhost:6379/0: Error 111 connecting to localhost:6379. Connection refused..
Trying again in 32.00 seconds... (16/100)

[2025-03-23 14:08:50,921: ERROR/MainProcess] consumer: Cannot connect to redis://localhost:6379/0: Error 111 connecting to localhost:6379. Connection refused..
Trying again in 32.00 seconds... (16/100)

[2025-03-23 14:09:22,933: ERROR/MainProcess] consumer: Cannot connect to redis://localhost:6379/0: Error 111 connecting to localhost:6379. Connection refused..
Trying again in 32.00 seconds... (16/100)

[2025-03-23 14:09:54,944: ERROR/MainProcess] consumer: Cannot connect to redis://localhost:6379/0: Error 111 connecting to localhost:6379. Connection refused..
Trying again in 32.00 seconds... (16/100)

[2025-03-23 14:10:26,951: ERROR/MainProcess] consumer: Cannot connect to redis://localhost:6379/0: Error 111 connecting to localhost:6379. Connection refused..
Trying again in 32.00 seconds... (16/100)

[2025-03-23 14:10:58,959: ERROR/MainProcess] consumer: Cannot connect to redis://localhost:6379/0: Error 111 connecting to localhost:6379. Connection refused..
Trying again in 32.00 seconds... (16/100)

[2025-03-23 14:11:30,970: ERROR/MainProcess] consumer: Cannot connect to redis://localhost:6379/0: Error 111 connecting to localhost:6379. Connection refused..
Trying again in 32.00 seconds... (16/100)

[2025-03-23 14:12:02,977: ERROR/MainProcess] consumer: Cannot connect to redis://localhost:6379/0: Error 111 connecting to localhost:6379. Connection refused..
Trying again in 32.00 seconds... (16/100)

[2025-03-23 14:12:34,983: ERROR/MainProcess] consumer: Cannot connect to redis://localhost:6379/0: Error 111 connecting to localhost:6379. Connection refused..
Trying again in 32.00 seconds... (16/100)

[2025-03-23 14:13:06,989: ERROR/MainProcess] consumer: Cannot connect to redis://localhost:6379/0: Error 111 connecting to localhost:6379. Connection refused..
Trying again in 32.00 seconds... (16/100)

[2025-03-23 14:13:38,996: ERROR/MainProcess] consumer: Cannot connect to redis://localhost:6379/0: Error 111 connecting to localhost:6379. Connection refused..
Trying again in 32.00 seconds... (16/100)

[2025-03-23 14:14:11,004: ERROR/MainProcess] consumer: Cannot connect to redis://localhost:6379/0: Error 111 connecting to localhost:6379. Connection refused..
Trying again in 32.00 seconds... (16/100)

[2025-03-23 14:14:43,010: ERROR/MainProcess] consumer: Cannot connect to redis://localhost:6379/0: Error 111 connecting to localhost:6379. Connection refused..
Trying again in 32.00 seconds... (16/100)

[2025-03-23 14:15:15,019: ERROR/MainProcess] consumer: Cannot connect to redis://localhost:6379/0: Error 111 connecting to localhost:6379. Connection refused..
Trying again in 32.00 seconds... (16/100)

[2025-03-23 14:15:47,028: ERROR/MainProcess] consumer: Cannot connect to redis://localhost:6379/0: Error 111 connecting to localhost:6379. Connection refused..
Trying again in 32.00 seconds... (16/100)

[2025-03-23 14:16:19,039: ERROR/MainProcess] consumer: Cannot connect to redis://localhost:6379/0: Error 111 connecting to localhost:6379. Connection refused..
Trying again in 32.00 seconds... (16/100)

[2025-03-23 14:16:51,047: ERROR/MainProcess] consumer: Cannot connect to redis://localhost:6379/0: Error 111 connecting to localhost:6379. Connection refused..
Trying again in 32.00 seconds... (16/100)

[2025-03-23 14:17:23,056: ERROR/MainProcess] consumer: Cannot connect to redis://localhost:6379/0: Error 111 connecting to localhost:6379. Connection refused..
Trying again in 32.00 seconds... (16/100)

[2025-03-23 14:17:55,066: CRITICAL/MainProcess] Unrecoverable error: OperationalError('Error 111 connecting to localhost:6379. Connection refused.')
Traceback (most recent call last):
  File "/home/abba/Desktop/skillsverse-backend/.venv/lib/python3.13/site-packages/kombu/transport/virtual/base.py", line 951, in create_channel
    return self._avail_channels.pop()
           ~~~~~~~~~~~~~~~~~~~~~~~~^^
IndexError: pop from empty list

During handling of the above exception, another exception occurred:

Traceback (most recent call last):
  File "/home/abba/Desktop/skillsverse-backend/.venv/lib/python3.13/site-packages/redis/connection.py", line 357, in connect
    sock = self.retry.call_with_retry(
        lambda: self._connect(), lambda error: self.disconnect(error)
    )
  File "/home/abba/Desktop/skillsverse-backend/.venv/lib/python3.13/site-packages/redis/retry.py", line 62, in call_with_retry
    return do()
  File "/home/abba/Desktop/skillsverse-backend/.venv/lib/python3.13/site-packages/redis/connection.py", line 358, in <lambda>
    lambda: self._connect(), lambda error: self.disconnect(error)
            ~~~~~~~~~~~~~^^
  File "/home/abba/Desktop/skillsverse-backend/.venv/lib/python3.13/site-packages/redis/connection.py", line 730, in _connect
    raise err
  File "/home/abba/Desktop/skillsverse-backend/.venv/lib/python3.13/site-packages/redis/connection.py", line 718, in _connect
    sock.connect(socket_address)
    ~~~~~~~~~~~~^^^^^^^^^^^^^^^^
ConnectionRefusedError: [Errno 111] Connection refused

During handling of the above exception, another exception occurred:

Traceback (most recent call last):
  File "/home/abba/Desktop/skillsverse-backend/.venv/lib/python3.13/site-packages/kombu/connection.py", line 472, in _reraise_as_library_errors
    yield
  File "/home/abba/Desktop/skillsverse-backend/.venv/lib/python3.13/site-packages/kombu/connection.py", line 459, in _ensure_connection
    return retry_over_time(
        self._connection_factory, self.recoverable_connection_errors,
    ...<2 lines>...
        callback, timeout=timeout
    )
  File "/home/abba/Desktop/skillsverse-backend/.venv/lib/python3.13/site-packages/kombu/utils/functional.py", line 318, in retry_over_time
    return fun(*args, **kwargs)
  File "/home/abba/Desktop/skillsverse-backend/.venv/lib/python3.13/site-packages/kombu/connection.py", line 934, in _connection_factory
    self._connection = self._establish_connection()
                       ~~~~~~~~~~~~~~~~~~~~~~~~~~^^
  File "/home/abba/Desktop/skillsverse-backend/.venv/lib/python3.13/site-packages/kombu/connection.py", line 860, in _establish_connection
    conn = self.transport.establish_connection()
  File "/home/abba/Desktop/skillsverse-backend/.venv/lib/python3.13/site-packages/kombu/transport/virtual/base.py", line 975, in establish_connection
    self._avail_channels.append(self.create_channel(self))
                                ~~~~~~~~~~~~~~~~~~~^^^^^^
  File "/home/abba/Desktop/skillsverse-backend/.venv/lib/python3.13/site-packages/kombu/transport/virtual/base.py", line 953, in create_channel
    channel = self.Channel(connection)
  File "/home/abba/Desktop/skillsverse-backend/.venv/lib/python3.13/site-packages/kombu/transport/redis.py", line 744, in __init__
    self.client.ping()
    ~~~~~~~~~~~~~~~~^^
  File "/home/abba/Desktop/skillsverse-backend/.venv/lib/python3.13/site-packages/redis/commands/core.py", line 1212, in ping
    return self.execute_command("PING", **kwargs)
           ~~~~~~~~~~~~~~~~~~~~^^^^^^^^^^^^^^^^^^
  File "/home/abba/Desktop/skillsverse-backend/.venv/lib/python3.13/site-packages/redis/client.py", line 559, in execute_command
    return self._execute_command(*args, **options)
           ~~~~~~~~~~~~~~~~~~~~~^^^^^^^^^^^^^^^^^^
  File "/home/abba/Desktop/skillsverse-backend/.venv/lib/python3.13/site-packages/redis/client.py", line 565, in _execute_command
    conn = self.connection or pool.get_connection(command_name, **options)
                              ~~~~~~~~~~~~~~~~~~~^^^^^^^^^^^^^^^^^^^^^^^^^
  File "/home/abba/Desktop/skillsverse-backend/.venv/lib/python3.13/site-packages/redis/connection.py", line 1422, in get_connection
    connection.connect()
    ~~~~~~~~~~~~~~~~~~^^
  File "/home/abba/Desktop/skillsverse-backend/.venv/lib/python3.13/site-packages/redis/connection.py", line 363, in connect
    raise ConnectionError(self._error_message(e))
redis.exceptions.ConnectionError: Error 111 connecting to localhost:6379. Connection refused.

The above exception was the direct cause of the following exception:

Traceback (most recent call last):
  File "/home/abba/Desktop/skillsverse-backend/.venv/lib/python3.13/site-packages/celery/worker/worker.py", line 202, in start
    self.blueprint.start(self)
    ~~~~~~~~~~~~~~~~~~~~^^^^^^
  File "/home/abba/Desktop/skillsverse-backend/.venv/lib/python3.13/site-packages/celery/bootsteps.py", line 116, in start
    step.start(parent)
    ~~~~~~~~~~^^^^^^^^
  File "/home/abba/Desktop/skillsverse-backend/.venv/lib/python3.13/site-packages/celery/bootsteps.py", line 365, in start
    return self.obj.start()
           ~~~~~~~~~~~~~~^^
  File "/home/abba/Desktop/skillsverse-backend/.venv/lib/python3.13/site-packages/celery/worker/consumer/consumer.py", line 340, in start
    blueprint.start(self)
    ~~~~~~~~~~~~~~~^^^^^^
  File "/home/abba/Desktop/skillsverse-backend/.venv/lib/python3.13/site-packages/celery/bootsteps.py", line 116, in start
    step.start(parent)
    ~~~~~~~~~~^^^^^^^^
  File "/home/abba/Desktop/skillsverse-backend/.venv/lib/python3.13/site-packages/celery/worker/consumer/connection.py", line 21, in start
    c.connection = c.connect()
                   ~~~~~~~~~^^
  File "/home/abba/Desktop/skillsverse-backend/.venv/lib/python3.13/site-packages/celery/worker/consumer/consumer.py", line 470, in connect
    conn = self.connection_for_read(heartbeat=self.amqheartbeat)
  File "/home/abba/Desktop/skillsverse-backend/.venv/lib/python3.13/site-packages/celery/worker/consumer/consumer.py", line 476, in connection_for_read
    return self.ensure_connected(
           ~~~~~~~~~~~~~~~~~~~~~^
        self.app.connection_for_read(heartbeat=heartbeat))
        ^^^^^^^^^^^^^^^^^^^^^^^^^^^^^^^^^^^^^^^^^^^^^^^^^^
  File "/home/abba/Desktop/skillsverse-backend/.venv/lib/python3.13/site-packages/celery/worker/consumer/consumer.py", line 527, in ensure_connected
    conn = conn.ensure_connection(
        _error_handler, self.app.conf.broker_connection_max_retries,
        callback=maybe_shutdown,
    )
  File "/home/abba/Desktop/skillsverse-backend/.venv/lib/python3.13/site-packages/kombu/connection.py", line 406, in ensure_connection
    self._ensure_connection(*args, **kwargs)
    ~~~~~~~~~~~~~~~~~~~~~~~^^^^^^^^^^^^^^^^^
  File "/home/abba/Desktop/skillsverse-backend/.venv/lib/python3.13/site-packages/kombu/connection.py", line 458, in _ensure_connection
    with ctx():
         ~~~^^
  File "/usr/lib/python3.13/contextlib.py", line 162, in __exit__
    self.gen.throw(value)
    ~~~~~~~~~~~~~~^^^^^^^
  File "/home/abba/Desktop/skillsverse-backend/.venv/lib/python3.13/site-packages/kombu/connection.py", line 476, in _reraise_as_library_errors
    raise ConnectionError(str(exc)) from exc
kombu.exceptions.OperationalError: Error 111 connecting to localhost:6379. Connection refused.
[2025-03-28 15:24:46,026: WARNING/MainProcess] /home/abba/Desktop/skillsverse-backend/.venv/lib/python3.13/site-packages/celery/worker/consumer/consumer.py:508: CPendingDeprecationWarning: The broker_connection_retry configuration setting will no longer determine
whether broker connection retries are made during startup in Celery 6.0 and above.
If you wish to retain the existing behavior for retrying connections on startup,
you should set broker_connection_retry_on_startup to True.
  warnings.warn(

[2025-03-28 15:24:46,031: ERROR/MainProcess] consumer: Cannot connect to redis://localhost:6379/0: Error 111 connecting to localhost:6379. Connection refused..
Trying again in 2.00 seconds... (1/100)

[2025-03-28 15:24:48,035: ERROR/MainProcess] consumer: Cannot connect to redis://localhost:6379/0: Error 111 connecting to localhost:6379. Connection refused..
Trying again in 4.00 seconds... (2/100)

[2025-03-28 15:24:52,040: ERROR/MainProcess] consumer: Cannot connect to redis://localhost:6379/0: Error 111 connecting to localhost:6379. Connection refused..
Trying again in 6.00 seconds... (3/100)

[2025-03-28 15:24:58,045: ERROR/MainProcess] consumer: Cannot connect to redis://localhost:6379/0: Error 111 connecting to localhost:6379. Connection refused..
Trying again in 8.00 seconds... (4/100)

[2025-03-28 15:25:06,049: ERROR/MainProcess] consumer: Cannot connect to redis://localhost:6379/0: Error 111 connecting to localhost:6379. Connection refused..
Trying again in 10.00 seconds... (5/100)

[2025-03-28 15:25:16,056: ERROR/MainProcess] consumer: Cannot connect to redis://localhost:6379/0: Error 111 connecting to localhost:6379. Connection refused..
Trying again in 12.00 seconds... (6/100)

[2025-03-28 15:25:28,062: ERROR/MainProcess] consumer: Cannot connect to redis://localhost:6379/0: Error 111 connecting to localhost:6379. Connection refused..
Trying again in 14.00 seconds... (7/100)

[2025-03-28 15:25:42,068: ERROR/MainProcess] consumer: Cannot connect to redis://localhost:6379/0: Error 111 connecting to localhost:6379. Connection refused..
Trying again in 16.00 seconds... (8/100)

[2025-03-28 15:25:58,081: ERROR/MainProcess] consumer: Cannot connect to redis://localhost:6379/0: Error 111 connecting to localhost:6379. Connection refused..
Trying again in 18.00 seconds... (9/100)

[2025-03-28 15:26:16,088: ERROR/MainProcess] consumer: Cannot connect to redis://localhost:6379/0: Error 111 connecting to localhost:6379. Connection refused..
Trying again in 20.00 seconds... (10/100)

[2025-03-28 15:26:36,096: ERROR/MainProcess] consumer: Cannot connect to redis://localhost:6379/0: Error 111 connecting to localhost:6379. Connection refused..
Trying again in 22.00 seconds... (11/100)

[2025-03-28 15:26:58,103: ERROR/MainProcess] consumer: Cannot connect to redis://localhost:6379/0: Error 111 connecting to localhost:6379. Connection refused..
Trying again in 24.00 seconds... (12/100)

[2025-03-28 15:27:22,112: ERROR/MainProcess] consumer: Cannot connect to redis://localhost:6379/0: Error 111 connecting to localhost:6379. Connection refused..
Trying again in 26.00 seconds... (13/100)

[2025-03-28 15:27:48,120: ERROR/MainProcess] consumer: Cannot connect to redis://localhost:6379/0: Error 111 connecting to localhost:6379. Connection refused..
Trying again in 28.00 seconds... (14/100)

[2025-03-28 15:28:16,128: ERROR/MainProcess] consumer: Cannot connect to redis://localhost:6379/0: Error 111 connecting to localhost:6379. Connection refused..
Trying again in 30.00 seconds... (15/100)

[2025-03-28 15:28:46,137: ERROR/MainProcess] consumer: Cannot connect to redis://localhost:6379/0: Error 111 connecting to localhost:6379. Connection refused..
Trying again in 32.00 seconds... (16/100)

[2025-03-28 15:29:18,147: ERROR/MainProcess] consumer: Cannot connect to redis://localhost:6379/0: Error 111 connecting to localhost:6379. Connection refused..
Trying again in 32.00 seconds... (16/100)

[2025-03-28 15:29:50,157: ERROR/MainProcess] consumer: Cannot connect to redis://localhost:6379/0: Error 111 connecting to localhost:6379. Connection refused..
Trying again in 32.00 seconds... (16/100)

[2025-03-28 15:30:22,170: ERROR/MainProcess] consumer: Cannot connect to redis://localhost:6379/0: Error 111 connecting to localhost:6379. Connection refused..
Trying again in 32.00 seconds... (16/100)

[2025-03-28 15:30:54,185: ERROR/MainProcess] consumer: Cannot connect to redis://localhost:6379/0: Error 111 connecting to localhost:6379. Connection refused..
Trying again in 32.00 seconds... (16/100)

[2025-03-28 15:31:26,195: ERROR/MainProcess] consumer: Cannot connect to redis://localhost:6379/0: Error 111 connecting to localhost:6379. Connection refused..
Trying again in 32.00 seconds... (16/100)

[2025-03-28 15:31:58,203: ERROR/MainProcess] consumer: Cannot connect to redis://localhost:6379/0: Error 111 connecting to localhost:6379. Connection refused..
Trying again in 32.00 seconds... (16/100)

[2025-03-28 15:32:30,214: ERROR/MainProcess] consumer: Cannot connect to redis://localhost:6379/0: Error 111 connecting to localhost:6379. Connection refused..
Trying again in 32.00 seconds... (16/100)

[2025-03-28 15:33:02,223: ERROR/MainProcess] consumer: Cannot connect to redis://localhost:6379/0: Error 111 connecting to localhost:6379. Connection refused..
Trying again in 32.00 seconds... (16/100)

[2025-03-28 15:33:34,235: ERROR/MainProcess] consumer: Cannot connect to redis://localhost:6379/0: Error 111 connecting to localhost:6379. Connection refused..
Trying again in 32.00 seconds... (16/100)

[2025-03-28 15:34:06,247: ERROR/MainProcess] consumer: Cannot connect to redis://localhost:6379/0: Error 111 connecting to localhost:6379. Connection refused..
Trying again in 32.00 seconds... (16/100)

[2025-03-28 15:34:38,258: ERROR/MainProcess] consumer: Cannot connect to redis://localhost:6379/0: Error 111 connecting to localhost:6379. Connection refused..
Trying again in 32.00 seconds... (16/100)

[2025-03-28 15:35:10,271: ERROR/MainProcess] consumer: Cannot connect to redis://localhost:6379/0: Error 111 connecting to localhost:6379. Connection refused..
Trying again in 32.00 seconds... (16/100)

[2025-03-28 15:35:42,283: ERROR/MainProcess] consumer: Cannot connect to redis://localhost:6379/0: Error 111 connecting to localhost:6379. Connection refused..
Trying again in 32.00 seconds... (16/100)

[2025-03-28 15:36:14,292: ERROR/MainProcess] consumer: Cannot connect to redis://localhost:6379/0: Error 111 connecting to localhost:6379. Connection refused..
Trying again in 32.00 seconds... (16/100)

[2025-03-28 15:36:46,302: ERROR/MainProcess] consumer: Cannot connect to redis://localhost:6379/0: Error 111 connecting to localhost:6379. Connection refused..
Trying again in 32.00 seconds... (16/100)

[2025-03-28 15:37:18,312: ERROR/MainProcess] consumer: Cannot connect to redis://localhost:6379/0: Error 111 connecting to localhost:6379. Connection refused..
Trying again in 32.00 seconds... (16/100)

[2025-03-28 15:37:50,324: ERROR/MainProcess] consumer: Cannot connect to redis://localhost:6379/0: Error 111 connecting to localhost:6379. Connection refused..
Trying again in 32.00 seconds... (16/100)

[2025-03-28 15:38:22,332: ERROR/MainProcess] consumer: Cannot connect to redis://localhost:6379/0: Error 111 connecting to localhost:6379. Connection refused..
Trying again in 32.00 seconds... (16/100)

[2025-03-28 15:38:54,343: ERROR/MainProcess] consumer: Cannot connect to redis://localhost:6379/0: Error 111 connecting to localhost:6379. Connection refused..
Trying again in 32.00 seconds... (16/100)

[2025-03-28 15:39:26,353: ERROR/MainProcess] consumer: Cannot connect to redis://localhost:6379/0: Error 111 connecting to localhost:6379. Connection refused..
Trying again in 32.00 seconds... (16/100)

[2025-03-28 15:39:58,362: ERROR/MainProcess] consumer: Cannot connect to redis://localhost:6379/0: Error 111 connecting to localhost:6379. Connection refused..
Trying again in 32.00 seconds... (16/100)

[2025-03-28 15:40:30,371: ERROR/MainProcess] consumer: Cannot connect to redis://localhost:6379/0: Error 111 connecting to localhost:6379. Connection refused..
Trying again in 32.00 seconds... (16/100)

[2025-03-28 15:41:02,381: ERROR/MainProcess] consumer: Cannot connect to redis://localhost:6379/0: Error 111 connecting to localhost:6379. Connection refused..
Trying again in 32.00 seconds... (16/100)

[2025-03-28 15:41:34,392: ERROR/MainProcess] consumer: Cannot connect to redis://localhost:6379/0: Error 111 connecting to localhost:6379. Connection refused..
Trying again in 32.00 seconds... (16/100)

[2025-03-28 15:42:06,402: ERROR/MainProcess] consumer: Cannot connect to redis://localhost:6379/0: Error 111 connecting to localhost:6379. Connection refused..
Trying again in 32.00 seconds... (16/100)

[2025-03-28 15:42:38,412: ERROR/MainProcess] consumer: Cannot connect to redis://localhost:6379/0: Error 111 connecting to localhost:6379. Connection refused..
Trying again in 32.00 seconds... (16/100)

[2025-03-28 15:43:10,422: ERROR/MainProcess] consumer: Cannot connect to redis://localhost:6379/0: Error 111 connecting to localhost:6379. Connection refused..
Trying again in 32.00 seconds... (16/100)

[2025-03-28 15:43:42,432: ERROR/MainProcess] consumer: Cannot connect to redis://localhost:6379/0: Error 111 connecting to localhost:6379. Connection refused..
Trying again in 32.00 seconds... (16/100)

[2025-03-28 15:44:14,442: ERROR/MainProcess] consumer: Cannot connect to redis://localhost:6379/0: Error 111 connecting to localhost:6379. Connection refused..
Trying again in 32.00 seconds... (16/100)

[2025-03-28 15:44:46,448: ERROR/MainProcess] consumer: Cannot connect to redis://localhost:6379/0: Error 111 connecting to localhost:6379. Connection refused..
Trying again in 32.00 seconds... (16/100)

[2025-03-28 15:45:18,460: ERROR/MainProcess] consumer: Cannot connect to redis://localhost:6379/0: Error 111 connecting to localhost:6379. Connection refused..
Trying again in 32.00 seconds... (16/100)

[2025-03-28 15:45:50,471: ERROR/MainProcess] consumer: Cannot connect to redis://localhost:6379/0: Error 111 connecting to localhost:6379. Connection refused..
Trying again in 32.00 seconds... (16/100)

[2025-03-28 15:46:22,481: ERROR/MainProcess] consumer: Cannot connect to redis://localhost:6379/0: Error 111 connecting to localhost:6379. Connection refused..
Trying again in 32.00 seconds... (16/100)

[2025-03-28 15:46:54,492: ERROR/MainProcess] consumer: Cannot connect to redis://localhost:6379/0: Error 111 connecting to localhost:6379. Connection refused..
Trying again in 32.00 seconds... (16/100)

[2025-03-28 15:47:26,498: ERROR/MainProcess] consumer: Cannot connect to redis://localhost:6379/0: Error 111 connecting to localhost:6379. Connection refused..
Trying again in 32.00 seconds... (16/100)

[2025-03-28 15:47:58,507: ERROR/MainProcess] consumer: Cannot connect to redis://localhost:6379/0: Error 111 connecting to localhost:6379. Connection refused..
Trying again in 32.00 seconds... (16/100)

[2025-03-28 15:48:30,515: ERROR/MainProcess] consumer: Cannot connect to redis://localhost:6379/0: Error 111 connecting to localhost:6379. Connection refused..
Trying again in 32.00 seconds... (16/100)

[2025-03-28 15:49:02,525: ERROR/MainProcess] consumer: Cannot connect to redis://localhost:6379/0: Error 111 connecting to localhost:6379. Connection refused..
Trying again in 32.00 seconds... (16/100)

[2025-03-28 15:49:34,536: ERROR/MainProcess] consumer: Cannot connect to redis://localhost:6379/0: Error 111 connecting to localhost:6379. Connection refused..
Trying again in 32.00 seconds... (16/100)

[2025-03-28 15:50:06,544: ERROR/MainProcess] consumer: Cannot connect to redis://localhost:6379/0: Error 111 connecting to localhost:6379. Connection refused..
Trying again in 32.00 seconds... (16/100)

[2025-03-28 15:50:38,554: ERROR/MainProcess] consumer: Cannot connect to redis://localhost:6379/0: Error 111 connecting to localhost:6379. Connection refused..
Trying again in 32.00 seconds... (16/100)

[2025-03-28 15:51:10,566: ERROR/MainProcess] consumer: Cannot connect to redis://localhost:6379/0: Error 111 connecting to localhost:6379. Connection refused..
Trying again in 32.00 seconds... (16/100)

[2025-03-28 15:51:42,581: ERROR/MainProcess] consumer: Cannot connect to redis://localhost:6379/0: Error 111 connecting to localhost:6379. Connection refused..
Trying again in 32.00 seconds... (16/100)

[2025-03-28 15:52:14,599: ERROR/MainProcess] consumer: Cannot connect to redis://localhost:6379/0: Error 111 connecting to localhost:6379. Connection refused..
Trying again in 32.00 seconds... (16/100)

[2025-03-28 15:52:46,607: ERROR/MainProcess] consumer: Cannot connect to redis://localhost:6379/0: Error 111 connecting to localhost:6379. Connection refused..
Trying again in 32.00 seconds... (16/100)

[2025-03-28 15:53:18,615: ERROR/MainProcess] consumer: Cannot connect to redis://localhost:6379/0: Error 111 connecting to localhost:6379. Connection refused..
Trying again in 32.00 seconds... (16/100)

[2025-03-28 15:53:50,625: ERROR/MainProcess] consumer: Cannot connect to redis://localhost:6379/0: Error 111 connecting to localhost:6379. Connection refused..
Trying again in 32.00 seconds... (16/100)

[2025-03-28 15:54:22,633: ERROR/MainProcess] consumer: Cannot connect to redis://localhost:6379/0: Error 111 connecting to localhost:6379. Connection refused..
Trying again in 32.00 seconds... (16/100)

[2025-03-28 15:54:54,641: ERROR/MainProcess] consumer: Cannot connect to redis://localhost:6379/0: Error 111 connecting to localhost:6379. Connection refused..
Trying again in 32.00 seconds... (16/100)

[2025-03-28 15:55:26,652: ERROR/MainProcess] consumer: Cannot connect to redis://localhost:6379/0: Error 111 connecting to localhost:6379. Connection refused..
Trying again in 32.00 seconds... (16/100)

[2025-03-28 15:55:58,664: ERROR/MainProcess] consumer: Cannot connect to redis://localhost:6379/0: Error 111 connecting to localhost:6379. Connection refused..
Trying again in 32.00 seconds... (16/100)

[2025-03-28 15:56:30,675: ERROR/MainProcess] consumer: Cannot connect to redis://localhost:6379/0: Error 111 connecting to localhost:6379. Connection refused..
Trying again in 32.00 seconds... (16/100)

[2025-03-28 15:57:02,688: ERROR/MainProcess] consumer: Cannot connect to redis://localhost:6379/0: Error 111 connecting to localhost:6379. Connection refused..
Trying again in 32.00 seconds... (16/100)

[2025-03-28 15:57:34,699: ERROR/MainProcess] consumer: Cannot connect to redis://localhost:6379/0: Error 111 connecting to localhost:6379. Connection refused..
Trying again in 32.00 seconds... (16/100)

[2025-03-28 15:58:06,713: ERROR/MainProcess] consumer: Cannot connect to redis://localhost:6379/0: Error 111 connecting to localhost:6379. Connection refused..
Trying again in 32.00 seconds... (16/100)

[2025-03-28 15:58:38,725: ERROR/MainProcess] consumer: Cannot connect to redis://localhost:6379/0: Error 111 connecting to localhost:6379. Connection refused..
Trying again in 32.00 seconds... (16/100)

[2025-03-28 15:59:10,736: ERROR/MainProcess] consumer: Cannot connect to redis://localhost:6379/0: Error 111 connecting to localhost:6379. Connection refused..
Trying again in 32.00 seconds... (16/100)

[2025-03-28 15:59:42,747: ERROR/MainProcess] consumer: Cannot connect to redis://localhost:6379/0: Error 111 connecting to localhost:6379. Connection refused..
Trying again in 32.00 seconds... (16/100)

[2025-03-28 16:00:14,758: ERROR/MainProcess] consumer: Cannot connect to redis://localhost:6379/0: Error 111 connecting to localhost:6379. Connection refused..
Trying again in 32.00 seconds... (16/100)

[2025-03-28 16:00:46,767: ERROR/MainProcess] consumer: Cannot connect to redis://localhost:6379/0: Error 111 connecting to localhost:6379. Connection refused..
Trying again in 32.00 seconds... (16/100)

[2025-03-28 16:01:18,779: ERROR/MainProcess] consumer: Cannot connect to redis://localhost:6379/0: Error 111 connecting to localhost:6379. Connection refused..
Trying again in 32.00 seconds... (16/100)

[2025-03-28 16:01:50,790: ERROR/MainProcess] consumer: Cannot connect to redis://localhost:6379/0: Error 111 connecting to localhost:6379. Connection refused..
Trying again in 32.00 seconds... (16/100)

[2025-03-28 16:02:22,800: ERROR/MainProcess] consumer: Cannot connect to redis://localhost:6379/0: Error 111 connecting to localhost:6379. Connection refused..
Trying again in 32.00 seconds... (16/100)

[2025-03-28 16:02:54,808: ERROR/MainProcess] consumer: Cannot connect to redis://localhost:6379/0: Error 111 connecting to localhost:6379. Connection refused..
Trying again in 32.00 seconds... (16/100)

[2025-03-28 16:03:26,816: ERROR/MainProcess] consumer: Cannot connect to redis://localhost:6379/0: Error 111 connecting to localhost:6379. Connection refused..
Trying again in 32.00 seconds... (16/100)

[2025-03-28 16:03:58,824: ERROR/MainProcess] consumer: Cannot connect to redis://localhost:6379/0: Error 111 connecting to localhost:6379. Connection refused..
Trying again in 32.00 seconds... (16/100)

[2025-03-28 16:04:30,832: ERROR/MainProcess] consumer: Cannot connect to redis://localhost:6379/0: Error 111 connecting to localhost:6379. Connection refused..
Trying again in 32.00 seconds... (16/100)

[2025-03-28 16:05:02,840: ERROR/MainProcess] consumer: Cannot connect to redis://localhost:6379/0: Error 111 connecting to localhost:6379. Connection refused..
Trying again in 32.00 seconds... (16/100)

[2025-03-28 16:05:34,848: ERROR/MainProcess] consumer: Cannot connect to redis://localhost:6379/0: Error 111 connecting to localhost:6379. Connection refused..
Trying again in 32.00 seconds... (16/100)

[2025-03-28 16:06:06,858: ERROR/MainProcess] consumer: Cannot connect to redis://localhost:6379/0: Error 111 connecting to localhost:6379. Connection refused..
Trying again in 32.00 seconds... (16/100)

[2025-03-28 16:06:38,867: ERROR/MainProcess] consumer: Cannot connect to redis://localhost:6379/0: Error 111 connecting to localhost:6379. Connection refused..
Trying again in 32.00 seconds... (16/100)

[2025-03-28 16:07:10,879: ERROR/MainProcess] consumer: Cannot connect to redis://localhost:6379/0: Error 111 connecting to localhost:6379. Connection refused..
Trying again in 32.00 seconds... (16/100)

[2025-03-28 16:07:42,891: ERROR/MainProcess] consumer: Cannot connect to redis://localhost:6379/0: Error 111 connecting to localhost:6379. Connection refused..
Trying again in 32.00 seconds... (16/100)

[2025-03-28 16:08:14,899: ERROR/MainProcess] consumer: Cannot connect to redis://localhost:6379/0: Error 111 connecting to localhost:6379. Connection refused..
Trying again in 32.00 seconds... (16/100)

[2025-03-28 16:08:46,907: ERROR/MainProcess] consumer: Cannot connect to redis://localhost:6379/0: Error 111 connecting to localhost:6379. Connection refused..
Trying again in 32.00 seconds... (16/100)

[2025-03-28 16:09:18,917: ERROR/MainProcess] consumer: Cannot connect to redis://localhost:6379/0: Error 111 connecting to localhost:6379. Connection refused..
Trying again in 32.00 seconds... (16/100)

[2025-03-28 16:09:50,926: ERROR/MainProcess] consumer: Cannot connect to redis://localhost:6379/0: Error 111 connecting to localhost:6379. Connection refused..
Trying again in 32.00 seconds... (16/100)

[2025-03-28 16:10:22,939: ERROR/MainProcess] consumer: Cannot connect to redis://localhost:6379/0: Error 111 connecting to localhost:6379. Connection refused..
Trying again in 32.00 seconds... (16/100)

[2025-03-28 16:10:54,945: ERROR/MainProcess] consumer: Cannot connect to redis://localhost:6379/0: Error 111 connecting to localhost:6379. Connection refused..
Trying again in 32.00 seconds... (16/100)

[2025-03-28 16:11:26,954: ERROR/MainProcess] consumer: Cannot connect to redis://localhost:6379/0: Error 111 connecting to localhost:6379. Connection refused..
Trying again in 32.00 seconds... (16/100)

[2025-03-28 16:11:58,963: ERROR/MainProcess] consumer: Cannot connect to redis://localhost:6379/0: Error 111 connecting to localhost:6379. Connection refused..
Trying again in 32.00 seconds... (16/100)

[2025-03-28 16:12:30,970: ERROR/MainProcess] consumer: Cannot connect to redis://localhost:6379/0: Error 111 connecting to localhost:6379. Connection refused..
Trying again in 32.00 seconds... (16/100)

[2025-03-28 16:13:02,980: ERROR/MainProcess] consumer: Cannot connect to redis://localhost:6379/0: Error 111 connecting to localhost:6379. Connection refused..
Trying again in 32.00 seconds... (16/100)

[2025-03-28 16:13:34,990: ERROR/MainProcess] consumer: Cannot connect to redis://localhost:6379/0: Error 111 connecting to localhost:6379. Connection refused..
Trying again in 32.00 seconds... (16/100)

[2025-03-28 16:14:07,002: CRITICAL/MainProcess] Unrecoverable error: OperationalError('Error 111 connecting to localhost:6379. Connection refused.')
Traceback (most recent call last):
  File "/home/abba/Desktop/skillsverse-backend/.venv/lib/python3.13/site-packages/kombu/transport/virtual/base.py", line 951, in create_channel
    return self._avail_channels.pop()
           ~~~~~~~~~~~~~~~~~~~~~~~~^^
IndexError: pop from empty list

During handling of the above exception, another exception occurred:

Traceback (most recent call last):
  File "/home/abba/Desktop/skillsverse-backend/.venv/lib/python3.13/site-packages/redis/connection.py", line 357, in connect
    sock = self.retry.call_with_retry(
        lambda: self._connect(), lambda error: self.disconnect(error)
    )
  File "/home/abba/Desktop/skillsverse-backend/.venv/lib/python3.13/site-packages/redis/retry.py", line 62, in call_with_retry
    return do()
  File "/home/abba/Desktop/skillsverse-backend/.venv/lib/python3.13/site-packages/redis/connection.py", line 358, in <lambda>
    lambda: self._connect(), lambda error: self.disconnect(error)
            ~~~~~~~~~~~~~^^
  File "/home/abba/Desktop/skillsverse-backend/.venv/lib/python3.13/site-packages/redis/connection.py", line 730, in _connect
    raise err
  File "/home/abba/Desktop/skillsverse-backend/.venv/lib/python3.13/site-packages/redis/connection.py", line 718, in _connect
    sock.connect(socket_address)
    ~~~~~~~~~~~~^^^^^^^^^^^^^^^^
ConnectionRefusedError: [Errno 111] Connection refused

During handling of the above exception, another exception occurred:

Traceback (most recent call last):
  File "/home/abba/Desktop/skillsverse-backend/.venv/lib/python3.13/site-packages/kombu/connection.py", line 472, in _reraise_as_library_errors
    yield
  File "/home/abba/Desktop/skillsverse-backend/.venv/lib/python3.13/site-packages/kombu/connection.py", line 459, in _ensure_connection
    return retry_over_time(
        self._connection_factory, self.recoverable_connection_errors,
    ...<2 lines>...
        callback, timeout=timeout
    )
  File "/home/abba/Desktop/skillsverse-backend/.venv/lib/python3.13/site-packages/kombu/utils/functional.py", line 318, in retry_over_time
    return fun(*args, **kwargs)
  File "/home/abba/Desktop/skillsverse-backend/.venv/lib/python3.13/site-packages/kombu/connection.py", line 934, in _connection_factory
    self._connection = self._establish_connection()
                       ~~~~~~~~~~~~~~~~~~~~~~~~~~^^
  File "/home/abba/Desktop/skillsverse-backend/.venv/lib/python3.13/site-packages/kombu/connection.py", line 860, in _establish_connection
    conn = self.transport.establish_connection()
  File "/home/abba/Desktop/skillsverse-backend/.venv/lib/python3.13/site-packages/kombu/transport/virtual/base.py", line 975, in establish_connection
    self._avail_channels.append(self.create_channel(self))
                                ~~~~~~~~~~~~~~~~~~~^^^^^^
  File "/home/abba/Desktop/skillsverse-backend/.venv/lib/python3.13/site-packages/kombu/transport/virtual/base.py", line 953, in create_channel
    channel = self.Channel(connection)
  File "/home/abba/Desktop/skillsverse-backend/.venv/lib/python3.13/site-packages/kombu/transport/redis.py", line 744, in __init__
    self.client.ping()
    ~~~~~~~~~~~~~~~~^^
  File "/home/abba/Desktop/skillsverse-backend/.venv/lib/python3.13/site-packages/redis/commands/core.py", line 1212, in ping
    return self.execute_command("PING", **kwargs)
           ~~~~~~~~~~~~~~~~~~~~^^^^^^^^^^^^^^^^^^
  File "/home/abba/Desktop/skillsverse-backend/.venv/lib/python3.13/site-packages/redis/client.py", line 559, in execute_command
    return self._execute_command(*args, **options)
           ~~~~~~~~~~~~~~~~~~~~~^^^^^^^^^^^^^^^^^^
  File "/home/abba/Desktop/skillsverse-backend/.venv/lib/python3.13/site-packages/redis/client.py", line 565, in _execute_command
    conn = self.connection or pool.get_connection(command_name, **options)
                              ~~~~~~~~~~~~~~~~~~~^^^^^^^^^^^^^^^^^^^^^^^^^
  File "/home/abba/Desktop/skillsverse-backend/.venv/lib/python3.13/site-packages/redis/connection.py", line 1422, in get_connection
    connection.connect()
    ~~~~~~~~~~~~~~~~~~^^
  File "/home/abba/Desktop/skillsverse-backend/.venv/lib/python3.13/site-packages/redis/connection.py", line 363, in connect
    raise ConnectionError(self._error_message(e))
redis.exceptions.ConnectionError: Error 111 connecting to localhost:6379. Connection refused.

The above exception was the direct cause of the following exception:

Traceback (most recent call last):
  File "/home/abba/Desktop/skillsverse-backend/.venv/lib/python3.13/site-packages/celery/worker/worker.py", line 202, in start
    self.blueprint.start(self)
    ~~~~~~~~~~~~~~~~~~~~^^^^^^
  File "/home/abba/Desktop/skillsverse-backend/.venv/lib/python3.13/site-packages/celery/bootsteps.py", line 116, in start
    step.start(parent)
    ~~~~~~~~~~^^^^^^^^
  File "/home/abba/Desktop/skillsverse-backend/.venv/lib/python3.13/site-packages/celery/bootsteps.py", line 365, in start
    return self.obj.start()
           ~~~~~~~~~~~~~~^^
  File "/home/abba/Desktop/skillsverse-backend/.venv/lib/python3.13/site-packages/celery/worker/consumer/consumer.py", line 340, in start
    blueprint.start(self)
    ~~~~~~~~~~~~~~~^^^^^^
  File "/home/abba/Desktop/skillsverse-backend/.venv/lib/python3.13/site-packages/celery/bootsteps.py", line 116, in start
    step.start(parent)
    ~~~~~~~~~~^^^^^^^^
  File "/home/abba/Desktop/skillsverse-backend/.venv/lib/python3.13/site-packages/celery/worker/consumer/connection.py", line 21, in start
    c.connection = c.connect()
                   ~~~~~~~~~^^
  File "/home/abba/Desktop/skillsverse-backend/.venv/lib/python3.13/site-packages/celery/worker/consumer/consumer.py", line 470, in connect
    conn = self.connection_for_read(heartbeat=self.amqheartbeat)
  File "/home/abba/Desktop/skillsverse-backend/.venv/lib/python3.13/site-packages/celery/worker/consumer/consumer.py", line 476, in connection_for_read
    return self.ensure_connected(
           ~~~~~~~~~~~~~~~~~~~~~^
        self.app.connection_for_read(heartbeat=heartbeat))
        ^^^^^^^^^^^^^^^^^^^^^^^^^^^^^^^^^^^^^^^^^^^^^^^^^^
  File "/home/abba/Desktop/skillsverse-backend/.venv/lib/python3.13/site-packages/celery/worker/consumer/consumer.py", line 527, in ensure_connected
    conn = conn.ensure_connection(
        _error_handler, self.app.conf.broker_connection_max_retries,
        callback=maybe_shutdown,
    )
  File "/home/abba/Desktop/skillsverse-backend/.venv/lib/python3.13/site-packages/kombu/connection.py", line 406, in ensure_connection
    self._ensure_connection(*args, **kwargs)
    ~~~~~~~~~~~~~~~~~~~~~~~^^^^^^^^^^^^^^^^^
  File "/home/abba/Desktop/skillsverse-backend/.venv/lib/python3.13/site-packages/kombu/connection.py", line 458, in _ensure_connection
    with ctx():
         ~~~^^
  File "/usr/lib/python3.13/contextlib.py", line 162, in __exit__
    self.gen.throw(value)
    ~~~~~~~~~~~~~~^^^^^^^
  File "/home/abba/Desktop/skillsverse-backend/.venv/lib/python3.13/site-packages/kombu/connection.py", line 476, in _reraise_as_library_errors
    raise ConnectionError(str(exc)) from exc
kombu.exceptions.OperationalError: Error 111 connecting to localhost:6379. Connection refused.
